Workbook

Sheet Cost Inputs
A1: Rubin USDF Model 2026 — Condensed Pricing — Cost Inputs
A2: Blue = input (edit here) · Yellow = key assumption · The forecast tab recalculates from column B.
A3: SIZING INPUTS (from condensed model)
A4: Input data per survey year | B4: 798.25 | C4: TB | D4: nights × visits × image × compression
A5: DRP core-hours per input TB | B5: 20571 | C5: ch/TB | D5: DR1 measured basis
A6: Developer/pilot load | B6: 158400 | C6: ch/yr | D6: 55 node-days/yr × 120 × 24
A7: Idle / inter-stage multiplier | B7: 1.35 | C7: × | D7: placeholder 1.3–1.5
A8: RSP extra fraction | B8: 0.01 | C8: fraction | D8: USDF-only
A9: Processing window | B9: 200 | C9: days
A10: Milano-equivalent cores per Torino node | B10: 240 | C10: cores | D10: 120 cores × 2.0 speedup
A11: Fleet capacity today (Milano-equivalent) | B11: 21600 | C11: cores | D11: (110 + 35×2) × 120
A12: Batch fleet nodes today | B12: 145 | C12: nodes | D12: 110 Milano + 35 Torino
A13: DP2 actual compute | B13: 2793600 | C13: core-hrs | D13: 970 node-days on Milano
A14: DP2 actual output | B14: 7430 | C14: TB
A15: DR-era output per survey-year | B15: 47000 | C15: TB | D15: campaign total, compressed
A16: Release products per survey-year | B16: 1600 | C16: TB
A17: Scratch fraction | B17: 0.35 | C17: fraction | D17: placeholder
A18: Installed disk today | B18: 30000 | C18: TB
A19: Qserv nodes deployed | B19: 92 | C19: nodes
A20: K8s nodes deployed | B20: 75 | C20: nodes
A21: Compute lifetime | B21: 3 | C21: years
A23: UNIT COSTS — 2026 HW Initial Capacity Capture (Aug 2026)
A24: Torino batch node (768 GB RAM) | B24: 89355 | C24: $/node | D24: current quote; default for future batch purchases
A25: Torino batch node (384 GB RAM) | B25: 58765 | C25: $/node | D25: reference only
A26: K8s / Qserv-class node (EPYC 7543P) | B26: 30866 | C26: $/node | D26: used for K8s and Qserv purchases
A27: Ceph usable disk | B27: 235.052 | C27: $/TB | D27: JBOD $203,320 / 865 usable TB
A28: Tape / archive | B28: 8.625 | C28: $/TB | D28: archive & backup estimate
A29: Hosting per node per year | B29: 566 | C29: $/node-yr | D29: prior agreement — not re-quoted in 2026 capture
A30: Overhead on hardware | B30: 0.14 | C30: %
A31: Overhead fixed | B31: 150000 | C31: $/yr
A32: Annual price change | B32: 0 | C32: %/yr | D32: flat by default; edit to model price falls/rises
A34: REFRESH & GROWTH ASSUMPTIONS
A35: Batch base-fleet rolling refresh | B35: 48 | C35: nodes/yr | D35: 145 nodes / 3-yr lifetime, from FY2027
A36: Qserv rolling refresh | B36: 31 | C36: nodes/yr | D36: 92 nodes / 3-yr lifetime, from FY2027
A37: K8s purchases per year (FY2027+) | B37: 29 | C37: nodes/yr | D37: 5% growth + 1/3 rolling refresh of 75-node base
A39: ASSUMPTIONS (stated):
A40: 1. FY2026 column uses the ACTUAL Rubin USDF requests from the 2026 HW Capacity Capture (0 batch nodes; +24 K8s = $740,784; +10,082 TB Ceph = $2,369,794; +5,000 TB archive = $43,125; deadline 2026-10-01). FY2027+ are model-driven.
A41: 2. Future batch purchases are Torino 768 GB at $89,355; each adds 240 Milano-equivalent cores (2.0× per-core speedup, measured on DP2-era tasks).
A42: 3. Growth purchases trigger when Milano-equivalent peak demand exceeds fleet capacity (21,600 cores today); purchased nodes are re-bought after the 3-year lifetime.
A43: 4. Base-fleet and Qserv refresh are modeled as rolling one-third per year from FY2027 (the FY2026 capture contains no batch/Qserv refresh request). The main model's Hardware Refresh tab carries the exact PO-cohort schedule.
...

Sheet USDF Pricing Forecast
A1: USDF Pricing Forecast — everything runs at USDF (partner facility prices unknown)
A2: Metric | B2: Unit | C2: FY2026 | D2: FY2027 | E2: FY2028 | F2: FY2029 | G2: FY2030 | H2: FY2031 | I2: FY2032 | J2: FY2033 | K2: FY2034 | L2: FY2035 | M2: 10-yr Total
C3: DP2 (actual) | D3: DR1 | E3: DR2 | F3: DR3 | G3: DR4 | H3: DR5 | I3: DR6 | J3: DR7 | K3: DR8 | L3: DR9
A5: DEMAND (from sizing model; FY2026 = DP2 actuals)
A6: Survey years of input processed | B6: years | C6: =30000/210000 -> 0.14285714 | D6: 1 | E6: 2 | F6: 3 | G6: 4 | H6: 5 | I6: 6 | J6: 7 | K6: 8 | L6: 9
A7: DRP core-hours | B7: core-hrs | C7: ='Cost Inputs'!$B$13 -> 2793600 | D7: =D6*'Cost Inputs'!$B$4*'Cost Inputs'!$B$5+D6*'Cost Inputs'!$B$6 -> 16579201 | E7: =E6*'Cost Inputs'!$B$4*'Cost Inputs'!$B$5+E6*'Cost Inputs'!$B$6 -> 33158402 | F7: =F6*'Cost Inputs'!$B$4*'Cost Inputs'!$B$5+F6*'Cost Inputs'!$B$6 -> 49737602 | G7: =G6*'Cost Inputs'!$B$4*'Cost Inputs'!$B$5+G6*'Cost Inputs'!$B$6 -> 66316803 | H7: =H6*'Cost Inputs'!$B$4*'Cost Inputs'!$B$5+H6*'Cost Inputs'!$B$6 -> 82896004 | I7: =I6*'Cost Inputs'!$B$4*'Cost Inputs'!$B$5+I6*'Cost Inputs'!$B$6 -> 99475204 | J7: =J6*'Cost Inputs'!$B$4*'Cost Inputs'!$B$5+J6*'Cost Inputs'!$B$6 -> 1.1605441e+08 | K7: =K6*'Cost Inputs'!$B$4*'Cost Inputs'!$B$5+K6*'Cost Inputs'!$B$6 -> 132633606 | L7: =L6*'Cost Inputs'!$B$4*'Cost Inputs'!$B$5+L6*'Cost Inputs'!$B$6 -> 1.4921281e+08
A8: Peak concurrent cores (Milano-eq demand) | B8: cores | C8: =ROUND(C7/('Cost Inputs'!$B$9*24)*'Cost Inputs'!$B$7*(1+'Cost Inputs'!$B$8),0) -> 794 | D8: =ROUND(D7/('Cost Inputs'!$B$9*24)*'Cost Inputs'!$B$7*(1+'Cost Inputs'!$B$8),0) -> 4710 | E8: =ROUND(E7/('Cost Inputs'!$B$9*24)*'Cost Inputs'!$B$7*(1+'Cost Inputs'!$B$8),0) -> 9419 | F8: =ROUND(F7/('Cost Inputs'!$B$9*24)*'Cost Inputs'!$B$7*(1+'Cost Inputs'!$B$8),0) -> 14129 | G8: =ROUND(G7/('Cost Inputs'!$B$9*24)*'Cost Inputs'!$B$7*(1+'Cost Inputs'!$B$8),0) -> 18838 | H8: =ROUND(H7/('Cost Inputs'!$B$9*24)*'Cost Inputs'!$B$7*(1+'Cost Inputs'!$B$8),0) -> 23548 | I8: =ROUND(I7/('Cost Inputs'!$B$9*24)*'Cost Inputs'!$B$7*(1+'Cost Inputs'!$B$8),0) -> 28257 | J8: =ROUND(J7/('Cost Inputs'!$B$9*24)*'Cost Inputs'!$B$7*(1+'Cost Inputs'!$B$8),0) -> 32967 | ... L8: =ROUND(L7/('Cost Inputs'!$B$9*24)*'Cost Inputs'!$B$7*(1+'Cost Inputs'!$B$8),0) -> 42386
A10: BATCH COMPUTE PURCHASES
A11: Cumulative Torino needed beyond fleet | B11: nodes | C11: =MAX(0,ROUNDUP((C8-'Cost Inputs'!$B$11)/'Cost Inputs'!$B$10,0)) -> 0 | D11: =MAX(0,ROUNDUP((D8-'Cost Inputs'!$B$11)/'Cost Inputs'!$B$10,0)) -> 0 | E11: =MAX(0,ROUNDUP((E8-'Cost Inputs'!$B$11)/'Cost Inputs'!$B$10,0)) -> 0 | F11: =MAX(0,ROUNDUP((F8-'Cost Inputs'!$B$11)/'Cost Inputs'!$B$10,0)) -> 0 | G11: =MAX(0,ROUNDUP((G8-'Cost Inputs'!$B$11)/'Cost Inputs'!$B$10,0)) -> 0 | H11: =MAX(0,ROUNDUP((H8-'Cost Inputs'!$B$11)/'Cost Inputs'!$B$10,0)) -> 9 | I11: =MAX(0,ROUNDUP((I8-'Cost Inputs'!$B$11)/'Cost Inputs'!$B$10,0)) -> 28 | J11: =MAX(0,ROUNDUP((J8-'Cost Inputs'!$B$11)/'Cost Inputs'!$B$10,0)) -> 48 | ... L11: =MAX(0,ROUNDUP((L8-'Cost Inputs'!$B$11)/'Cost Inputs'!$B$10,0)) -> 87
A12: Growth purchases this FY | B12: nodes | C12: =C11 -> 0 | D12: =D11-C11 -> 0 | E12: =E11-D11 -> 0 | F12: =F11-E11 -> 0 | G12: =G11-F11 -> 0 | H12: =H11-G11 -> 9 | I12: =I11-H11 -> 19 | J12: =J11-I11 -> 20 | K12: =K11-J11 -> 19 | L12: =L11-K11 -> 20 | M12: =SUM(C12:L12) -> 87
A13: Base-fleet rolling refresh | B13: nodes | C13: 0 | D13: ='Cost Inputs'!$B$35 -> 48 | E13: ='Cost Inputs'!$B$35 -> 48 | F13: ='Cost Inputs'!$B$35 -> 48 | G13: ='Cost Inputs'!$B$35 -> 48 | H13: ='Cost Inputs'!$B$35 -> 48 | I13: ='Cost Inputs'!$B$35 -> 48 | J13: ='Cost Inputs'!$B$35 -> 48 | K13: ='Cost Inputs'!$B$35 -> 48 | L13: ='Cost Inputs'!$B$35 -> 48 | M13: =SUM(C13:L13) -> 432
A14: Re-refresh of growth purchases (3-yr) | B14: nodes | C14: 0 | D14: 0 | E14: 0 | F14: =C12 -> 0 | G14: =D12 -> 0 | H14: =E12 -> 0 | I14: =F12 -> 0 | J14: =G12 -> 0 | K14: =H12 -> 9 | L14: =I12 -> 19 | M14: =SUM(C14:L14) -> 28
A15: Batch nodes purchased | B15: nodes | C15: =C12+C13+C14 -> 0 | D15: =D12+D13+D14 -> 48 | E15: =E12+E13+E14 -> 48 | F15: =F12+F13+F14 -> 48 | G15: =G12+G13+G14 -> 48 | H15: =H12+H13+H14 -> 57 | I15: =I12+I13+I14 -> 67 | J15: =J12+J13+J14 -> 68 | ... L15: =L12+L13+L14 -> 87 | M15: =SUM(C15:L15) -> 547
A16: Batch compute cost | B16: $ | C16: =C15*'Cost Inputs'!$B$24*(1+'Cost Inputs'!$B$32)^(0) -> 0 | D16: =D15*'Cost Inputs'!$B$24*(1+'Cost Inputs'!$B$32)^(1) -> 4289040 | E16: =E15*'Cost Inputs'!$B$24*(1+'Cost Inputs'!$B$32)^(2) -> 4289040 | F16: =F15*'Cost Inputs'!$B$24*(1+'Cost Inputs'!$B$32)^(3) -> 4289040 | G16: =G15*'Cost Inputs'!$B$24*(1+'Cost Inputs'!$B$32)^(4) -> 4289040 | H16: =H15*'Cost Inputs'!$B$24*(1+'Cost Inputs'!$B$32)^(5) -> 5093235 | I16: =I15*'Cost Inputs'!$B$24*(1+'Cost Inputs'!$B$32)^(6) -> 5986785 | J16: =J15*'Cost Inputs'!$B$24*(1+'Cost Inputs'!$B$32)^(7) -> 6076140 | K16: =K15*'Cost Inputs'!$B$24*(1+'Cost Inputs'!$B$32)^(8) -> 6790980 | L16: =L15*'Cost Inputs'!$B$24*(1+'Cost Inputs'!$B$32)^(9) -> 7773885 | M16: =SUM(C16:L16) -> 48877185
A18: DISK & TAPE PURCHASES
A19: Campaign output this FY | B19: TB | C19: ='Cost Inputs'!$B$14 -> 7430 | D19: =D6*'Cost Inputs'!$B$15 -> 47000 | E19: =E6*'Cost Inputs'!$B$15 -> 94000 | F19: =F6*'Cost Inputs'!$B$15 -> 141000 | G19: =G6*'Cost Inputs'!$B$15 -> 188000 | H19: =H6*'Cost Inputs'!$B$15 -> 235000 | I19: =I6*'Cost Inputs'!$B$15 -> 282000 | J19: =J6*'Cost Inputs'!$B$15 -> 329000 | K19: =K6*'Cost Inputs'!$B$15 -> 376000 | L19: =L6*'Cost Inputs'!$B$15 -> 423000
A20: Disk need (output × (1+scratch) + prior output) | B20: TB | C20: =C19*(1+'Cost Inputs'!$B$17) -> 10030.5 | D20: =D19*(1+'Cost Inputs'!$B$17)+C19 -> 70880 | E20: =E19*(1+'Cost Inputs'!$B$17)+D19 -> 173900 | F20: =F19*(1+'Cost Inputs'!$B$17)+E19 -> 284350 | G20: =G19*(1+'Cost Inputs'!$B$17)+F19 -> 394800 | H20: =H19*(1+'Cost Inputs'!$B$17)+G19 -> 505250 | I20: =I19*(1+'Cost Inputs'!$B$17)+H19 -> 615700 | J20: =J19*(1+'Cost Inputs'!$B$17)+I19 -> 726150 | K20: =K19*(1+'Cost Inputs'!$B$17)+J19 -> 836600 | L20: =L19*(1+'Cost Inputs'!$B$17)+K19 -> 947050
A21: Disk installed + purchased to date | B21: TB | C21: ='Cost Inputs'!$B$18+C22 -> 40082 | D21: =C21+D22 -> 70880 | E21: =D21+E22 -> 173900 | F21: =E21+F22 -> 284350 | G21: =F21+G22 -> 394800 | H21: =G21+H22 -> 505250 | I21: =H21+I22 -> 615700 | J21: =I21+J22 -> 726150 | K21: =J21+K22 -> 836600 | L21: =K21+L22 -> 947050
A22: Disk purchased this FY | B22: TB | C22: 10082 | D22: =MAX(0,D20-C21) -> 30798 | E22: =MAX(0,E20-D21) -> 103020 | F22: =MAX(0,F20-E21) -> 110450 | G22: =MAX(0,G20-F21) -> 110450 | H22: =MAX(0,H20-G21) -> 110450 | I22: =MAX(0,I20-H21) -> 110450 | J22: =MAX(0,J20-I21) -> 110450 | K22: =MAX(0,K20-J21) -> 110450 | L22: =MAX(0,L20-K21) -> 110450 | M22: =SUM(C22:L22) -> 917050
A23: Disk cost | B23: $ | C23: 2369794 | D23: =D22*'Cost Inputs'!$B$27*(1+'Cost Inputs'!$B$32)^(1) -> 7239131.5 | E23: =E22*'Cost Inputs'!$B$27*(1+'Cost Inputs'!$B$32)^(2) -> 24215057 | F23: =F22*'Cost Inputs'!$B$27*(1+'Cost Inputs'!$B$32)^(3) -> 25961493 | G23: =G22*'Cost Inputs'!$B$27*(1+'Cost Inputs'!$B$32)^(4) -> 25961493 | H23: =H22*'Cost Inputs'!$B$27*(1+'Cost Inputs'!$B$32)^(5) -> 25961493 | I23: =I22*'Cost Inputs'!$B$27*(1+'Cost Inputs'!$B$32)^(6) -> 25961493 | J23: =J22*'Cost Inputs'!$B$27*(1+'Cost Inputs'!$B$32)^(7) -> 25961493 | K23: =K22*'Cost Inputs'!$B$27*(1+'Cost Inputs'!$B$32)^(8) -> 25961493 | L23: =L22*'Cost Inputs'!$B$27*(1+'Cost Inputs'!$B$32)^(9) -> 25961493 | M23: =SUM(C23:L23) -> 2.1555444e+08
A24: Tape/archive added | B24: TB | C24: 5000 | D24: ='Cost Inputs'!$B$4+(D6-C6)*'Cost Inputs'!$B$16 -> 2169.6786 | E24: ='Cost Inputs'!$B$4+(E6-D6)*'Cost Inputs'!$B$16 -> 2398.25 | F24: ='Cost Inputs'!$B$4+(F6-E6)*'Cost Inputs'!$B$16 -> 2398.25 | G24: ='Cost Inputs'!$B$4+(G6-F6)*'Cost Inputs'!$B$16 -> 2398.25 | H24: ='Cost Inputs'!$B$4+(H6-G6)*'Cost Inputs'!$B$16 -> 2398.25 | I24: ='Cost Inputs'!$B$4+(I6-H6)*'Cost Inputs'!$B$16 -> 2398.25 | J24: ='Cost Inputs'!$B$4+(J6-I6)*'Cost Inputs'!$B$16 -> 2398.25 | K24: ='Cost Inputs'!$B$4+(K6-J6)*'Cost Inputs'!$B$16 -> 2398.25 | L24: ='Cost Inputs'!$B$4+(L6-K6)*'Cost Inputs'!$B$16 -> 2398.25 | M24: =SUM(C24:L24) -> 26355.679
A25: Tape cost | B25: $ | C25: 43125 | D25: =D24*'Cost Inputs'!$B$28*(1+'Cost Inputs'!$B$32)^(1) -> 18713.478 | E25: =E24*'Cost Inputs'!$B$28*(1+'Cost Inputs'!$B$32)^(2) -> 20684.906 | F25: =F24*'Cost Inputs'!$B$28*(1+'Cost Inputs'!$B$32)^(3) -> 20684.906 | G25: =G24*'Cost Inputs'!$B$28*(1+'Cost Inputs'!$B$32)^(4) -> 20684.906 | H25: =H24*'Cost Inputs'!$B$28*(1+'Cost Inputs'!$B$32)^(5) -> 20684.906 | I25: =I24*'Cost Inputs'!$B$28*(1+'Cost Inputs'!$B$32)^(6) -> 20684.906 | J25: =J24*'Cost Inputs'!$B$28*(1+'Cost Inputs'!$B$32)^(7) -> 20684.906 | K25: =K24*'Cost Inputs'!$B$28*(1+'Cost Inputs'!$B$32)^(8) -> 20684.906 | L25: =L24*'Cost Inputs'!$B$28*(1+'Cost Inputs'!$B$32)^(9) -> 20684.906 | M25: =SUM(C25:L25) -> 227317.73
A27: K8S & QSERV PURCHASES
A28: K8s nodes purchased | B28: nodes | C28: 24 | D28: ='Cost Inputs'!$B$37 -> 29 | E28: ='Cost Inputs'!$B$37 -> 29 | F28: ='Cost Inputs'!$B$37 -> 29 | G28: ='Cost Inputs'!$B$37 -> 29 | H28: ='Cost Inputs'!$B$37 -> 29 | I28: ='Cost Inputs'!$B$37 -> 29 | J28: ='Cost Inputs'!$B$37 -> 29 | K28: ='Cost Inputs'!$B$37 -> 29 | L28: ='Cost Inputs'!$B$37 -> 29 | M28: =SUM(C28:L28) -> 285
A29: K8s cost | B29: $ | C29: 740784 | D29: =D28*'Cost Inputs'!$B$26*(1+'Cost Inputs'!$B$32)^(1) -> 895114 | E29: =E28*'Cost Inputs'!$B$26*(1+'Cost Inputs'!$B$32)^(2) -> 895114 | F29: =F28*'Cost Inputs'!$B$26*(1+'Cost Inputs'!$B$32)^(3) -> 895114 | G29: =G28*'Cost Inputs'!$B$26*(1+'Cost Inputs'!$B$32)^(4) -> 895114 | H29: =H28*'Cost Inputs'!$B$26*(1+'Cost Inputs'!$B$32)^(5) -> 895114 | I29: =I28*'Cost Inputs'!$B$26*(1+'Cost Inputs'!$B$32)^(6) -> 895114 | J29: =J28*'Cost Inputs'!$B$26*(1+'Cost Inputs'!$B$32)^(7) -> 895114 | K29: =K28*'Cost Inputs'!$B$26*(1+'Cost Inputs'!$B$32)^(8) -> 895114 | L29: =L28*'Cost Inputs'!$B$26*(1+'Cost Inputs'!$B$32)^(9) -> 895114 | M29: =SUM(C29:L29) -> 8796810
A30: Qserv nodes needed (3-release window) | B30: nodes | C30: 82 | D30: 211 | E30: 194 | F30: 265 | G30: 336 | H30: 407 | I30: 240 | J30: 276 | K30: 311 | L30: 347
A31: Running max needed | B31: nodes | C31: =MAX('Cost Inputs'!$B$19,C30) -> 92 | D31: =MAX(C31,D30) -> 211 | E31: =MAX(D31,E30) -> 211 | F31: =MAX(E31,F30) -> 265 | G31: =MAX(F31,G30) -> 336 | H31: =MAX(G31,H30) -> 407 | I31: =MAX(H31,I30) -> 407 | J31: =MAX(I31,J30) -> 407 | K31: =MAX(J31,K30) -> 407 | L31: =MAX(K31,L30) -> 407
A32: Qserv growth purchases | B32: nodes | C32: =MAX(0,C30-'Cost Inputs'!$B$19) -> 0 | D32: =D31-C31 -> 119 | E32: =E31-D31 -> 0 | F32: =F31-E31 -> 54 | G32: =G31-F31 -> 71 | H32: =H31-G31 -> 71 | I32: =I31-H31 -> 0 | J32: =J31-I31 -> 0 | K32: =K31-J31 -> 0 | L32: =L31-K31 -> 0 | M32: =SUM(C32:L32) -> 315
A33: Qserv rolling refresh | B33: nodes | C33: 0 | D33: ='Cost Inputs'!$B$36 -> 31 | E33: ='Cost Inputs'!$B$36 -> 31 | F33: ='Cost Inputs'!$B$36 -> 31 | G33: ='Cost Inputs'!$B$36 -> 31 | H33: ='Cost Inputs'!$B$36 -> 31 | I33: ='Cost Inputs'!$B$36 -> 31 | J33: ='Cost Inputs'!$B$36 -> 31 | K33: ='Cost Inputs'!$B$36 -> 31 | L33: ='Cost Inputs'!$B$36 -> 31 | M33: =SUM(C33:L33) -> 279
A34: Qserv cost | B34: $ | C34: =(C32+C33)*'Cost Inputs'!$B$26*(1+'Cost Inputs'!$B$32)^(0) -> 0 | D34: =(D32+D33)*'Cost Inputs'!$B$26*(1+'Cost Inputs'!$B$32)^(1) -> 4629900 | E34: =(E32+E33)*'Cost Inputs'!$B$26*(1+'Cost Inputs'!$B$32)^(2) -> 956846 | F34: =(F32+F33)*'Cost Inputs'!$B$26*(1+'Cost Inputs'!$B$32)^(3) -> 2623610 | G34: =(G32+G33)*'Cost Inputs'!$B$26*(1+'Cost Inputs'!$B$32)^(4) -> 3148332 | H34: =(H32+H33)*'Cost Inputs'!$B$26*(1+'Cost Inputs'!$B$32)^(5) -> 3148332 | I34: =(I32+I33)*'Cost Inputs'!$B$26*(1+'Cost Inputs'!$B$32)^(6) -> 956846 | J34: =(J32+J33)*'Cost Inputs'!$B$26*(1+'Cost Inputs'!$B$32)^(7) -> 956846 | K34: =(K32+K33)*'Cost Inputs'!$B$26*(1+'Cost Inputs'!$B$32)^(8) -> 956846 | L34: =(L32+L33)*'Cost Inputs'!$B$26*(1+'Cost Inputs'!$B$32)^(9) -> 956846 | M34: =SUM(C34:L34) -> 18334404
A36: HOSTING, OVERHEAD, TOTALS
A37: Hardware subtotal | B37: $ | C37: =C16+C23+C25+C29+C34 -> 3153703 | D37: =D16+D23+D25+D29+D34 -> 17071899 | E37: =E16+E23+E25+E29+E34 -> 30376742 | F37: =F16+F23+F25+F29+F34 -> 33789942 | G37: =G16+G23+G25+G29+G34 -> 34314664 | H37: =H16+H23+H25+H29+H34 -> 35118859 | I37: =I16+I23+I25+I29+I34 -> 33820923 | J37: =J16+J23+J25+J29+J34 -> 33910278 | ... L37: =L16+L23+L25+L29+L34 -> 35608023 | M37: =SUM(C37:L37) -> 2.9179015e+08
A38: Nodes in service (approx) | B38: nodes | C38: =323+SUM($C$12:C12)+SUM($C$32:C32)+SUM($C$28:C28)-24 -> 323 | D38: =323+SUM($C$12:D12)+SUM($C$32:D32)+SUM($C$28:D28)-24 -> 471 | E38: =323+SUM($C$12:E12)+SUM($C$32:E32)+SUM($C$28:E28)-24 -> 500 | F38: =323+SUM($C$12:F12)+SUM($C$32:F32)+SUM($C$28:F28)-24 -> 583 | G38: =323+SUM($C$12:G12)+SUM($C$32:G32)+SUM($C$28:G28)-24 -> 683 | H38: =323+SUM($C$12:H12)+SUM($C$32:H32)+SUM($C$28:H28)-24 -> 792 | I38: =323+SUM($C$12:I12)+SUM($C$32:I32)+SUM($C$28:I28)-24 -> 840 | J38: =323+SUM($C$12:J12)+SUM($C$32:J32)+SUM($C$28:J28)-24 -> 889 | ... L38: =323+SUM($C$12:L12)+SUM($C$32:L32)+SUM($C$28:L28)-24 -> 986
A39: Hosting | B39: $ | C39: =C38*'Cost Inputs'!$B$29 -> 182818 | D39: =D38*'Cost Inputs'!$B$29 -> 266586 | E39: =E38*'Cost Inputs'!$B$29 -> 283000 | F39: =F38*'Cost Inputs'!$B$29 -> 329978 | G39: =G38*'Cost Inputs'!$B$29 -> 386578 | H39: =H38*'Cost Inputs'!$B$29 -> 448272 | I39: =I38*'Cost Inputs'!$B$29 -> 475440 | J39: =J38*'Cost Inputs'!$B$29 -> 503174 | ... L39: =L38*'Cost Inputs'!$B$29 -> 558076 | M39: =SUM(C39:L39) -> 3964264
A40: Overhead (14% of hardware + fixed) | B40: $ | C40: =C37*'Cost Inputs'!$B$30+'Cost Inputs'!$B$31 -> 591518.42 | D40: =D37*'Cost Inputs'!$B$30+'Cost Inputs'!$B$31 -> 2540065.9 | E40: =E37*'Cost Inputs'!$B$30+'Cost Inputs'!$B$31 -> 4402743.9 | F40: =F37*'Cost Inputs'!$B$30+'Cost Inputs'!$B$31 -> 4880591.9 | G40: =G37*'Cost Inputs'!$B$30+'Cost Inputs'!$B$31 -> 4954053 | H40: =H37*'Cost Inputs'!$B$30+'Cost Inputs'!$B$31 -> 5066640.3 | I40: =I37*'Cost Inputs'!$B$30+'Cost Inputs'!$B$31 -> 4884929.3 | J40: =J37*'Cost Inputs'!$B$30+'Cost Inputs'!$B$31 -> 4897439 | ... L40: =L37*'Cost Inputs'!$B$30+'Cost Inputs'!$B$31 -> 5135123.3 | M40: =SUM(C40:L40) -> 42350621
A41: TOTAL annual spend | B41: $ | C41: =C37+C39+C40 -> 3928039.4 | D41: =D37+D39+D40 -> 19878551 | E41: =E37+E39+E40 -> 35062486 | F41: =F37+F39+F40 -> 39000512 | G41: =G37+G39+G40 -> 39655295 | H41: =H37+H39+H40 -> 40633772 | I41: =I37+I39+I40 -> 39181293 | J41: =J37+J39+J40 -> 39310891 | ... L41: =L37+L39+L40 -> 41301223 | M41: =SUM(C41:L41) -> 3.3810504e+08
A42: TOTAL annual spend | B42: $M | C42: =C41 -> 3928039.4 | D42: =D41 -> 19878551 | E42: =E41 -> 35062486 | F42: =F41 -> 39000512 | G42: =G41 -> 39655295 | H42: =H41 -> 40633772 | I42: =I41 -> 39181293 | J42: =J41 -> 39310891 | ... L42: =L41 -> 41301223 | M42: =SUM(C42:L42) -> 3.3810504e+08
A43: Cumulative spend | B43: $M | C43: =C42 -> 3928039.4 | D43: =C43+D42 -> 23806590 | E43: =D43+E42 -> 58869076 | F43: =E43+F42 -> 97869588 | G43: =F43+G42 -> 1.3752488e+08 | H43: =G43+H42 -> 1.7815866e+08 | I43: =H43+I42 -> 2.1733995e+08 | J43: =I43+J42 -> 2.5665084e+08 | K43: =J43+K42 -> 2.9680382e+08 | L43: =K43+L42 -> 3.3810504e+08
A45: FY2026 = actual 2026 capture requests. From FY2027: growth purchases trigger when Milano-equivalent demand exceeds fleet capacity; disk purchases cover campaign need vs installed+purchased; refresh is rolling 1/3 per year. Assumptions and unit-cost sources on the Cost Inputs tab.
