Workbook
Name computeLifetime: Model!$B$23
Name cpuFac: Model!$C$19
Name diskFac: Model!$C$20
Name qservFac: Model!$C$21
Name scaleYear: Model!$B$22
Name storageLifetime: Model!$B$24

Sheet Reference Data
A1: Rubin USDF Sizing Model — Reference Data
A3: Parameter | B3: Value | C3: Source / Notes
A4: DRP Estimates
A5: DR1 node-days (reference only) | B5: 5700 | C5: Not used in formulas; see core_hours_per_input_tb
A6: DRP CPU doc reference | B6: DRP Resource Usage Estimates — CPU from DM-53697 (v30_0_0_rc2), DM-52836 (w_2025_41) | C6: DRP Resource Usage Estimates
A7: Safety margin | B7: 1.5
A8: Cores per node | B8: 120
A9: Processing window (days) | B9: 200
A10: DR1 total storage (PB) | B10: 47 | C10: Compressed
A11: DR1 release products (PB) | B11: 1.6
A12: Wall-to-CPU ratio | B12: 1.14
A13: DR2 multiplier | B13: 2
A14: Prompt Products (RFC-1134)
A15: Tier 1 TB/night | B15: 5.6 | C15: Long-term retention until DR1
A16: Tier 2 TB/night | B16: 6 | C16: 30-day rolling
A17: DR1 target year | B17: 2027
A18: Qserv (from Igor)
A19: Current nodes | B19: 92
A20: Cores per node | B20: 32
A21: Storage TB per node | B21: 32
A22: Replication factor | B22: 3
A23: Current Fleet (2026 — Rubin USDF)
A24: Milano batch nodes | B24: 110 | C24: FY24 CPU Planner, Rubin USDF
A25: Torino batch nodes | B25: 35 | C25: Confirmed available to Rubin
A26: K8s nodes | B26: 75 | C26: Initial k8s Capture, Rubin USDF
A27: Interactive nodes | B27: 11 | C27: Initial InteractiveWorkflow Cap
A28: GPU H200 nodes | B28: 2 | C28: Initial GPU Capture, Rubin USDF
A29: Qserv nodes | B29: 92 | C29: From conversation with Igor
A30: Cassandra nodes | B30: 12 | C30: Rubin Hardware Summary Mar 2025 JTM (Yemi)
A31: NVMe servers | B31: 4 | C31: Weka / flash tier (JTM)
A32: JBOD enclosures (total / deployed) | B32: 62 / 37 | C32: JTM
A33: Installed storage (PB) | B33: 30 | C33: Initial Storage Capture, Rubin USDF
A34: Total batch cores | B34: 17400 | C34: Milano + Torino
A35: Node Costs
A36: Milano node (USD) | B36: 11800
A37: Torino node (USD) | B37: 16000 | C37: Estimated
A38: K8s node (USD) | B38: 8000
A39: Qserv node (USD) | B39: 20000
A40: GPU H200 node (USD) | B40: 250000
A41: Storage Costs ($/TB)
...

Sheet Ops Storage
A1: Ops Storage — USDF Parameters
A2: Parameter | B2: Unit | C2: LOY1 | D2: LOY2 | E2: LOY3 | F2: LOY4 | G2: LOY5 | H2: LOY6 | I2: LOY7 | J2: LOY8 | K2: LOY9 | L2: LOY10
A4: Objects | B4: count | C4: 27500000000 | D4: 32500000000 | E4: 35700000000 | F4: 38200000000 | G4: 40300000000 | H4: 42200000000 | I4: 43800000000 | J4: 45300000000 | K4: 46400000000 | L4: 47400000000
A5: Sources | B5: count | C5: 901000000000 | D5: 1800000000000 | E5: 2700000000000 | F5: 3600000000000 | G5: 4510000000000 | H5: 5410000000000 | I5: 6310000000000 | J5: 7210000000000 | K5: 8110000000000 | L5: 9010000000000
A6: ForcedSources | B6: count | C6: 2910000000000 | D6: 6870000000000 | E6: 11300000000000 | F6: 16100000000000 | G6: 21300000000000 | H6: 26700000000000 | I6: 32400000000000 | J6: 38300000000000 | K6: 44100000000000 | L6: 50100000000000
A8: Science users | B8: users | C8: 5000 | D8: 6000 | E8: 7000 | F8: 7500 | G8: 7500 | H8: 7500 | I8: 7500 | J8: 7500 | K8: 7500 | L8: 7500
A9: Storage per science user | B9: TB | C9: 0.4 | D9: 0.5 | E9: 0.6 | F9: 0.7 | G9: 0.8 | H9: 0.9 | I9: 1 | J9: 1.1 | K9: 1.2 | L9: 1.3
A11: LSSTCam image size | B11: TB | C11: 0.00819222 | D11: 0.00819222 | E11: 0.00819222 | F11: 0.00819222 | G11: 0.00819222 | H11: 0.00819222 | I11: 0.00819222 | J11: 0.00819222 | K11: 0.00819222 | L11: 0.00819222
A12: Raw image compression (science) | B12: factor | C12: 0.464 | D12: 0.464 | E12: 0.464 | F12: 0.464 | G12: 0.464 | H12: 0.464 | I12: 0.464 | J12: 0.464 | K12: 0.464 | L12: 0.464
A13: Lossy image compression | B13: factor | C13: 0.27 | D13: 0.27 | E13: 0.27 | F13: 0.27 | G13: 0.27 | H13: 0.27 | I13: 0.27 | J13: 0.27 | K13: 0.27 | L13: 0.27
A14: Calibration image compression | B14: factor | C14: 0.464 | D14: 0.464 | E14: 0.464 | F14: 0.464 | G14: 0.464 | H14: 0.464 | I14: 0.464 | J14: 0.464 | K14: 0.464 | L14: 0.464
A15: Observing nights per year | B15: nights | C15: 300 | D15: 300 | E15: 300 | F15: 300 | G15: 300 | H15: 300 | I15: 300 | J15: 300 | K15: 300 | L15: 300
A16: Visits per night | B16: visits | C16: 700 | D16: 700 | E16: 700 | F16: 700 | G16: 700 | H16: 700 | I16: 700 | J16: 700 | K16: 700 | L16: 700
A17: Images per visit | B17: images | C17: 1 | D17: 1 | E17: 1 | F17: 1 | G17: 1 | H17: 1 | I17: 1 | J17: 1 | K17: 1 | L17: 1
A18: Calibration images per day | B18: images | C18: 450 | D18: 450 | E18: 450 | F18: 450 | G18: 450 | H18: 450 | I18: 450 | J18: 450 | K18: 450 | L18: 450
A19: LSSTCam Science images (per year) | B19: images | C19: =C15*C16*C17 -> 210000 | D19: =D15*D16*D17 -> 210000 | E19: =E15*E16*E17 -> 210000 | F19: =F15*F16*F17 -> 210000 | G19: =G15*G16*G17 -> 210000 | H19: =H15*H16*H17 -> 210000 | I19: =I15*I16*I17 -> 210000 | J19: =J15*J16*J17 -> 210000 | ... L19: =L15*L16*L17 -> 210000
A20: LSSTCam Engineering images (1% of science) | B20: images | C20: =0.01*C19 -> 2100 | D20: =0.01*D19 -> 2100 | E20: =0.01*E19 -> 2100 | F20: =0.01*F19 -> 2100 | G20: =0.01*G19 -> 2100 | H20: =0.01*H19 -> 2100 | I20: =0.01*I19 -> 2100 | J20: =0.01*J19 -> 2100 | ... L20: =0.01*L19 -> 2100
A21: LSSTCam Calibration images (per year) | B21: images | C21: =C15*C18 -> 135000 | D21: =D15*D18 -> 135000 | E21: =E15*E18 -> 135000 | F21: =F15*F18 -> 135000 | G21: =G15*G18 -> 135000 | H21: =H15*H18 -> 135000 | I21: =I15*I18 -> 135000 | J21: =J15*J18 -> 135000 | ... L21: =L15*L18 -> 135000
A22: Number of coadd data products | B22: count | C22: 2 | D22: 2 | E22: 2 | F22: 2 | G22: 2 | H22: 2 | I22: 2 | J22: 2 | K22: 2 | L22: 2
A23: Object table row size | B23: bytes | C23: 1896 | D23: 1953 | E23: 2012 | F23: 2073 | G23: 2136 | H23: 2201 | I23: 2268 | J23: 2337 | K23: 2408 | L23: 2481
A24: Object_Extra table row size | B24: bytes | C24: 21005 | D24: 21636 | E24: 22286 | F24: 22955 | G24: 23644 | H24: 24354 | I24: 25085 | J24: 25838 | K24: 26614 | L24: 27413
A25: Source table row size | B25: bytes | C25: 467 | D25: 482 | E25: 497 | F25: 512 | G25: 528 | H25: 544 | I25: 561 | J25: 578 | K25: 596 | L25: 614
A26: ForcedSource table row size | B26: bytes | C26: 41 | D26: 41 | E26: 41 | F26: 41 | G26: 41 | H26: 41 | I26: 41 | J26: 41 | K26: 41 | L26: 41
A27: Qserv replication factor | B27: factor | C27: 3 | D27: 3 | E27: 3 | F27: 3 | G27: 3 | H27: 3 | I27: 3 | J27: 3 | K27: 3 | L27: 3
A29: Dataset Sizing (annual production)
A30: Dataset | B30: Unit | C30: LOY1 | D30: LOY2 | E30: LOY3 | F30: LOY4 | G30: LOY5 | H30: LOY6 | I30: LOY7 | J30: LOY8 | K30: LOY9 | L30: LOY10
A31: APDB | B31: TB | C31: =4.5/57000*C16*C15 -> 16.578947 | D31: =4.5/57000*D16*D15 -> 16.578947 | E31: =4.5/57000*E16*E15 -> 16.578947 | F31: =4.5/57000*F16*F15 -> 16.578947 | G31: =4.5/57000*G16*G15 -> 16.578947 | H31: =4.5/57000*H16*H15 -> 16.578947 | I31: =4.5/57000*I16*I15 -> 16.578947 | J31: =4.5/57000*J16*J15 -> 16.578947 | ... L31: =4.5/57000*L16*L15 -> 16.578947
A32: Prompt Tier 1 (cumulative) | B32: TB | C32: 1680 | D32: 3360 | E32: 3360 | F32: 3360 | G32: 3360 | H32: 3360 | I32: 3360 | J32: 3360 | K32: 3360 | L32: 3360
A33: Prompt Tier 2 (30-day rolling) | B33: TB | C33: 180 | D33: 180 | E33: 180 | F33: 180 | G33: 180 | H33: 180 | I33: 180 | J33: 180 | K33: 180 | L33: 180
A35: LSSTCam Raw Images (per year) | B35: TB | C35: =(C19+C20)*C11*C12+C21*C11*C14 -> 1319.3931 | D35: =(D19+D20)*D11*D12+D21*D11*D14 -> 1319.3931 | E35: =(E19+E20)*E11*E12+E21*E11*E14 -> 1319.3931 | F35: =(F19+F20)*F11*F12+F21*F11*F14 -> 1319.3931 | G35: =(G19+G20)*G11*G12+G21*G11*G14 -> 1319.3931 | H35: =(H19+H20)*H11*H12+H21*H11*H14 -> 1319.3931 | I35: =(I19+I20)*I11*I12+I21*I11*I14 -> 1319.3931 | J35: =(J19+J20)*J11*J12+J21*J11*J14 -> 1319.3931 | ... L35: =(L19+L20)*L11*L12+L21*L11*L14 -> 1319.3931
A36: LSSTCam Output Coadd Images (per DR) | B36: TB | C36: 2700 | D36: 2700 | E36: 2700 | F36: 2700 | G36: 2700 | H36: 2700 | I36: 2700 | J36: 2700 | K36: 2700 | L36: 2700
A38: LSSTCam Output Images (per year) | B38: TB | C38: =0.01906*C19/C17 -> 4002.6 | D38: =0.01906*D19/D17 -> 4002.6 | E38: =0.01906*E19/E17 -> 4002.6 | F38: =0.01906*F19/F17 -> 4002.6 | G38: =0.01906*G19/G17 -> 4002.6 | H38: =0.01906*H19/H17 -> 4002.6 | I38: =0.01906*I19/I17 -> 4002.6 | J38: =0.01906*J19/J17 -> 4002.6 | ... L38: =0.01906*L19/L17 -> 4002.6
A39: LSSTCam Output Parquet (per year) | B39: TB | C39: =0.00618*C19/C17 -> 1297.8 | D39: =0.00618*D19/D17 -> 1297.8 | E39: =0.00618*E19/E17 -> 1297.8 | F39: =0.00618*F19/F17 -> 1297.8 | G39: =0.00618*G19/G17 -> 1297.8 | H39: =0.00618*H19/H17 -> 1297.8 | I39: =0.00618*I19/I17 -> 1297.8 | J39: =0.00618*J19/J17 -> 1297.8 | ... L39: =0.00618*L19/L17 -> 1297.8
A40: Sims output | B40: TB | C40: 5 | D40: 5 | E40: 5 | F40: 5 | G40: 5 | H40: 5 | I40: 5 | J40: 5 | K40: 5 | L40: 5
A41: Scratch (10% of output images) | B41: TB | C41: =0.1*C38 -> 400.26 | D41: =0.1*D38 -> 400.26 | E41: =0.1*E38 -> 400.26 | F41: =0.1*F38 -> 400.26 | G41: =0.1*G38 -> 400.26 | H41: =0.1*H38 -> 400.26 | I41: =0.1*I38 -> 400.26 | J41: =0.1*J38 -> 400.26 | ... L41: =0.1*L38 -> 400.26
A42: Qserv Czar/Object | B42: TB | C42: =C4*C23*C27/1000000000000 -> 156.42 | D42: =D4*D23*D27/1000000000000 -> 190.4175 | E42: =E4*E23*E27/1000000000000 -> 215.4852 | F42: =F4*F23*F27/1000000000000 -> 237.5658 | G42: =G4*G23*G27/1000000000000 -> 258.2424 | H42: =H4*H23*H27/1000000000000 -> 278.6466 | I42: =I4*I23*I27/1000000000000 -> 298.0152 | J42: =J4*J23*J27/1000000000000 -> 317.5983 | ... L42: =L4*L23*L27/1000000000000 -> 352.7982
A43: Qserv Database | B43: TB | C43: =(C4*(C23+C24)+C5*C25+C6*C26)*C27/1000000000000 -> 3509.5635 | D43: =(D4*(D23+D24)+D5*D25+D6*D26)*D27/1000000000000 -> 5747.7375 | E43: =(E4*(E23+E24)+E5*E25+E6*E26)*E27/1000000000000 -> 8017.9158 | F43: =(F4*(F23+F24)+F5*F25+F6*F26)*F27/1000000000000 -> 10378.109 | G43: =(G4*(G23+G24)+G5*G25+G6*G26)*G27/1000000000000 -> 12880.542 | H43: =(H4*(H23+H24)+H5*H25+H6*H26)*H27/1000000000000 -> 15475.083 | I43: =(I4*(I23+I24)+I5*I25+I6*I26)*I27/1000000000000 -> 18199.114 | J43: =(J4*(J23+J24)+J5*J25+J6*J26)*J27/1000000000000 -> 21042.022 | ... L43: =(L4*(L23+L24)+L5*L25+L6*L26)*L27/1000000000000 -> 27009.647
A44: Science User Home | B44: TB | C44: =C8*C9 -> 2000 | D44: =D8*D9 -> 3000 | E44: =E8*E9 -> 4200 | F44: =F8*F9 -> 5250 | G44: =G8*G9 -> 6000 | H44: =H8*H9 -> 6750 | I44: =I8*I9 -> 7500 | J44: =J8*J9 -> 8250 | ... L44: =L8*L9 -> 9750
A45: Other/Misc (20%) | B45: TB | C45: =0.2*SUM(C31:C44) -> 3453.5231 | D45: =0.2*SUM(D31:D44) -> 4443.9574 | E45: =0.2*SUM(E31:E44) -> 5143.0066 | F45: =0.2*SUM(F31:F44) -> 5829.4613 | G45: =0.2*SUM(G31:G44) -> 6484.0833 | H45: =0.2*SUM(H31:H44) -> 7157.0723 | I45: =0.2*SUM(I31:I44) -> 7855.7523 | J45: =0.2*SUM(J31:J44) -> 8578.2506 | ... L45: =0.2*SUM(L31:L44) -> 10078.815
A47: USDF Storage On-Floor (by tier)
...

Sheet Ops Compute
A1: Ops Compute — USDF
A2: Category | B2: Unit | C2: LOY1 | D2: LOY2 | E2: LOY3 | F2: LOY4 | G2: LOY5 | H2: LOY6 | I2: LOY7 | J2: LOY8 | K2: LOY9 | L2: LOY10
A3: DRP core-hours needed | B3: core-hours | C3: 16420799 | D3: 32841598 | E3: 49262397 | F3: 65683196 | G3: 82103995 | H3: 98524794 | I3: 114945593 | J3: 131366392 | K3: 147787191 | L3: 164207990
A4: DRP cores needed (batch) | B4: cores | C4: =C3/4800 -> 3420.9998 | D4: =D3/4800 -> 6841.9996 | E4: =E3/4800 -> 10262.999 | F4: =F3/4800 -> 13683.999 | G4: =G3/4800 -> 17104.999 | H4: =H3/4800 -> 20525.999 | I4: =I3/4800 -> 23946.999 | J4: =J3/4800 -> 27367.998 | ... L4: =L3/4800 -> 34209.998
A5: DRP cores annual increase | B5: cores | C5: =C4 -> 3420.9998 | D5: =D4-C4 -> 3420.9998 | E5: =E4-D4 -> 3420.9998 | F5: =F4-E4 -> 3420.9998 | G5: =G4-F4 -> 3420.9998 | H5: =H4-G4 -> 3420.9998 | I5: =I4-H4 -> 3420.9998 | J5: =J4-I4 -> 3420.9998 | K5: =K4-J4 -> 3420.9998 | L5: =L4-K4 -> 3420.9998
A6: DRP cores refresh (3yr cycle) | B6: cores | C6: 0 | D6: 0 | E6: 0 | F6: =C5 -> 3420.9998 | G6: =D5 -> 3420.9998 | H6: =E5 -> 3420.9998 | I6: =F5 -> 3420.9998 | J6: =G5 -> 3420.9998 | K6: =H5 -> 3420.9998 | L6: =I5 -> 3420.9998
A7: DRP cores to purchase | B7: cores | C7: =C5+C6 -> 3420.9998 | D7: =D5+D6 -> 3420.9998 | E7: =E5+E6 -> 3420.9998 | F7: =F5+F6 -> 6841.9996 | G7: =G5+G6 -> 6841.9996 | H7: =H5+H6 -> 6841.9996 | I7: =I5+I6 -> 6841.9996 | J7: =J5+J6 -> 6841.9996 | ... L7: =L5+L6 -> 6841.9996
A9: AP cores needed (K8s / prompt, not batch) | B9: cores | C9: =$B$99 -> 1188 | D9: =$B$99 -> 1188 | E9: =$B$99 -> 1188 | F9: =$B$99 -> 1188 | G9: =$B$99 -> 1188 | H9: =$B$99 -> 1188 | I9: =$B$99 -> 1188 | J9: =$B$99 -> 1188 | ... L9: =$B$99 -> 1188
A10: AP cores initial purchase (LOY1 only) | B10: cores | C10: =IF(COLUMN()=3,$B$99,0) -> 1188 | D10: =IF(COLUMN()=3,$B$99,0) -> 0 | E10: =IF(COLUMN()=3,$B$99,0) -> 0 | F10: =IF(COLUMN()=3,$B$99,0) -> 0 | G10: =IF(COLUMN()=3,$B$99,0) -> 0 | H10: =IF(COLUMN()=3,$B$99,0) -> 0 | I10: =IF(COLUMN()=3,$B$99,0) -> 0 | J10: =IF(COLUMN()=3,$B$99,0) -> 0 | ... L10: =IF(COLUMN()=3,$B$99,0) -> 0
A11: AP cores refresh (3yr full replace) | B11: cores | C11: =IF(AND(COLUMN()>=6,MOD(COLUMN()-3,3)=0),$B$99,0) -> 0 | D11: =IF(AND(COLUMN()>=6,MOD(COLUMN()-3,3)=0),$B$99,0) -> 0 | E11: =IF(AND(COLUMN()>=6,MOD(COLUMN()-3,3)=0),$B$99,0) -> 0 | F11: =IF(AND(COLUMN()>=6,MOD(COLUMN()-3,3)=0),$B$99,0) -> 1188 | G11: =IF(AND(COLUMN()>=6,MOD(COLUMN()-3,3)=0),$B$99,0) -> 0 | H11: =IF(AND(COLUMN()>=6,MOD(COLUMN()-3,3)=0),$B$99,0) -> 0 | I11: =IF(AND(COLUMN()>=6,MOD(COLUMN()-3,3)=0),$B$99,0) -> 1188 | J11: =IF(AND(COLUMN()>=6,MOD(COLUMN()-3,3)=0),$B$99,0) -> 0 | ... L11: =IF(AND(COLUMN()>=6,MOD(COLUMN()-3,3)=0),$B$99,0) -> 1188
A12: AP cores to purchase (K8s budget) | B12: cores | C12: =C10+C11 -> 1188 | D12: =D10+D11 -> 0 | E12: =E10+E11 -> 0 | F12: =F10+F11 -> 1188 | G12: =G10+G11 -> 0 | H12: =H10+H11 -> 0 | I12: =I10+I11 -> 1188 | J12: =J10+J11 -> 0 | ... L12: =L10+L11 -> 1188
A14: DAC/LSP cores (10% of DRP) | B14: cores | C14: =0.1*C4 -> 342.09998 | D14: =0.1*D4 -> 684.19996 | E14: =0.1*E4 -> 1026.2999 | F14: =0.1*F4 -> 1368.3999 | G14: =0.1*G4 -> 1710.4999 | H14: =0.1*H4 -> 2052.5999 | I14: =0.1*I4 -> 2394.6999 | J14: =0.1*J4 -> 2736.7998 | ... L14: =0.1*L4 -> 3420.9998
A15: DAC cores annual increase | B15: cores | C15: =C14 -> 342.09998 | D15: =D14-C14 -> 342.09998 | E15: =E14-D14 -> 342.09998 | F15: =F14-E14 -> 342.09998 | G15: =G14-F14 -> 342.09998 | H15: =H14-G14 -> 342.09998 | I15: =I14-H14 -> 342.09998 | J15: =J14-I14 -> 342.09998 | K15: =K14-J14 -> 342.09998 | L15: =L14-K14 -> 342.09998
A16: DAC cores refresh (3yr) | B16: cores | C16: 0 | D16: 0 | E16: 0 | F16: =C15 -> 342.09998 | G16: =D15 -> 342.09998 | H16: =E15 -> 342.09998 | I16: =F15 -> 342.09998 | J16: =G15 -> 342.09998 | K16: =H15 -> 342.09998 | L16: =I15 -> 342.09998
A17: DAC cores to purchase | B17: cores | C17: =C15+C16 -> 342.09998 | D17: =D15+D16 -> 342.09998 | E17: =E15+E16 -> 342.09998 | F17: =F15+F16 -> 684.19996 | G17: =G15+G16 -> 684.19996 | H17: =H15+H16 -> 684.19996 | I17: =I15+I16 -> 684.19996 | J17: =J15+J16 -> 684.19996 | ... L17: =L15+L16 -> 684.19996
A18: Staff LSP cores (10% of DAC) | B18: cores | C18: =0.1*C14 -> 34.209998 | D18: =0.1*D14 -> 68.419996 | E18: =0.1*E14 -> 102.62999 | F18: =0.1*F14 -> 136.83999 | G18: =0.1*G14 -> 171.04999 | H18: =0.1*H14 -> 205.25999 | I18: =0.1*I14 -> 239.46999 | J18: =0.1*J14 -> 273.67998 | ... L18: =0.1*L14 -> 342.09998
A19: Staff cores annual increase | B19: cores | C19: =C18 -> 34.209998 | D19: =D18-C18 -> 34.209998 | E19: =E18-D18 -> 34.209998 | F19: =F18-E18 -> 34.209998 | G19: =G18-F18 -> 34.209998 | H19: =H18-G18 -> 34.209998 | I19: =I18-H18 -> 34.209998 | J19: =J18-I18 -> 34.209998 | K19: =K18-J18 -> 34.209998 | L19: =L18-K18 -> 34.209998
A20: Staff cores refresh (3yr) | B20: cores | C20: 0 | D20: 0 | E20: 0 | F20: =C19 -> 34.209998 | G20: =D19 -> 34.209998 | H20: =E19 -> 34.209998 | I20: =F19 -> 34.209998 | J20: =G19 -> 34.209998 | K20: =H19 -> 34.209998 | L20: =I19 -> 34.209998
A21: Staff cores to purchase | B21: cores | C21: =C19+C20 -> 34.209998 | D21: =D19+D20 -> 34.209998 | E21: =E19+E20 -> 34.209998 | F21: =F19+F20 -> 68.419996 | G21: =G19+G20 -> 68.419996 | H21: =H19+H20 -> 68.419996 | I21: =I19+I20 -> 68.419996 | J21: =J19+J20 -> 68.419996 | ... L21: =L19+L20 -> 68.419996
A23: Qserv data per node (capacity this LOY) | B23: TB/node | C23: 43.2 | D23: 43.2 | E23: 86.4 | F23: 86.4 | G23: 86.4 | H23: 86.4 | I23: 172.8 | J23: 172.8 | K23: 172.8 | L23: 172.8
A24: Qserv nodes needed (total on floor) | B24: nodes | C24: =CEILING('Ops Storage'!C55/C23,1) -> 82 | D24: =CEILING('Ops Storage'!D55/D23,1) -> 215 | E24: =CEILING('Ops Storage'!E55/E23,1) -> 200 | F24: =CEILING('Ops Storage'!F55/F23,1) -> 280 | G24: =CEILING('Ops Storage'!G55/G23,1) -> 362 | H24: =CEILING('Ops Storage'!H55/H23,1) -> 449 | I24: =CEILING('Ops Storage'!I55/I23,1) -> 270 | J24: =CEILING('Ops Storage'!J55/J23,1) -> 317 | ... L24: =CEILING('Ops Storage'!L55/L23,1) -> 417
A25: Qserv nodes annual increase | B25: nodes | C25: =C24 -> 82 | D25: =D24-C24 -> 133 | E25: =E24-D24 -> -15 | F25: =F24-E24 -> 80 | G25: =G24-F24 -> 82 | H25: =H24-G24 -> 87 | I25: =I24-H24 -> -179 | J25: =J24-I24 -> 47 | K25: =K24-J24 -> 49 | L25: =L24-K24 -> 51
A26: Qserv nodes refresh (3yr) | B26: nodes | C26: 0 | D26: 0 | E26: 0 | F26: =C25 -> 82 | G26: =D25 -> 133 | H26: =E25 -> -15 | I26: =F25 -> 80 | J26: =G25 -> 82 | K26: =H25 -> 87 | L26: =I25 -> -179
A27: Qserv nodes to purchase | B27: nodes | C27: =C25+C26 -> 82 | D27: =D25+D26 -> 133 | E27: =E25+E26 -> -15 | F27: =F25+F26 -> 162 | G27: =G25+G26 -> 215 | H27: =H25+H26 -> 72 | I27: =I25+I26 -> -99 | J27: =J25+J26 -> 129 | ... L27: =L25+L26 -> -128
A29: GPU H200 nodes | B29: nodes | C29: 2 | D29: 2 | E29: 2 | F29: 2 | G29: 2 | H29: 2 | I29: 2 | J29: 2 | K29: 2 | L29: 2
A31: K8s infrastructure nodes (workers) | B31: nodes | C31: 75 | D31: 75 | E31: 75 | F31: 75 | G31: 75 | H31: 75 | I31: 75 | J31: 75 | K31: 75 | L31: 75
A33: LSP cores per science user | B33: cores/user | C33: =C14/'Ops Storage'!C8 -> 0.068419996 | D33: =D14/'Ops Storage'!D8 -> 0.11403333 | E33: =E14/'Ops Storage'!E8 -> 0.14661428 | F33: =F14/'Ops Storage'!F8 -> 0.18245332 | G33: =G14/'Ops Storage'!G8 -> 0.22806665 | H33: =H14/'Ops Storage'!H8 -> 0.27367998 | I33: =I14/'Ops Storage'!I8 -> 0.31929331 | J33: =J14/'Ops Storage'!J8 -> 0.36490664 | ... L33: =L14/'Ops Storage'!L8 -> 0.45613331
A34: BATCH cores to purchase (DRP+DAC+Staff) | B34: cores | C34: =C7+C17+C21 -> 3797.3098 | D34: =D7+D17+D21 -> 3797.3098 | E34: =E7+E17+E21 -> 3797.3098 | F34: =F7+F17+F21 -> 7594.6195 | G34: =G7+G17+G21 -> 7594.6195 | H34: =H7+H17+H21 -> 7594.6195 | I34: =I7+I17+I21 -> 7594.6195 | J34: =J7+J17+J21 -> 7594.6195 | ... L34: =L7+L17+L21 -> 7594.6195
A35: Batch nodes to purchase (Torino-class) | B35: nodes | C35: =ROUNDUP(C34/120,0) -> 32 | D35: =ROUNDUP(D34/120,0) -> 32 | E35: =ROUNDUP(E34/120,0) -> 32 | F35: =ROUNDUP(F34/120,0) -> 64 | G35: =ROUNDUP(G34/120,0) -> 64 | H35: =ROUNDUP(H34/120,0) -> 64 | I35: =ROUNDUP(I34/120,0) -> 64 | J35: =ROUNDUP(J34/120,0) -> 64 | ... L35: =ROUNDUP(L34/120,0) -> 64
A36: Cumulative batch cores owned | B36: cores | C36: =17400+C34 -> 21197.31 | D36: =C36+D34 -> 24994.62 | E36: =D36+E34 -> 28791.929 | F36: =E36+F34 -> 36386.549 | G36: =F36+G34 -> 43981.168 | H36: =G36+H34 -> 51575.788 | I36: =H36+I34 -> 59170.407 | J36: =I36+J34 -> 66765.027 | K36: =J36+K34 -> 74359.647 | L36: =K36+L34 -> 81954.266
A99: AP cores (for formulas) | B99: 1188

Sheet Model
A1: Machine Catalog
A2: Type | B2: Cores | C2: RAM (GB) | D2: Eff Cores/Node | E2: Cost (USD) | F2: Purpose
A3: Milano (batch) | B3: 120 | C3: 480 | D3: 120 | E3: 11800 | F3: Current Slurm batch
A4: Torino (batch) | B4: 120 | C4: 720 | D4: 120 | E4: 16000 | F4: Future Slurm batch
A5: K8s node | B5: 48 | C5: 256 | D5: 27 | E5: 8000 | F5: Kubernetes infra
A6: Qserv node | B6: 32 | C6: 256 | D6: 32 | E6: 20000 | F6: Qserv/Cassandra bare-metal
A7: GPU H200 | B7: 128 | C7: 512 | D7: 128 | E7: 250000 | F7: GPU compute
A9: Storage Catalog
A10: Tier | B10: $/TB (2026)
A11: Flash (NVMe / Weka) | B11: 320
A12: Normal (SATA HDD / Ceph) | B12: 56
A13: Latent (Object Store) | B13: 36
A14: Tape (LTO) | B14: 12.5
A17: Price & Lifecycle Parameters
A18: Parameter | B18: Value | C18: Factor (1-rate)
A19: CPU annual price decrease | B19: 0 | C19: =1-B19 -> 1
A20: Storage annual price decrease | B20: 0 | C20: =1-B20 -> 1
A21: Qserv annual price decrease | B21: 0 | C21: =1-B21 -> 1
A22: Scale year (baseline) | B22: 2026
A23: Compute lifetime (years) | B23: 3
A24: Storage lifetime (years) | B24: 5
A27: Hosting & Overhead
A28: Nodes per rack | B28: 36
A29: Rack install cost (USD) | B29: 24000
A30: Hosting per node per year (USD) | B30: 566
A31: Overhead % of hardware | B31: 0.14
A32: Overhead fixed ($M/year) | B32: 0.15

Sheet Ops Costs
A1: Ops Costs — USDF Annual Hardware Spend
A2: Category | B2: Unit | C2: LOY1 (FY2026) | D2: LOY2 (FY2027) | E2: LOY3 (FY2028) | F2: LOY4 (FY2029) | G2: LOY5 (FY2030) | H2: LOY6 (FY2031) | I2: LOY7 (FY2032) | J2: LOY8 (FY2033) | K2: LOY9 (FY2034) | L2: LOY10 (FY2035) | M2: Total
A3: Batch compute (nodes * Torino price) | B3: $M | C3: ='Ops Compute'!C35*16000/1000000 -> 0.512 | D3: ='Ops Compute'!D35*16000/1000000 -> 0.512 | E3: ='Ops Compute'!E35*16000/1000000 -> 0.512 | F3: ='Ops Compute'!F35*16000/1000000 -> 1.024 | G3: ='Ops Compute'!G35*16000/1000000 -> 1.024 | H3: ='Ops Compute'!H35*16000/1000000 -> 1.024 | I3: ='Ops Compute'!I35*16000/1000000 -> 1.024 | J3: ='Ops Compute'!J35*16000/1000000 -> 1.024 | ... L3: ='Ops Compute'!L35*16000/1000000 -> 1.024 | M3: =SUM(C3:L3) -> 8.704
A4: Batch compute (price-adjusted) | B4: $M | C4: =C3*POWER(1,2026-2026) -> 0.512 | D4: =D3*POWER(1,2027-2026) -> 0.512 | E4: =E3*POWER(1,2028-2026) -> 0.512 | F4: =F3*POWER(1,2029-2026) -> 1.024 | G4: =G3*POWER(1,2030-2026) -> 1.024 | H4: =H3*POWER(1,2031-2026) -> 1.024 | I4: =I3*POWER(1,2032-2026) -> 1.024 | J4: =J3*POWER(1,2033-2026) -> 1.024 | K4: =K3*POWER(1,2034-2026) -> 1.024 | L4: =L3*POWER(1,2035-2026) -> 1.024 | M4: =SUM(C4:L4) -> 8.704
A5: Qserv node purchases | B5: $M | C5: ='Ops Compute'!C27*20000/1000000 -> 1.64 | D5: ='Ops Compute'!D27*20000/1000000 -> 2.66 | E5: ='Ops Compute'!E27*20000/1000000 -> -0.3 | F5: ='Ops Compute'!F27*20000/1000000 -> 3.24 | G5: ='Ops Compute'!G27*20000/1000000 -> 4.3 | H5: ='Ops Compute'!H27*20000/1000000 -> 1.44 | I5: ='Ops Compute'!I27*20000/1000000 -> -1.98 | J5: ='Ops Compute'!J27*20000/1000000 -> 2.58 | ... L5: ='Ops Compute'!L27*20000/1000000 -> -2.56 | M5: =SUM(C5:L5) -> 13.74
A6: Qserv (price-adjusted) | B6: $M | C6: =C5*POWER(1,2026-2026) -> 1.64 | D6: =D5*POWER(1,2027-2026) -> 2.66 | E6: =E5*POWER(1,2028-2026) -> -0.3 | F6: =F5*POWER(1,2029-2026) -> 3.24 | G6: =G5*POWER(1,2030-2026) -> 4.3 | H6: =H5*POWER(1,2031-2026) -> 1.44 | I6: =I5*POWER(1,2032-2026) -> -1.98 | J6: =J5*POWER(1,2033-2026) -> 2.58 | K6: =K5*POWER(1,2034-2026) -> 2.72 | L6: =L5*POWER(1,2035-2026) -> -2.56 | M6: =SUM(C6:L6) -> 13.74
A7: GPU H200 purchases | B7: $M | C7: ='Ops Compute'!C29*250000/1000000 -> 0.5 | D7: ='Ops Compute'!D29*250000/1000000 -> 0.5 | E7: ='Ops Compute'!E29*250000/1000000 -> 0.5 | F7: ='Ops Compute'!F29*250000/1000000 -> 0.5 | G7: ='Ops Compute'!G29*250000/1000000 -> 0.5 | H7: ='Ops Compute'!H29*250000/1000000 -> 0.5 | I7: ='Ops Compute'!I29*250000/1000000 -> 0.5 | J7: ='Ops Compute'!J29*250000/1000000 -> 0.5 | ... L7: ='Ops Compute'!L29*250000/1000000 -> 0.5 | M7: =SUM(C7:L7) -> 5
A8: K8s infrastructure | B8: $M | C8: ='Ops Compute'!C31*8000/1000000 -> 0.6 | D8: 0 | E8: 0 | F8: 0 | G8: 0 | H8: 0 | I8: 0 | J8: 0 | K8: 0 | L8: 0 | M8: =SUM(C8:L8) -> 0.6
A9: Total Compute Cost | B9: $M | C9: =C4+C6+C7+C8 -> 3.252 | D9: =D4+D6+D7+D8 -> 3.672 | E9: =E4+E6+E7+E8 -> 0.712 | F9: =F4+F6+F7+F8 -> 4.764 | G9: =G4+G6+G7+G8 -> 5.824 | H9: =H4+H6+H7+H8 -> 2.964 | I9: =I4+I6+I7+I8 -> -0.456 | J9: =J4+J6+J7+J8 -> 4.104 | ... L9: =L4+L6+L7+L8 -> -1.036 | M9: =SUM(C9:L9) -> 28.044
A11: Storage Costs
A12: Flash storage (NVMe) | B12: $M | C12: ='Ops Storage'!C51*320/1000000 -> 0.11295966 | D12: =MAX(0,'Ops Storage'!D51-'Ops Storage'!C51)*320/1000000 -> 0.0609336 | E12: =MAX(0,'Ops Storage'!E51-'Ops Storage'!D51)*320/1000000 -> 0.068955264 | F12: =MAX(0,'Ops Storage'!F51-'Ops Storage'!E51)*320/1000000 -> 0.025966656 | G12: =MAX(0,'Ops Storage'!G51-'Ops Storage'!F51)*320/1000000 -> 0.021703968 | H12: =MAX(0,'Ops Storage'!H51-'Ops Storage'!G51)*320/1000000 -> 0.020211648 | I12: =MAX(0,'Ops Storage'!I51-'Ops Storage'!H51)*320/1000000 -> 0.019343808 | J12: =MAX(0,'Ops Storage'!J51-'Ops Storage'!I51)*320/1000000 -> 0.018993888 | K12: =MAX(0,'Ops Storage'!K51-'Ops Storage'!J51)*320/1000000 -> 0.01809504 | L12: =MAX(0,'Ops Storage'!L51-'Ops Storage'!K51)*320/1000000 -> 0.01753056 | M12: =SUM(C12:L12) -> 0.3846941
A13: Normal storage (HDD) | B13: $M | C13: ='Ops Storage'!C53*56/1000000 -> 0.83020933 | D13: =MAX(0,'Ops Storage'!D53-'Ops Storage'!C53)*56/1000000 -> 0.23870592 | E13: =MAX(0,'Ops Storage'!E53-'Ops Storage'!D53)*56/1000000 -> 0.23488053 | F13: =MAX(0,'Ops Storage'!F53-'Ops Storage'!E53)*56/1000000 -> 0.23064879 | G13: =MAX(0,'Ops Storage'!G53-'Ops Storage'!F53)*56/1000000 -> 0.21995298 | H13: =MAX(0,'Ops Storage'!H53-'Ops Storage'!G53)*56/1000000 -> 0.22612432 | I13: =MAX(0,'Ops Storage'!I53-'Ops Storage'!H53)*56/1000000 -> 0.23475647 | J13: =MAX(0,'Ops Storage'!J53-'Ops Storage'!I53)*56/1000000 -> 0.24275942 | K13: =MAX(0,'Ops Storage'!K53-'Ops Storage'!J53)*56/1000000 -> 0.2479959 | L13: =MAX(0,'Ops Storage'!L53-'Ops Storage'!K53)*56/1000000 -> 0.25619388 | M13: =SUM(C13:L13) -> 2.9622275
A14: Object Store (latent) | B14: $M | C14: ='Ops Storage'!C61*36/1000000 -> 0.29080422 | D14: =MAX(0,'Ops Storage'!D61-'Ops Storage'!C61)*36/1000000 -> 0.29080422 | E14: =MAX(0,'Ops Storage'!E61-'Ops Storage'!D61)*36/1000000 -> 0.19141895 | F14: =MAX(0,'Ops Storage'!F61-'Ops Storage'!E61)*36/1000000 -> 0.047498151 | G14: =MAX(0,'Ops Storage'!G61-'Ops Storage'!F61)*36/1000000 -> 0.047498151 | H14: =MAX(0,'Ops Storage'!H61-'Ops Storage'!G61)*36/1000000 -> 0.047498151 | I14: =MAX(0,'Ops Storage'!I61-'Ops Storage'!H61)*36/1000000 -> 0.047498151 | J14: =MAX(0,'Ops Storage'!J61-'Ops Storage'!I61)*36/1000000 -> 0.047498151 | K14: =MAX(0,'Ops Storage'!K61-'Ops Storage'!J61)*36/1000000 -> 0.047498151 | L14: =MAX(0,'Ops Storage'!L61-'Ops Storage'!K61)*36/1000000 -> 0.047498151 | M14: =SUM(C14:L14) -> 1.1055145
A15: Tape storage | B15: $M | C15: ='Ops Storage'!C66*12.5/1000000 -> 0.18472895 | D15: =MAX(0,'Ops Storage'!D66-'Ops Storage'!C66)*12.5/1000000 -> 0.20960938 | E15: =MAX(0,'Ops Storage'!E66-'Ops Storage'!D66)*12.5/1000000 -> 0.2333475 | F15: =MAX(0,'Ops Storage'!F66-'Ops Storage'!E66)*12.5/1000000 -> 0.25505318 | G15: =MAX(0,'Ops Storage'!G66-'Ops Storage'!F66)*12.5/1000000 -> 0.27261095 | H15: =MAX(0,'Ops Storage'!H66-'Ops Storage'!G66)*12.5/1000000 -> 0.29039832 | I15: =MAX(0,'Ops Storage'!I66-'Ops Storage'!H66)*12.5/1000000 -> 0.30850682 | J15: =MAX(0,'Ops Storage'!J66-'Ops Storage'!I66)*12.5/1000000 -> 0.32691305 | K15: =MAX(0,'Ops Storage'!K66-'Ops Storage'!J66)*12.5/1000000 -> 0.34551408 | L15: =MAX(0,'Ops Storage'!L66-'Ops Storage'!K66)*12.5/1000000 -> 0.36442011 | M15: =SUM(C15:L15) -> 2.7911023
A16: Total Storage (price-adjusted) | B16: $M | C16: =(C12+C13+C14+C15)*POWER(1,2026-2026) -> 1.4187022 | D16: =(D12+D13+D14+D15)*POWER(1,2027-2026) -> 0.80005313 | E16: =(E12+E13+E14+E15)*POWER(1,2028-2026) -> 0.72860224 | F16: =(F12+F13+F14+F15)*POWER(1,2029-2026) -> 0.55916677 | G16: =(G12+G13+G14+G15)*POWER(1,2030-2026) -> 0.56176605 | H16: =(H12+H13+H14+H15)*POWER(1,2031-2026) -> 0.58423243 | I16: =(I12+I13+I14+I15)*POWER(1,2032-2026) -> 0.61010524 | J16: =(J12+J13+J14+J15)*POWER(1,2033-2026) -> 0.63616451 | K16: =(K12+K13+K14+K15)*POWER(1,2034-2026) -> 0.65910318 | L16: =(L12+L13+L14+L15)*POWER(1,2035-2026) -> 0.6856427 | M16: =SUM(C16:L16) -> 7.2435384
A17: Total Storage (base pricing) | B17: $M | C17: =C12+C13+C14+C15 -> 1.4187022 | D17: =D12+D13+D14+D15 -> 0.80005313 | E17: =E12+E13+E14+E15 -> 0.72860224 | F17: =F12+F13+F14+F15 -> 0.55916677 | G17: =G12+G13+G14+G15 -> 0.56176605 | H17: =H12+H13+H14+H15 -> 0.58423243 | I17: =I12+I13+I14+I15 -> 0.61010524 | J17: =J12+J13+J14+J15 -> 0.63616451 | ... L17: =L12+L13+L14+L15 -> 0.6856427 | M17: =SUM(C17:L17) -> 7.2435384
A19: Hosting & Overhead
A20: USDF hosting (nodes * $/node/yr) | B20: $M | C20: =CEILING('Ops Compute'!C36/Model!$D$4,1)*Model!$B$30/1000000 -> 0.100182 | D20: =CEILING('Ops Compute'!D36/Model!$D$4,1)*Model!$B$30/1000000 -> 0.118294 | E20: =CEILING('Ops Compute'!E36/Model!$D$4,1)*Model!$B$30/1000000 -> 0.13584 | F20: =CEILING('Ops Compute'!F36/Model!$D$4,1)*Model!$B$30/1000000 -> 0.172064 | G20: =CEILING('Ops Compute'!G36/Model!$D$4,1)*Model!$B$30/1000000 -> 0.207722 | H20: =CEILING('Ops Compute'!H36/Model!$D$4,1)*Model!$B$30/1000000 -> 0.24338 | I20: =CEILING('Ops Compute'!I36/Model!$D$4,1)*Model!$B$30/1000000 -> 0.279604 | J20: =CEILING('Ops Compute'!J36/Model!$D$4,1)*Model!$B$30/1000000 -> 0.315262 | ... L20: =CEILING('Ops Compute'!L36/Model!$D$4,1)*Model!$B$30/1000000 -> 0.386578 | M20: =SUM(C20:L20) -> 2.309846
A21: Overhead (14% HW + $0.15M fixed) | B21: $M | C21: =0.14*(C9+C17)+0.15 -> 0.8038983 | D21: =0.14*(D9+D17)+0.15 -> 0.77608744 | E21: =0.14*(E9+E17)+0.15 -> 0.35168431 | F21: =0.14*(F9+F17)+0.15 -> 0.89524335 | G21: =0.14*(G9+G17)+0.15 -> 1.0440072 | H21: =0.14*(H9+H17)+0.15 -> 0.64675254 | I21: =0.14*(I9+I17)+0.15 -> 0.17157473 | J21: =0.14*(J9+J17)+0.15 -> 0.81362303 | ... L21: =0.14*(L9+L17)+0.15 -> 0.10094998 | M21: =SUM(C21:L21) -> 6.4402554
A23: GRAND TOTALS
A24: Annual Total (base pricing) | B24: $M | C24: =C9+C17+C20+C21 -> 5.5747825 | D24: =D9+D17+D20+D21 -> 5.3664346 | E24: =E9+E17+E20+E21 -> 1.9281266 | F24: =F9+F17+F20+F21 -> 6.3904741 | G24: =G9+G17+G20+G21 -> 7.6374953 | H24: =H9+H17+H20+H21 -> 4.438365 | I24: =I9+I17+I20+I21 -> 0.60528398 | J24: =J9+J17+J20+J21 -> 5.8690495 | ... L24: =L9+L17+L20+L21 -> 0.13717068 | M24: =SUM(C24:L24) -> 44.03764
A25: Annual Total (price-adjusted) | B25: $M | C25: =C4+C6+C7+C8+C16+C20+C21 -> 5.5747825 | D25: =D4+D6+D7+D8+D16+D20+D21 -> 5.3664346 | E25: =E4+E6+E7+E8+E16+E20+E21 -> 1.9281266 | F25: =F4+F6+F7+F8+F16+F20+F21 -> 6.3904741 | G25: =G4+G6+G7+G8+G16+G20+G21 -> 7.6374953 | H25: =H4+H6+H7+H8+H16+H20+H21 -> 4.438365 | I25: =I4+I6+I7+I8+I16+I20+I21 -> 0.60528398 | J25: =J4+J6+J7+J8+J16+J20+J21 -> 5.8690495 | ... L25: =L4+L6+L7+L8+L16+L20+L21 -> 0.13717068 | M25: =SUM(C25:L25) -> 44.03764
A26: Cumulative (price-adjusted) | B26: $M | C26: =C25 -> 5.5747825 | D26: =C26+D25 -> 10.941217 | E26: =D26+E25 -> 12.869344 | F26: =E26+F25 -> 19.259818 | G26: =F26+G25 -> 26.897313 | H26: =G26+H25 -> 31.335678 | I26: =H26+I25 -> 31.940962 | J26: =I26+J25 -> 37.810012 | K26: =J26+K25 -> 43.900469 | L26: =K26+L25 -> 44.03764

Sheet Purchase Plan
A1: Annual Purchase Plan — USDF
A2: Metric | B2: Unit | C2: LOY1 | D2: LOY2 | E2: LOY3 | F2: LOY4 | G2: LOY5 | H2: LOY6 | I2: LOY7 | J2: LOY8 | K2: LOY9 | L2: LOY10
A3: Fiscal Year | C3: FY2026 | D3: FY2027 | E3: FY2028 | F3: FY2029 | G3: FY2030 | H3: FY2031 | I3: FY2032 | J3: FY2033 | K3: FY2034 | L3: FY2035
A4: Milestone | C4: DP2 | D4: DR1 | E4: DR2 | F4: DR3 | G4: DR4 | H4: DR5 | I4: DR6 | J4: DR7 | K4: DR8 | L4: DR9
A6: COMPUTE PURCHASES
A7: DRP cores needed | B7: cores | C7: ='Ops Compute'!C4 -> 3420.9998 | D7: ='Ops Compute'!D4 -> 6841.9996 | E7: ='Ops Compute'!E4 -> 10262.999 | F7: ='Ops Compute'!F4 -> 13683.999 | G7: ='Ops Compute'!G4 -> 17104.999 | H7: ='Ops Compute'!H4 -> 20525.999 | I7: ='Ops Compute'!I4 -> 23946.999 | J7: ='Ops Compute'!J4 -> 27367.998 | ... L7: ='Ops Compute'!L4 -> 34209.998
A8: USDF DRP cores (100%) | B8: cores | C8: =C7 -> 3420.9998 | D8: =D7 -> 6841.9996 | E8: =E7 -> 10262.999 | F8: =F7 -> 13683.999 | G8: =G7 -> 17104.999 | H8: =H7 -> 20525.999 | I8: =I7 -> 23946.999 | J8: =J7 -> 27367.998 | ... L8: =L7 -> 34209.998
A9: AP cores | B9: cores | C9: ='Ops Compute'!C9 -> 1188 | D9: ='Ops Compute'!D9 -> 1188 | E9: ='Ops Compute'!E9 -> 1188 | F9: ='Ops Compute'!F9 -> 1188 | G9: ='Ops Compute'!G9 -> 1188 | H9: ='Ops Compute'!H9 -> 1188 | I9: ='Ops Compute'!I9 -> 1188 | J9: ='Ops Compute'!J9 -> 1188 | ... L9: ='Ops Compute'!L9 -> 1188
A10: DAC/LSP + Staff cores | B10: cores | C10: ='Ops Compute'!C14+'Ops Compute'!C18 -> 376.30998 | D10: ='Ops Compute'!D14+'Ops Compute'!D18 -> 752.61995 | E10: ='Ops Compute'!E14+'Ops Compute'!E18 -> 1128.9299 | F10: ='Ops Compute'!F14+'Ops Compute'!F18 -> 1505.2399 | G10: ='Ops Compute'!G14+'Ops Compute'!G18 -> 1881.5499 | H10: ='Ops Compute'!H14+'Ops Compute'!H18 -> 2257.8599 | I10: ='Ops Compute'!I14+'Ops Compute'!I18 -> 2634.1698 | J10: ='Ops Compute'!J14+'Ops Compute'!J18 -> 3010.4798 | ... L10: ='Ops Compute'!L14+'Ops Compute'!L18 -> 3763.0998
A11: Total batch cores needed (DRP+DAC+Staff) | B11: cores | C11: =C8+C10 -> 3797.3098 | D11: =D8+D10 -> 7594.6195 | E11: =E8+E10 -> 11391.929 | F11: =F8+F10 -> 15189.239 | G11: =G8+G10 -> 18986.549 | H11: =H8+H10 -> 22783.859 | I11: =I8+I10 -> 26581.168 | J11: =J8+J10 -> 30378.478 | ... L11: =L8+L10 -> 37973.098
A12: Cumulative cores available | B12: cores | C12: =17400+MAX(0,C14) -> 21197.31 | D12: =C12+MAX(0,D14) -> 24994.62 | E12: =D12+MAX(0,E14) -> 28791.929 | F12: =E12+MAX(0,F14) -> 36386.549 | G12: =F12+MAX(0,G14) -> 43981.168 | H12: =G12+MAX(0,H14) -> 51575.788 | I12: =H12+MAX(0,I14) -> 59170.407 | J12: =I12+MAX(0,J14) -> 66765.027 | K12: =J12+MAX(0,K14) -> 74359.647 | L12: =K12+MAX(0,L14) -> 81954.266
A13: Compute gap (need − available) | B13: cores | C13: =C11-C12 -> -17400 | D13: =D11-D12 -> -17400 | E13: =E11-E12 -> -17400 | F13: =F11-F12 -> -21197.31 | G13: =G11-G12 -> -24994.62 | H13: =H11-H12 -> -28791.929 | I13: =I11-I12 -> -32589.239 | J13: =J11-J12 -> -36386.549 | ... L13: =L11-L12 -> -43981.168
A14: Batch cores to purchase (= Ops Compute) | B14: cores | C14: ='Ops Compute'!C34 -> 3797.3098 | D14: ='Ops Compute'!D34 -> 3797.3098 | E14: ='Ops Compute'!E34 -> 3797.3098 | F14: ='Ops Compute'!F34 -> 7594.6195 | G14: ='Ops Compute'!G34 -> 7594.6195 | H14: ='Ops Compute'!H34 -> 7594.6195 | I14: ='Ops Compute'!I34 -> 7594.6195 | J14: ='Ops Compute'!J34 -> 7594.6195 | ... L14: ='Ops Compute'!L34 -> 7594.6195
A15: Batch nodes to purchase (= Ops Compute) | B15: nodes | C15: ='Ops Compute'!C35 -> 32 | D15: ='Ops Compute'!D35 -> 32 | E15: ='Ops Compute'!E35 -> 32 | F15: ='Ops Compute'!F35 -> 64 | G15: ='Ops Compute'!G35 -> 64 | H15: ='Ops Compute'!H35 -> 64 | I15: ='Ops Compute'!I35 -> 64 | J15: ='Ops Compute'!J35 -> 64 | ... L15: ='Ops Compute'!L35 -> 64
A16: K8s nodes needed | B16: nodes | C16: 75 | D16: 79 | E16: 83 | F16: 87 | G16: 91 | H16: 96 | I16: 101 | J16: 106 | K16: 111 | L16: 116
A17: K8s incremental purchase | B17: nodes | C17: 0 | D17: =MAX(0,D16-C16) -> 4 | E17: =MAX(0,E16-D16) -> 4 | F17: =MAX(0,F16-E16) -> 4 | G17: =MAX(0,G16-F16) -> 4 | H17: =MAX(0,H16-G16) -> 5 | I17: =MAX(0,I16-H16) -> 5 | J17: =MAX(0,J16-I16) -> 5 | K17: =MAX(0,K16-J16) -> 5 | L17: =MAX(0,L16-K16) -> 5
A18: Qserv nodes to purchase (annual, = Ops Compute) | B18: nodes | C18: ='Ops Compute'!C27 -> 82 | D18: ='Ops Compute'!D27 -> 133 | E18: ='Ops Compute'!E27 -> -15 | F18: ='Ops Compute'!F27 -> 162 | G18: ='Ops Compute'!G27 -> 215 | H18: ='Ops Compute'!H27 -> 72 | I18: ='Ops Compute'!I27 -> -99 | J18: ='Ops Compute'!J27 -> 129 | ... L18: ='Ops Compute'!L27 -> -128
A20: STORAGE PURCHASES (by tier)
A21: Flash (NVMe) on floor | B21: TB | C21: ='Ops Storage'!C51 -> 352.99895 | D21: ='Ops Storage'!D51 -> 543.41645 | E21: ='Ops Storage'!E51 -> 758.90165 | F21: ='Ops Storage'!F51 -> 840.04745 | G21: ='Ops Storage'!G51 -> 907.87235 | H21: ='Ops Storage'!H51 -> 971.03375 | I21: ='Ops Storage'!I51 -> 1031.4831 | J21: ='Ops Storage'!J51 -> 1090.839 | ... L21: ='Ops Storage'!L51 -> 1202.169
A22: Flash (NVMe) incremental purchase | B22: TB | C22: =C21 -> 352.99895 | D22: =MAX(0,D21-C21) -> 190.4175 | E22: =MAX(0,E21-D21) -> 215.4852 | F22: =MAX(0,F21-E21) -> 81.1458 | G22: =MAX(0,G21-F21) -> 67.8249 | H22: =MAX(0,H21-G21) -> 63.1614 | I22: =MAX(0,I21-H21) -> 60.4494 | J22: =MAX(0,J21-I21) -> 59.3559 | K22: =MAX(0,K21-J21) -> 56.547 | L22: =MAX(0,L21-K21) -> 54.783
A23: Normal HDD on floor | B23: TB | C23: ='Ops Storage'!C53 -> 14825.167 | D23: ='Ops Storage'!D53 -> 19087.772 | E23: ='Ops Storage'!E53 -> 23282.068 | F23: ='Ops Storage'!F53 -> 27400.796 | G23: ='Ops Storage'!G53 -> 31328.528 | H23: ='Ops Storage'!H53 -> 35366.462 | I23: ='Ops Storage'!I53 -> 39558.542 | J23: ='Ops Storage'!J53 -> 43893.531 | ... L23: ='Ops Storage'!L53 -> 52896.92
A24: Normal HDD incremental purchase | B24: TB | C24: =C23 -> 14825.167 | D24: =MAX(0,D23-C23) -> 4262.6058 | E24: =MAX(0,E23-D23) -> 4194.2952 | F24: =MAX(0,F23-E23) -> 4118.7283 | G24: =MAX(0,G23-F23) -> 3927.7318 | H24: =MAX(0,H23-G23) -> 4037.9342 | I24: =MAX(0,I23-H23) -> 4192.0798 | J24: =MAX(0,J23-I23) -> 4334.9897 | K24: =MAX(0,K23-J23) -> 4428.4982 | L24: =MAX(0,L23-K23) -> 4574.8908
A25: Object Store on floor | B25: TB | C25: ='Ops Storage'!C61 -> 8077.8951 | D25: ='Ops Storage'!D61 -> 16155.79 | E25: ='Ops Storage'!E61 -> 21472.983 | F25: ='Ops Storage'!F61 -> 22792.376 | G25: ='Ops Storage'!G61 -> 24111.769 | H25: ='Ops Storage'!H61 -> 25431.162 | I25: ='Ops Storage'!I61 -> 26750.556 | J25: ='Ops Storage'!J61 -> 28069.949 | ... L25: ='Ops Storage'!L61 -> 30708.735
A26: Object Store incremental purchase | B26: TB | C26: =C25 -> 8077.8951 | D26: =MAX(0,D25-C25) -> 8077.8951 | E26: =MAX(0,E25-D25) -> 5317.1931 | F26: =MAX(0,F25-E25) -> 1319.3931 | G26: =MAX(0,G25-F25) -> 1319.3931 | H26: =MAX(0,H25-G25) -> 1319.3931 | I26: =MAX(0,I25-H25) -> 1319.3931 | J26: =MAX(0,J25-I25) -> 1319.3931 | K26: =MAX(0,K25-J25) -> 1319.3931 | L26: =MAX(0,L25-K25) -> 1319.3931
A27: Qserv on floor | B27: TB | C27: ='Ops Storage'!C55 -> 3509.5635 | D27: ='Ops Storage'!D55 -> 9257.301 | E27: ='Ops Storage'!E55 -> 17275.217 | F27: ='Ops Storage'!F55 -> 24143.762 | G27: ='Ops Storage'!G55 -> 31276.567 | H27: ='Ops Storage'!H55 -> 38733.734 | I27: ='Ops Storage'!I55 -> 46554.739 | J27: ='Ops Storage'!J55 -> 54716.22 | ... L27: ='Ops Storage'!L55 -> 72016.512
A28: Qserv incremental purchase | B28: TB | C28: =C27 -> 3509.5635 | D28: =MAX(0,D27-C27) -> 5747.7375 | E28: =MAX(0,E27-D27) -> 8017.9158 | F28: =MAX(0,F27-E27) -> 6868.5453 | G28: =MAX(0,G27-F27) -> 7132.8045 | H28: =MAX(0,H27-G27) -> 7457.1672 | I28: =MAX(0,I27-H27) -> 7821.0054 | J28: =MAX(0,J27-I27) -> 8161.4805 | K28: =MAX(0,K27-J27) -> 8489.7594 | L28: =MAX(0,L27-K27) -> 8810.5326
A30: ONLINE total on floor (hot+warm) | B30: TB | C30: =C21+C23+C25+C27 -> 26765.624 | D30: =D21+D23+D25+D27 -> 45044.28 | E30: =E21+E23+E25+E27 -> 62789.169 | F30: =F21+F23+F25+F27 -> 75176.982 | G30: =G21+G23+G25+G27 -> 87624.736 | H30: =H21+H23+H25+H27 -> 100502.39 | I30: =I21+I23+I25+I27 -> 113895.32 | J30: =J21+J23+J25+J27 -> 127770.54 | ... L30: =L21+L23+L25+L27 -> 156824.34
A31: Online available (installed + purchases) | B31: TB | C31: =30000+C32 -> 30000 | D31: =C31+D32 -> 45044.28 | E31: =D31+E32 -> 62789.169 | F31: =E31+F32 -> 75176.982 | G31: =F31+G32 -> 87624.736 | H31: =G31+H32 -> 100502.39 | I31: =H31+I32 -> 113895.32 | J31: =I31+J32 -> 127770.54 | K31: =J31+K32 -> 142064.74 | L31: =K31+L32 -> 156824.34
A32: Online purchase (hot+warm) | B32: TB | C32: =MAX(0,C30-30000) -> 0 | D32: =MAX(0,D30-C31) -> 15044.28 | E32: =MAX(0,E30-D31) -> 17744.889 | F32: =MAX(0,F30-E31) -> 12387.812 | G32: =MAX(0,G30-F31) -> 12447.754 | H32: =MAX(0,H30-G31) -> 12877.656 | I32: =MAX(0,I30-H31) -> 13392.928 | J32: =MAX(0,J30-I31) -> 13875.219 | K32: =MAX(0,K30-J31) -> 14294.198 | L32: =MAX(0,L30-K31) -> 14759.599
A33: Online purchase (PB) | B33: PB | C33: =C32/1000 -> 0 | D33: =D32/1000 -> 15.04428 | E33: =E32/1000 -> 17.744889 | F33: =F32/1000 -> 12.387812 | G33: =G32/1000 -> 12.447754 | H33: =H32/1000 -> 12.877656 | I33: =I32/1000 -> 13.392928 | J33: =J32/1000 -> 13.875219 | ... L33: =L32/1000 -> 14.759599
A35: Tape on floor | B35: TB | C35: ='Ops Storage'!C66 -> 14778.316 | D35: ='Ops Storage'!D66 -> 31547.067 | E35: ='Ops Storage'!E66 -> 50214.866 | F35: ='Ops Storage'!F66 -> 70619.121 | G35: ='Ops Storage'!G66 -> 92427.997 | H35: ='Ops Storage'!H66 -> 115659.86 | I35: ='Ops Storage'!I66 -> 140340.41 | J35: ='Ops Storage'!J66 -> 166493.45 | ... L35: ='Ops Storage'!L66 -> 223288.19
A36: Tape incremental purchase | B36: TB | C36: =C35 -> 14778.316 | D36: =MAX(0,D35-C35) -> 16768.75 | E36: =MAX(0,E35-D35) -> 18667.8 | F36: =MAX(0,F35-E35) -> 20404.254 | G36: =MAX(0,G35-F35) -> 21808.876 | H36: =MAX(0,H35-G35) -> 23231.865 | I36: =MAX(0,I35-H35) -> 24680.545 | J36: =MAX(0,J35-I35) -> 26153.044 | K36: =MAX(0,K35-J35) -> 27641.127 | L36: =MAX(0,L35-K35) -> 29153.608
A37: Tape purchase (PB) | B37: PB | C37: =C36/1000 -> 14.778316 | D37: =D36/1000 -> 16.76875 | E37: =E36/1000 -> 18.6678 | F37: =F36/1000 -> 20.404254 | G37: =G36/1000 -> 21.808876 | H37: =H36/1000 -> 23.231865 | I37: =I36/1000 -> 24.680545 | J37: =J36/1000 -> 26.153044 | ... L37: =L36/1000 -> 29.153608
A39: TOTAL storage purchase (TB) | B39: TB | C39: =C32+C36 -> 14778.316 | D39: =D32+D36 -> 31813.03 | E39: =E32+E36 -> 36412.689 | F39: =F32+F36 -> 32792.067 | G39: =G32+G36 -> 34256.631 | H39: =H32+H36 -> 36109.521 | I39: =I32+I36 -> 38073.473 | J39: =J32+J36 -> 40028.263 | ... L39: =L32+L36 -> 43913.208
A40: TOTAL storage purchase (PB) | B40: PB | C40: =C39/1000 -> 14.778316 | D40: =D39/1000 -> 31.81303 | E40: =E39/1000 -> 36.412689 | F40: =F39/1000 -> 32.792067 | G40: =G39/1000 -> 34.256631 | H40: =H39/1000 -> 36.109521 | I40: =I39/1000 -> 38.073473 | J40: =J39/1000 -> 40.028263 | ... L40: =L39/1000 -> 43.913208
A42: LOY1 (FY2026) — CURRENT YEAR DETAIL
A43: Months elapsed in FY | B43: 3
A44: Months remaining | B44: 9
A45: Currently running | B45: DP2 (10% of DR1)
A47: DP2 compute (core-hours) | B47: =ROUND('Ops Compute'!C3*0.1,0) -> 1642080
...

Sheet International Compute
A1: International DRP Compute Sharing
A2: Metric | B2: Unit | C2: LOY1 | D2: LOY2 | E2: LOY3 | F2: LOY4 | G2: LOY5 | H2: LOY6 | I2: LOY7 | J2: LOY8 | K2: LOY9 | L2: LOY10
A3: Fiscal Year | C3: FY2026 | D3: FY2027 | E3: FY2028 | F3: FY2029 | G3: FY2030 | H3: FY2031 | I3: FY2032 | J3: FY2033 | K3: FY2034 | L3: FY2035
A4: Milestone | C4: DP2 | D4: DR1 | E4: DR2 | F4: DR3 | G4: DR4 | H4: DR5 | I4: DR6 | J4: DR7 | K4: DR8 | L4: DR9
A6: DRP COMPUTE SPLIT
A7: Total DRP core-hours | B7: core-hrs | C7: ='Ops Compute'!C3 -> 16420799 | D7: ='Ops Compute'!D3 -> 32841598 | E7: ='Ops Compute'!E3 -> 49262397 | F7: ='Ops Compute'!F3 -> 65683196 | G7: ='Ops Compute'!G3 -> 82103995 | H7: ='Ops Compute'!H3 -> 98524794 | I7: ='Ops Compute'!I3 -> 114945593 | J7: ='Ops Compute'!J3 -> 131366392 | ... L7: ='Ops Compute'!L3 -> 164207990
A8: Total DRP cores | B8: cores | C8: ='Ops Compute'!C4 -> 3420.9998 | D8: ='Ops Compute'!D4 -> 6841.9996 | E8: ='Ops Compute'!E4 -> 10262.999 | F8: ='Ops Compute'!F4 -> 13683.999 | G8: ='Ops Compute'!G4 -> 17104.999 | H8: ='Ops Compute'!H4 -> 20525.999 | I8: ='Ops Compute'!I4 -> 23946.999 | J8: ='Ops Compute'!J4 -> 27367.998 | ... L8: ='Ops Compute'!L4 -> 34209.998
A9: DRP Cores by Facility
A10: USDF (35%) | B10: cores | C10: =ROUND(C8*0.35,0) -> 1197 | D10: =ROUND(D8*0.35,0) -> 2395 | E10: =ROUND(E8*0.35,0) -> 3592 | F10: =ROUND(F8*0.35,0) -> 4789 | G10: =ROUND(G8*0.35,0) -> 5987 | H10: =ROUND(H8*0.35,0) -> 7184 | I10: =ROUND(I8*0.35,0) -> 8381 | J10: =ROUND(J8*0.35,0) -> 9579 | ... L10: =ROUND(L8*0.35,0) -> 11973
A11: France / CC-IN2P3 (40%) | B11: cores | C11: =ROUND(C8*0.4,0) -> 1368 | D11: =ROUND(D8*0.4,0) -> 2737 | E11: =ROUND(E8*0.4,0) -> 4105 | F11: =ROUND(F8*0.4,0) -> 5474 | G11: =ROUND(G8*0.4,0) -> 6842 | H11: =ROUND(H8*0.4,0) -> 8210 | I11: =ROUND(I8*0.4,0) -> 9579 | J11: =ROUND(J8*0.4,0) -> 10947 | ... L11: =ROUND(L8*0.4,0) -> 13684
A12: UK / UKDF (25%) | B12: cores | C12: =ROUND(C8*0.25,0) -> 855 | D12: =ROUND(D8*0.25,0) -> 1710 | E12: =ROUND(E8*0.25,0) -> 2566 | F12: =ROUND(F8*0.25,0) -> 3421 | G12: =ROUND(G8*0.25,0) -> 4276 | H12: =ROUND(H8*0.25,0) -> 5131 | I12: =ROUND(I8*0.25,0) -> 5987 | J12: =ROUND(J8*0.25,0) -> 6842 | ... L12: =ROUND(L8*0.25,0) -> 8552
A14: DRP Core-Hours by Facility
A15: USDF (35%) | B15: core-hrs | C15: =ROUND(C7*0.35,0) -> 5747280 | D15: =ROUND(D7*0.35,0) -> 11494559 | E15: =ROUND(E7*0.35,0) -> 17241839 | F15: =ROUND(F7*0.35,0) -> 22989119 | G15: =ROUND(G7*0.35,0) -> 28736398 | H15: =ROUND(H7*0.35,0) -> 34483678 | I15: =ROUND(I7*0.35,0) -> 40230958 | J15: =ROUND(J7*0.35,0) -> 45978237 | ... L15: =ROUND(L7*0.35,0) -> 57472797
A16: France / CC-IN2P3 (40%) | B16: core-hrs | C16: =ROUND(C7*0.4,0) -> 6568320 | D16: =ROUND(D7*0.4,0) -> 13136639 | E16: =ROUND(E7*0.4,0) -> 19704959 | F16: =ROUND(F7*0.4,0) -> 26273278 | G16: =ROUND(G7*0.4,0) -> 32841598 | H16: =ROUND(H7*0.4,0) -> 39409918 | I16: =ROUND(I7*0.4,0) -> 45978237 | J16: =ROUND(J7*0.4,0) -> 52546557 | ... L16: =ROUND(L7*0.4,0) -> 65683196
A17: UK / UKDF (25%) | B17: core-hrs | C17: =ROUND(C7*0.25,0) -> 4105200 | D17: =ROUND(D7*0.25,0) -> 8210400 | E17: =ROUND(E7*0.25,0) -> 12315599 | F17: =ROUND(F7*0.25,0) -> 16420799 | G17: =ROUND(G7*0.25,0) -> 20525999 | H17: =ROUND(H7*0.25,0) -> 24631199 | I17: =ROUND(I7*0.25,0) -> 28736398 | J17: =ROUND(J7*0.25,0) -> 32841598 | ... L17: =ROUND(L7*0.25,0) -> 41051998
A19: FRANCE (CC-IN2P3) DETAIL
A20: DRP cores | B20: cores | C20: =C11 -> 1368 | D20: =D11 -> 2737 | E20: =E11 -> 4105 | F20: =F11 -> 5474 | G20: =G11 -> 6842 | H20: =H11 -> 8210 | I20: =I11 -> 9579 | J20: =J11 -> 10947 | ... L20: =L11 -> 13684
A21: Batch nodes (est.) | B21: nodes | C21: =CEILING(C20/120,1) -> 12 | D21: =CEILING(D20/120,1) -> 23 | E21: =CEILING(E20/120,1) -> 35 | F21: =CEILING(F20/120,1) -> 46 | G21: =CEILING(G20/120,1) -> 58 | H21: =CEILING(H20/120,1) -> 69 | I21: =CEILING(I20/120,1) -> 80 | J21: =CEILING(J20/120,1) -> 92 | ... L21: =CEILING(L20/120,1) -> 115
A22: DRP scratch storage (est.) | B22: TB | C22: =ROUND(('Ops Storage'!C38+'Ops Storage'!C39+'Ops Storage'!C41)*0.4,0) -> 2280 | D22: =ROUND(('Ops Storage'!D38+'Ops Storage'!D39+'Ops Storage'!D41)*0.4,0) -> 2280 | E22: =ROUND(('Ops Storage'!E38+'Ops Storage'!E39+'Ops Storage'!E41)*0.4,0) -> 2280 | F22: =ROUND(('Ops Storage'!F38+'Ops Storage'!F39+'Ops Storage'!F41)*0.4,0) -> 2280 | G22: =ROUND(('Ops Storage'!G38+'Ops Storage'!G39+'Ops Storage'!G41)*0.4,0) -> 2280 | H22: =ROUND(('Ops Storage'!H38+'Ops Storage'!H39+'Ops Storage'!H41)*0.4,0) -> 2280 | I22: =ROUND(('Ops Storage'!I38+'Ops Storage'!I39+'Ops Storage'!I41)*0.4,0) -> 2280 | J22: =ROUND(('Ops Storage'!J38+'Ops Storage'!J39+'Ops Storage'!J41)*0.4,0) -> 2280 | ... L22: =ROUND(('Ops Storage'!L38+'Ops Storage'!L39+'Ops Storage'!L41)*0.4,0) -> 2280
A24: UK (UKDF) DETAIL
A25: DRP cores | B25: cores | C25: =C12 -> 855 | D25: =D12 -> 1710 | E25: =E12 -> 2566 | F25: =F12 -> 3421 | G25: =G12 -> 4276 | H25: =H12 -> 5131 | I25: =I12 -> 5987 | J25: =J12 -> 6842 | ... L25: =L12 -> 8552
A26: Batch nodes (est.) | B26: nodes | C26: =CEILING(C25/120,1) -> 8 | D26: =CEILING(D25/120,1) -> 15 | E26: =CEILING(E25/120,1) -> 22 | F26: =CEILING(F25/120,1) -> 29 | G26: =CEILING(G25/120,1) -> 36 | H26: =CEILING(H25/120,1) -> 43 | I26: =CEILING(I25/120,1) -> 50 | J26: =CEILING(J25/120,1) -> 58 | ... L26: =CEILING(L25/120,1) -> 72
A27: DRP scratch storage (est.) | B27: TB | C27: =ROUND(('Ops Storage'!C38+'Ops Storage'!C39+'Ops Storage'!C41)*0.25,0) -> 1425 | D27: =ROUND(('Ops Storage'!D38+'Ops Storage'!D39+'Ops Storage'!D41)*0.25,0) -> 1425 | E27: =ROUND(('Ops Storage'!E38+'Ops Storage'!E39+'Ops Storage'!E41)*0.25,0) -> 1425 | F27: =ROUND(('Ops Storage'!F38+'Ops Storage'!F39+'Ops Storage'!F41)*0.25,0) -> 1425 | G27: =ROUND(('Ops Storage'!G38+'Ops Storage'!G39+'Ops Storage'!G41)*0.25,0) -> 1425 | H27: =ROUND(('Ops Storage'!H38+'Ops Storage'!H39+'Ops Storage'!H41)*0.25,0) -> 1425 | I27: =ROUND(('Ops Storage'!I38+'Ops Storage'!I39+'Ops Storage'!I41)*0.25,0) -> 1425 | J27: =ROUND(('Ops Storage'!J38+'Ops Storage'!J39+'Ops Storage'!J41)*0.25,0) -> 1425 | ... L27: =ROUND(('Ops Storage'!L38+'Ops Storage'!L39+'Ops Storage'!L41)*0.25,0) -> 1425
A29: Note: France and UK handle DRP compute only. Long-term data products and storage reside at USDF.

Sheet Yearly Readiness
A1: Yearly Readiness — LOY1 to LOY10
A3: LOY | B3: Year | C3: Milestone | D3: Total Cores Needed | E3: Cores Available (before purchase) | F3: Compute Gap | G3: Online Storage Needed (PB) | H3: Storage Available (before purchase, PB) | I3: Storage Gap (PB) | J3: Status
A4: LOY1 | B4: 2026 | C4: DP2 | D4: ='Purchase Plan'!C11 -> 3797.3098 | E4: 17400 | F4: =MAX(0,D4-E4) -> 0 | G4: ='Purchase Plan'!C30/1000 -> 26.765624 | H4: 30 | I4: =MAX(0,G4-H4) -> 0 | J4: =IF(AND(F4<=0,I4<=0),"On Track","Need: "&IF(F4>0,TEXT(F4,"#,##0")&" cores","")&IF(AND(F4>0,I4>0)," + ","")&IF(I4>0,TEXT(I4,"#,##0.0")&" PB","")) -> On Track
A5: LOY2 | B5: 2027 | C5: DR1 | D5: ='Purchase Plan'!D11 -> 7594.6195 | E5: ='Purchase Plan'!C12 -> 21197.31 | F5: =MAX(0,D5-E5) -> 0 | G5: ='Purchase Plan'!D30/1000 -> 45.04428 | H5: ='Purchase Plan'!C31/1000 -> 30 | I5: =MAX(0,G5-H5) -> 15.04428 | J5: =IF(AND(F5<=0,I5<=0),"On Track","Need: "&IF(F5>0,TEXT(F5,"#,##0")&" cores","")&IF(AND(F5>0,I5>0)," + ","")&IF(I5>0,TEXT(I5,"#,##0.0")&" PB","")) -> Need: 15.0 PB
A6: LOY3 | B6: 2028 | C6: DR2 | D6: ='Purchase Plan'!E11 -> 11391.929 | E6: ='Purchase Plan'!D12 -> 24994.62 | F6: =MAX(0,D6-E6) -> 0 | G6: ='Purchase Plan'!E30/1000 -> 62.789169 | H6: ='Purchase Plan'!D31/1000 -> 45.04428 | I6: =MAX(0,G6-H6) -> 17.744889 | J6: =IF(AND(F6<=0,I6<=0),"On Track","Need: "&IF(F6>0,TEXT(F6,"#,##0")&" cores","")&IF(AND(F6>0,I6>0)," + ","")&IF(I6>0,TEXT(I6,"#,##0.0")&" PB","")) -> Need: 17.7 PB
A7: LOY4 | B7: 2029 | C7: DR3 | D7: ='Purchase Plan'!F11 -> 15189.239 | E7: ='Purchase Plan'!E12 -> 28791.929 | F7: =MAX(0,D7-E7) -> 0 | G7: ='Purchase Plan'!F30/1000 -> 75.176982 | H7: ='Purchase Plan'!E31/1000 -> 62.789169 | I7: =MAX(0,G7-H7) -> 12.387812 | J7: =IF(AND(F7<=0,I7<=0),"On Track","Need: "&IF(F7>0,TEXT(F7,"#,##0")&" cores","")&IF(AND(F7>0,I7>0)," + ","")&IF(I7>0,TEXT(I7,"#,##0.0")&" PB","")) -> Need: 12.4 PB
A8: LOY5 | B8: 2030 | C8: DR4 | D8: ='Purchase Plan'!G11 -> 18986.549 | E8: ='Purchase Plan'!F12 -> 36386.549 | F8: =MAX(0,D8-E8) -> 0 | G8: ='Purchase Plan'!G30/1000 -> 87.624736 | H8: ='Purchase Plan'!F31/1000 -> 75.176982 | I8: =MAX(0,G8-H8) -> 12.447754 | J8: =IF(AND(F8<=0,I8<=0),"On Track","Need: "&IF(F8>0,TEXT(F8,"#,##0")&" cores","")&IF(AND(F8>0,I8>0)," + ","")&IF(I8>0,TEXT(I8,"#,##0.0")&" PB","")) -> Need: 12.4 PB
A9: LOY6 | B9: 2031 | C9: DR5 | D9: ='Purchase Plan'!H11 -> 22783.859 | E9: ='Purchase Plan'!G12 -> 43981.168 | F9: =MAX(0,D9-E9) -> 0 | G9: ='Purchase Plan'!H30/1000 -> 100.50239 | H9: ='Purchase Plan'!G31/1000 -> 87.624736 | I9: =MAX(0,G9-H9) -> 12.877656 | J9: =IF(AND(F9<=0,I9<=0),"On Track","Need: "&IF(F9>0,TEXT(F9,"#,##0")&" cores","")&IF(AND(F9>0,I9>0)," + ","")&IF(I9>0,TEXT(I9,"#,##0.0")&" PB","")) -> Need: 12.9 PB
A10: LOY7 | B10: 2032 | C10: DR6 | D10: ='Purchase Plan'!I11 -> 26581.168 | E10: ='Purchase Plan'!H12 -> 51575.788 | F10: =MAX(0,D10-E10) -> 0 | G10: ='Purchase Plan'!I30/1000 -> 113.89532 | H10: ='Purchase Plan'!H31/1000 -> 100.50239 | I10: =MAX(0,G10-H10) -> 13.392928 | J10: =IF(AND(F10<=0,I10<=0),"On Track","Need: "&IF(F10>0,TEXT(F10,"#,##0")&" cores","")&IF(AND(F10>0,I10>0)," + ","")&IF(I10>0,TEXT(I10,"#,##0.0")&" PB","")) -> Need: 13.4 PB
A11: LOY8 | B11: 2033 | C11: DR7 | D11: ='Purchase Plan'!J11 -> 30378.478 | E11: ='Purchase Plan'!I12 -> 59170.407 | F11: =MAX(0,D11-E11) -> 0 | G11: ='Purchase Plan'!J30/1000 -> 127.77054 | H11: ='Purchase Plan'!I31/1000 -> 113.89532 | I11: =MAX(0,G11-H11) -> 13.875219 | J11: =IF(AND(F11<=0,I11<=0),"On Track","Need: "&IF(F11>0,TEXT(F11,"#,##0")&" cores","")&IF(AND(F11>0,I11>0)," + ","")&IF(I11>0,TEXT(I11,"#,##0.0")&" PB","")) -> Need: 13.9 PB
A12: LOY9 | B12: 2034 | C12: DR8 | D12: ='Purchase Plan'!K11 -> 34175.788 | E12: ='Purchase Plan'!J12 -> 66765.027 | F12: =MAX(0,D12-E12) -> 0 | G12: ='Purchase Plan'!K30/1000 -> 142.06474 | H12: ='Purchase Plan'!J31/1000 -> 127.77054 | I12: =MAX(0,G12-H12) -> 14.294198 | J12: =IF(AND(F12<=0,I12<=0),"On Track","Need: "&IF(F12>0,TEXT(F12,"#,##0")&" cores","")&IF(AND(F12>0,I12>0)," + ","")&IF(I12>0,TEXT(I12,"#,##0.0")&" PB","")) -> Need: 14.3 PB
A13: LOY10 | B13: 2035 | C13: DR9 | D13: ='Purchase Plan'!L11 -> 37973.098 | E13: ='Purchase Plan'!K12 -> 74359.647 | F13: =MAX(0,D13-E13) -> 0 | G13: ='Purchase Plan'!L30/1000 -> 156.82434 | H13: ='Purchase Plan'!K31/1000 -> 142.06474 | I13: =MAX(0,G13-H13) -> 14.759599 | J13: =IF(AND(F13<=0,I13<=0),"On Track","Need: "&IF(F13>0,TEXT(F13,"#,##0")&" cores","")&IF(AND(F13>0,I13>0)," + ","")&IF(I13>0,TEXT(I13,"#,##0.0")&" PB","")) -> Need: 14.8 PB
A15: Notes:
A16: 'Available' = what is on hand BEFORE this year's purchase cycle. 'Gap' = additional capacity to procure. 100% USDF compute assumed.
A17: See 'International Compute' tab for France (40%) + UK (25%) DRP offload scenario.

Sheet Hardware Refresh
A1: Hardware Refresh / EOL (annual units to replace)
A2: Each cohort: replace `Qty` in FY when FY > delivery_year and MOD(FY − delivery_year, lifetime_years) = 0. Lifetimes: compute-class 3 yr, JBOD/NVMe 5 yr (from YAML). Source: Rubin Hardware Summary for March 2025 JTM + sizing_params.yaml.
A5: Fiscal Year (FY) | G5: 2026 | H5: 2027 | I5: 2028 | J5: 2029 | K5: 2030 | L5: 2031 | M5: 2032 | N5: 2033 | O5: 2034 | P5: 2035
A6: Label | B6: Category | C6: Qty | D6: Delivery FY | E6: Lifetime (yr) | F6: First EOL FY | G6: LOY1 | H6: LOY2 | I6: LOY3 | J6: LOY4 | K6: LOY5 | L6: LOY6 | M6: LOY7 | N6: LOY8 | O6: LOY9 | P6: LOY10
A7: k8s PO215594 | B7: k8s | C7: 16 | D7: 2022 | E7: 3 | F7: 2025 | G7: 16 | H7: =IF(AND(H$5>$D7,MOD(H$5-$D7,$E7)=0),$C7,0) -> 0 | I7: =IF(AND(I$5>$D7,MOD(I$5-$D7,$E7)=0),$C7,0) -> 16 | J7: =IF(AND(J$5>$D7,MOD(J$5-$D7,$E7)=0),$C7,0) -> 0 | K7: =IF(AND(K$5>$D7,MOD(K$5-$D7,$E7)=0),$C7,0) -> 0 | L7: =IF(AND(L$5>$D7,MOD(L$5-$D7,$E7)=0),$C7,0) -> 16 | M7: =IF(AND(M$5>$D7,MOD(M$5-$D7,$E7)=0),$C7,0) -> 0 | N7: =IF(AND(N$5>$D7,MOD(N$5-$D7,$E7)=0),$C7,0) -> 0 | O7: =IF(AND(O$5>$D7,MOD(O$5-$D7,$E7)=0),$C7,0) -> 16 | P7: =IF(AND(P$5>$D7,MOD(P$5-$D7,$E7)=0),$C7,0) -> 0
A8: JBOD PO216503 del 2022-04-13 | B8: jbod | C8: 4 | D8: 2022 | E8: 5 | F8: 2027 | G8: =IF(AND(G$5>$D8,MOD(G$5-$D8,$E8)=0),$C8,0) -> 0 | H8: =IF(AND(H$5>$D8,MOD(H$5-$D8,$E8)=0),$C8,0) -> 4 | I8: =IF(AND(I$5>$D8,MOD(I$5-$D8,$E8)=0),$C8,0) -> 0 | J8: =IF(AND(J$5>$D8,MOD(J$5-$D8,$E8)=0),$C8,0) -> 0 | K8: =IF(AND(K$5>$D8,MOD(K$5-$D8,$E8)=0),$C8,0) -> 0 | L8: =IF(AND(L$5>$D8,MOD(L$5-$D8,$E8)=0),$C8,0) -> 0 | M8: =IF(AND(M$5>$D8,MOD(M$5-$D8,$E8)=0),$C8,0) -> 4 | N8: =IF(AND(N$5>$D8,MOD(N$5-$D8,$E8)=0),$C8,0) -> 0 | ... P8: =IF(AND(P$5>$D8,MOD(P$5-$D8,$E8)=0),$C8,0) -> 0
A9: JBOD PO220246 | B9: jbod | C9: 11 | D9: 2022 | E9: 5 | F9: 2027 | G9: =IF(AND(G$5>$D9,MOD(G$5-$D9,$E9)=0),$C9,0) -> 0 | H9: =IF(AND(H$5>$D9,MOD(H$5-$D9,$E9)=0),$C9,0) -> 11 | I9: =IF(AND(I$5>$D9,MOD(I$5-$D9,$E9)=0),$C9,0) -> 0 | J9: =IF(AND(J$5>$D9,MOD(J$5-$D9,$E9)=0),$C9,0) -> 0 | K9: =IF(AND(K$5>$D9,MOD(K$5-$D9,$E9)=0),$C9,0) -> 0 | L9: =IF(AND(L$5>$D9,MOD(L$5-$D9,$E9)=0),$C9,0) -> 0 | M9: =IF(AND(M$5>$D9,MOD(M$5-$D9,$E9)=0),$C9,0) -> 11 | N9: =IF(AND(N$5>$D9,MOD(N$5-$D9,$E9)=0),$C9,0) -> 0 | ... P9: =IF(AND(P$5>$D9,MOD(P$5-$D9,$E9)=0),$C9,0) -> 0
A10: JBOD PO222151 / dup PO216503 | B10: jbod | C10: 4 | D10: 2022 | E10: 5 | F10: 2027 | G10: =IF(AND(G$5>$D10,MOD(G$5-$D10,$E10)=0),$C10,0) -> 0 | H10: =IF(AND(H$5>$D10,MOD(H$5-$D10,$E10)=0),$C10,0) -> 4 | I10: =IF(AND(I$5>$D10,MOD(I$5-$D10,$E10)=0),$C10,0) -> 0 | J10: =IF(AND(J$5>$D10,MOD(J$5-$D10,$E10)=0),$C10,0) -> 0 | K10: =IF(AND(K$5>$D10,MOD(K$5-$D10,$E10)=0),$C10,0) -> 0 | L10: =IF(AND(L$5>$D10,MOD(L$5-$D10,$E10)=0),$C10,0) -> 0 | M10: =IF(AND(M$5>$D10,MOD(M$5-$D10,$E10)=0),$C10,0) -> 4 | N10: =IF(AND(N$5>$D10,MOD(N$5-$D10,$E10)=0),$C10,0) -> 0 | ... P10: =IF(AND(P$5>$D10,MOD(P$5-$D10,$E10)=0),$C10,0) -> 0
A11: NVMe PO220192 | B11: nvme_server | C11: 4 | D11: 2022 | E11: 5 | F11: 2027 | G11: =IF(AND(G$5>$D11,MOD(G$5-$D11,$E11)=0),$C11,0) -> 0 | H11: =IF(AND(H$5>$D11,MOD(H$5-$D11,$E11)=0),$C11,0) -> 4 | I11: =IF(AND(I$5>$D11,MOD(I$5-$D11,$E11)=0),$C11,0) -> 0 | J11: =IF(AND(J$5>$D11,MOD(J$5-$D11,$E11)=0),$C11,0) -> 0 | K11: =IF(AND(K$5>$D11,MOD(K$5-$D11,$E11)=0),$C11,0) -> 0 | L11: =IF(AND(L$5>$D11,MOD(L$5-$D11,$E11)=0),$C11,0) -> 0 | M11: =IF(AND(M$5>$D11,MOD(M$5-$D11,$E11)=0),$C11,0) -> 4 | N11: =IF(AND(N$5>$D11,MOD(N$5-$D11,$E11)=0),$C11,0) -> 0 | ... P11: =IF(AND(P$5>$D11,MOD(P$5-$D11,$E11)=0),$C11,0) -> 0
A12: Milan PO222151 | B12: milan_batch | C12: 40 | D12: 2023 | E12: 3 | F12: 2026 | G12: =IF(AND(G$5>$D12,MOD(G$5-$D12,$E12)=0),$C12,0) -> 40 | H12: =IF(AND(H$5>$D12,MOD(H$5-$D12,$E12)=0),$C12,0) -> 0 | I12: =IF(AND(I$5>$D12,MOD(I$5-$D12,$E12)=0),$C12,0) -> 0 | J12: =IF(AND(J$5>$D12,MOD(J$5-$D12,$E12)=0),$C12,0) -> 40 | K12: =IF(AND(K$5>$D12,MOD(K$5-$D12,$E12)=0),$C12,0) -> 0 | L12: =IF(AND(L$5>$D12,MOD(L$5-$D12,$E12)=0),$C12,0) -> 0 | M12: =IF(AND(M$5>$D12,MOD(M$5-$D12,$E12)=0),$C12,0) -> 40 | N12: =IF(AND(N$5>$D12,MOD(N$5-$D12,$E12)=0),$C12,0) -> 0 | ... P12: =IF(AND(P$5>$D12,MOD(P$5-$D12,$E12)=0),$C12,0) -> 40
A13: Qserv PO222151 | B13: qserv | C13: 15 | D13: 2023 | E13: 3 | F13: 2026 | G13: =IF(AND(G$5>$D13,MOD(G$5-$D13,$E13)=0),$C13,0) -> 15 | H13: =IF(AND(H$5>$D13,MOD(H$5-$D13,$E13)=0),$C13,0) -> 0 | I13: =IF(AND(I$5>$D13,MOD(I$5-$D13,$E13)=0),$C13,0) -> 0 | J13: =IF(AND(J$5>$D13,MOD(J$5-$D13,$E13)=0),$C13,0) -> 15 | K13: =IF(AND(K$5>$D13,MOD(K$5-$D13,$E13)=0),$C13,0) -> 0 | L13: =IF(AND(L$5>$D13,MOD(L$5-$D13,$E13)=0),$C13,0) -> 0 | M13: =IF(AND(M$5>$D13,MOD(M$5-$D13,$E13)=0),$C13,0) -> 15 | N13: =IF(AND(N$5>$D13,MOD(N$5-$D13,$E13)=0),$C13,0) -> 0 | ... P13: =IF(AND(P$5>$D13,MOD(P$5-$D13,$E13)=0),$C13,0) -> 15
A14: k8s PO222151 | B14: k8s | C14: 32 | D14: 2023 | E14: 3 | F14: 2026 | G14: =IF(AND(G$5>$D14,MOD(G$5-$D14,$E14)=0),$C14,0) -> 32 | H14: =IF(AND(H$5>$D14,MOD(H$5-$D14,$E14)=0),$C14,0) -> 0 | I14: =IF(AND(I$5>$D14,MOD(I$5-$D14,$E14)=0),$C14,0) -> 0 | J14: =IF(AND(J$5>$D14,MOD(J$5-$D14,$E14)=0),$C14,0) -> 32 | K14: =IF(AND(K$5>$D14,MOD(K$5-$D14,$E14)=0),$C14,0) -> 0 | L14: =IF(AND(L$5>$D14,MOD(L$5-$D14,$E14)=0),$C14,0) -> 0 | M14: =IF(AND(M$5>$D14,MOD(M$5-$D14,$E14)=0),$C14,0) -> 32 | N14: =IF(AND(N$5>$D14,MOD(N$5-$D14,$E14)=0),$C14,0) -> 0 | ... P14: =IF(AND(P$5>$D14,MOD(P$5-$D14,$E14)=0),$C14,0) -> 32
A15: Milan PO227883 | B15: milan_batch | C15: 32 | D15: 2023 | E15: 3 | F15: 2026 | G15: =IF(AND(G$5>$D15,MOD(G$5-$D15,$E15)=0),$C15,0) -> 32 | H15: =IF(AND(H$5>$D15,MOD(H$5-$D15,$E15)=0),$C15,0) -> 0 | I15: =IF(AND(I$5>$D15,MOD(I$5-$D15,$E15)=0),$C15,0) -> 0 | J15: =IF(AND(J$5>$D15,MOD(J$5-$D15,$E15)=0),$C15,0) -> 32 | K15: =IF(AND(K$5>$D15,MOD(K$5-$D15,$E15)=0),$C15,0) -> 0 | L15: =IF(AND(L$5>$D15,MOD(L$5-$D15,$E15)=0),$C15,0) -> 0 | M15: =IF(AND(M$5>$D15,MOD(M$5-$D15,$E15)=0),$C15,0) -> 32 | N15: =IF(AND(N$5>$D15,MOD(N$5-$D15,$E15)=0),$C15,0) -> 0 | ... P15: =IF(AND(P$5>$D15,MOD(P$5-$D15,$E15)=0),$C15,0) -> 32
A16: Qserv PO227883 | B16: qserv | C16: 32 | D16: 2023 | E16: 3 | F16: 2026 | G16: =IF(AND(G$5>$D16,MOD(G$5-$D16,$E16)=0),$C16,0) -> 32 | H16: =IF(AND(H$5>$D16,MOD(H$5-$D16,$E16)=0),$C16,0) -> 0 | I16: =IF(AND(I$5>$D16,MOD(I$5-$D16,$E16)=0),$C16,0) -> 0 | J16: =IF(AND(J$5>$D16,MOD(J$5-$D16,$E16)=0),$C16,0) -> 32 | K16: =IF(AND(K$5>$D16,MOD(K$5-$D16,$E16)=0),$C16,0) -> 0 | L16: =IF(AND(L$5>$D16,MOD(L$5-$D16,$E16)=0),$C16,0) -> 0 | M16: =IF(AND(M$5>$D16,MOD(M$5-$D16,$E16)=0),$C16,0) -> 32 | N16: =IF(AND(N$5>$D16,MOD(N$5-$D16,$E16)=0),$C16,0) -> 0 | ... P16: =IF(AND(P$5>$D16,MOD(P$5-$D16,$E16)=0),$C16,0) -> 32
