Workbook

Sheet Key Numbers
A1: Rubin USDF Model 2026 — Condensed — Key Numbers
A2: Blue = input (edit here) · Black = formula · Yellow = editable assumption · Column D = same quantity in alternate units. Downstream tabs recalculate from column B.
A3: OBSERVING
A4: Observing nights per year | B4: 300 | C4: nights
A5: Visits per night (sim-based) | B5: 700 | C5: visits
A6: Image size (logical) | B6: 0.00819222 | C6: TB
A7: Raw compression ratio | B7: 0.464 | C7: ratio
A8: Input data per survey year | B8: =B4*B5*B6*B7 -> 798.24992 | C8: TB | D8: =B8/1000 -> 0.79824992
A9: DRP COMPUTE
A10: DRP core-hours per input TB | B10: 20571 | C10: ch/TB
A11: DR1 compute (measured basis) | B11: 16416000 | C11: core-hrs | D11: =B11/(24*B13) -> 5700
A12: DP2 compute (actual, on Milano) | B12: 970 | C12: node-days | D12: =B12*B13*24 -> 2793600
A13: Cores per batch node | B13: 120 | C13: cores
A14: DRP processing window | B14: 200 | C14: days
A15: Idle / inter-stage multiplier | B15: 1.35 | C15: ×
A16: USDF RSP extra load fraction | B16: 0.01 | C16: fraction
A17: Developer/pilot batch load | B17: 55 | C17: node-days/yr | D17: =B17*B13*24 -> 158400
A18: Safety margin | B18: 1.5 | C18: ×
A19: DRP STORAGE
A20: DP2 total DRP output (actual) | B20: 7.43 | C20: PB | D20: =B20*1000 -> 7430
A21: DP2 release products (actual) | B21: 0.32 | C21: PB | D21: =B21*1000 -> 320
A22: DR-era total output per survey-year | B22: 47 | C22: PB | D22: =B22*1000 -> 47000
A23: DR-era release products per survey-year | B23: 1.6 | C23: PB | D23: =B23*1000 -> 1600
A24: Scratch / intermediate fraction | B24: 0.35 | C24: fraction
A25: USDF FLEET (2026)
A26: Batch nodes (Milano + Torino) | B26: 145 | C26: nodes
A27: Batch cores (raw) | B27: =B26*B13 -> 17400 | C27: cores | D27: =B27*B14*24 -> 83520000
A28: Installed storage | B28: 30 | C28: PB | D28: =B28*1000 -> 30000
A29: FACILITY SPLIT (DRP COMPUTE) — aggregates; per-year profile on Facility Split tab
A30: France / CC-IN2P3 share | B30: 0.4 | C30: %
A31: UK / UKDF share (10-yr aggregate) | B31: 0.25 | C31: %
A32: USDF share (residual, aggregate) | B32: =1-B30-B31 -> 0.35 | C32: %
A33: UK provisioned capacity | B33: 40000000 | C33: ch/yr | D33: =B33/(24*B13) -> 13888.889
A34: France provisioned capacity | B34: TBD | C34: ch/yr
A35: QSERV (CATALOG DATABASE)
A36: Qserv nodes deployed | B36: 92 | C36: nodes
A37: Cores per Qserv node (AMD EPYC 7543P) | B37: 32 | C37: cores | D37: 64
A38: RAM per Qserv node | B38: 256 | C38: GB
A39: NVMe storage per node (raw, 12/24 slots) | B39: 32 | C39: TB | D39: =B39*2 -> 64
A40: Qserv replication factor | B40: 3 | C40: ×
...

Sheet All at USDF
A1: Scenario A — Everything runs at USDF (100% of DRP)
A2: Metric | B2: Unit | C2: LOY1 | D2: LOY2 | E2: LOY3 | F2: LOY4 | G2: LOY5 | H2: LOY6 | I2: LOY7 | J2: LOY8 | K2: LOY9 | L2: LOY10
A3: Fiscal Year | C3: FY2026 | D3: FY2027 | E3: FY2028 | F3: FY2029 | G3: FY2030 | H3: FY2031 | I3: FY2032 | J3: FY2033 | K3: FY2034 | L3: FY2035
A4: Milestone | C4: DP2 (actual) | D4: DR1 | E4: DR2 | F4: DR3 | G4: DR4 | H4: DR5 | I4: DR6 | J4: DR7 | K4: DR8 | L4: DR9
A6: DRP COMPUTE — core-hours / node-days / peak cores (LOY1 = DP2 actuals)
A7: Survey years of input processed | B7: years | C7: ='Key Numbers'!$B$56/('Key Numbers'!$B$4*'Key Numbers'!$B$5) -> 0.14285714 | D7: 1 | E7: 2 | F7: 3 | G7: 4 | H7: 5 | I7: 6 | J7: 7 | K7: 8 | L7: 9
A8: Cumulative input data | B8: TB | C8: =C7*'Key Numbers'!$B$8 -> 114.0357 | D8: =D7*'Key Numbers'!$B$8 -> 798.24992 | E8: =E7*'Key Numbers'!$B$8 -> 1596.4998 | F8: =F7*'Key Numbers'!$B$8 -> 2394.7498 | G8: =G7*'Key Numbers'!$B$8 -> 3192.9997 | H8: =H7*'Key Numbers'!$B$8 -> 3991.2496 | I8: =I7*'Key Numbers'!$B$8 -> 4789.4995 | J8: =J7*'Key Numbers'!$B$8 -> 5587.7494 | ... L8: =L7*'Key Numbers'!$B$8 -> 7184.2493
A9: DRP work — core-hours | B9: core-hrs | C9: ='Key Numbers'!$B$12*'Key Numbers'!$B$13*24 -> 2793600 | D9: =D8*'Key Numbers'!$B$10+D7*'Key Numbers'!$B$17*'Key Numbers'!$B$13*24 -> 16579199 | E9: =E8*'Key Numbers'!$B$10+E7*'Key Numbers'!$B$17*'Key Numbers'!$B$13*24 -> 33158398 | F9: =F8*'Key Numbers'!$B$10+F7*'Key Numbers'!$B$17*'Key Numbers'!$B$13*24 -> 49737597 | G9: =G8*'Key Numbers'!$B$10+G7*'Key Numbers'!$B$17*'Key Numbers'!$B$13*24 -> 66316796 | H9: =H8*'Key Numbers'!$B$10+H7*'Key Numbers'!$B$17*'Key Numbers'!$B$13*24 -> 82895995 | I9: =I8*'Key Numbers'!$B$10+I7*'Key Numbers'!$B$17*'Key Numbers'!$B$13*24 -> 99475194 | J9: =J8*'Key Numbers'!$B$10+J7*'Key Numbers'!$B$17*'Key Numbers'!$B$13*24 -> 1.1605439e+08 | K9: =K8*'Key Numbers'!$B$10+K7*'Key Numbers'!$B$17*'Key Numbers'!$B$13*24 -> 1.3263359e+08 | L9: =L8*'Key Numbers'!$B$10+L7*'Key Numbers'!$B$17*'Key Numbers'!$B$13*24 -> 1.4921279e+08
A10: DRP work — node-days (@120 cores/node) | B10: node-days | C10: =C9/(24*'Key Numbers'!$B$13) -> 970 | D10: =D9/(24*'Key Numbers'!$B$13) -> 5756.6663 | E10: =E9/(24*'Key Numbers'!$B$13) -> 11513.333 | F10: =F9/(24*'Key Numbers'!$B$13) -> 17269.999 | G10: =G9/(24*'Key Numbers'!$B$13) -> 23026.665 | H10: =H9/(24*'Key Numbers'!$B$13) -> 28783.332 | I10: =I9/(24*'Key Numbers'!$B$13) -> 34539.998 | J10: =J9/(24*'Key Numbers'!$B$13) -> 40296.664 | ... L10: =L9/(24*'Key Numbers'!$B$13) -> 51809.997
A11: DRP work — peak concurrent cores (200-day window) | B11: cores | C11: =ROUND(C9/('Key Numbers'!$B$14*24)*'Key Numbers'!$B$15*(1+'Key Numbers'!$B$16),0) -> 794 | D11: =ROUND(D9/('Key Numbers'!$B$14*24)*'Key Numbers'!$B$15*(1+'Key Numbers'!$B$16),0) -> 4710 | E11: =ROUND(E9/('Key Numbers'!$B$14*24)*'Key Numbers'!$B$15*(1+'Key Numbers'!$B$16),0) -> 9419 | F11: =ROUND(F9/('Key Numbers'!$B$14*24)*'Key Numbers'!$B$15*(1+'Key Numbers'!$B$16),0) -> 14129 | G11: =ROUND(G9/('Key Numbers'!$B$14*24)*'Key Numbers'!$B$15*(1+'Key Numbers'!$B$16),0) -> 18838 | H11: =ROUND(H9/('Key Numbers'!$B$14*24)*'Key Numbers'!$B$15*(1+'Key Numbers'!$B$16),0) -> 23548 | I11: =ROUND(I9/('Key Numbers'!$B$14*24)*'Key Numbers'!$B$15*(1+'Key Numbers'!$B$16),0) -> 28257 | J11: =ROUND(J9/('Key Numbers'!$B$14*24)*'Key Numbers'!$B$15*(1+'Key Numbers'!$B$16),0) -> 32967 | ... L11: =ROUND(L9/('Key Numbers'!$B$14*24)*'Key Numbers'!$B$15*(1+'Key Numbers'!$B$16),0) -> 42386
A12: Core-hours w/ safety margin (1.5×) | B12: core-hrs | C12: =C9*'Key Numbers'!$B$18 -> 4190400 | D12: =D9*'Key Numbers'!$B$18 -> 24868799 | E12: =E9*'Key Numbers'!$B$18 -> 49737597 | F12: =F9*'Key Numbers'!$B$18 -> 74606396 | G12: =G9*'Key Numbers'!$B$18 -> 99475194 | H12: =H9*'Key Numbers'!$B$18 -> 1.2434399e+08 | I12: =I9*'Key Numbers'!$B$18 -> 1.4921279e+08 | J12: =J9*'Key Numbers'!$B$18 -> 1.7408159e+08 | ... L12: =L9*'Key Numbers'!$B$18 -> 2.2381919e+08
A13: Batch nodes needed (peak) | B13: nodes | C13: =ROUNDUP(C11/'Key Numbers'!$B$13,0) -> 7 | D13: =ROUNDUP(D11/'Key Numbers'!$B$13,0) -> 40 | E13: =ROUNDUP(E11/'Key Numbers'!$B$13,0) -> 79 | F13: =ROUNDUP(F11/'Key Numbers'!$B$13,0) -> 118 | G13: =ROUNDUP(G11/'Key Numbers'!$B$13,0) -> 157 | H13: =ROUNDUP(H11/'Key Numbers'!$B$13,0) -> 197 | I13: =ROUNDUP(I11/'Key Numbers'!$B$13,0) -> 236 | J13: =ROUNDUP(J11/'Key Numbers'!$B$13,0) -> 275 | ... L13: =ROUNDUP(L11/'Key Numbers'!$B$13,0) -> 354
A14: USDF fleet cores (raw) | B14: cores | C14: ='Key Numbers'!$B$27 -> 17400 | D14: ='Key Numbers'!$B$27 -> 17400 | E14: ='Key Numbers'!$B$27 -> 17400 | F14: ='Key Numbers'!$B$27 -> 17400 | G14: ='Key Numbers'!$B$27 -> 17400 | H14: ='Key Numbers'!$B$27 -> 17400 | I14: ='Key Numbers'!$B$27 -> 17400 | J14: ='Key Numbers'!$B$27 -> 17400 | ... L14: ='Key Numbers'!$B$27 -> 17400
A15: USDF fleet, Milano-equivalent cores | B15: cores | C15: ='Key Numbers'!$B$55 -> 21600 | D15: ='Key Numbers'!$B$55 -> 21600 | E15: ='Key Numbers'!$B$55 -> 21600 | F15: ='Key Numbers'!$B$55 -> 21600 | G15: ='Key Numbers'!$B$55 -> 21600 | H15: ='Key Numbers'!$B$55 -> 21600 | I15: ='Key Numbers'!$B$55 -> 21600 | J15: ='Key Numbers'!$B$55 -> 21600 | ... L15: ='Key Numbers'!$B$55 -> 21600
A16: Fleet utilization (peak / Milano-eq) | B16: % | C16: =C11/C15 -> 0.036759259 | D16: =D11/D15 -> 0.21805556 | E16: =E11/E15 -> 0.43606481 | F16: =F11/F15 -> 0.65412037 | G16: =G11/G15 -> 0.87212963 | H16: =H11/H15 -> 1.0901852 | I16: =I11/I15 -> 1.3081944 | J16: =J11/J15 -> 1.52625 | ... L16: =L11/L15 -> 1.9623148
A18: DRP STORAGE — campaign output, PB and TB (LOY1 = DP2 actuals)
A19: Raw data cumulative (compressed) | B19: PB | C19: =C8/1000 -> 0.1140357 | D19: =D8/1000 -> 0.79824992 | E19: =E8/1000 -> 1.5964998 | F19: =F8/1000 -> 2.3947498 | G19: =G8/1000 -> 3.1929997 | H19: =H8/1000 -> 3.9912496 | I19: =I8/1000 -> 4.7894995 | J19: =J8/1000 -> 5.5877494 | ... L19: =L8/1000 -> 7.1842493
A20: same in TB | B20: TB | C20: =C19*1000 -> 114.0357 | D20: =D19*1000 -> 798.24992 | E20: =E19*1000 -> 1596.4998 | F20: =F19*1000 -> 2394.7498 | G20: =G19*1000 -> 3192.9997 | H20: =H19*1000 -> 3991.2496 | I20: =I19*1000 -> 4789.4995 | J20: =J19*1000 -> 5587.7494 | ... L20: =L19*1000 -> 7184.2493
A21: DRP total output of this year's campaign | B21: PB | C21: ='Key Numbers'!$B$20 -> 7.43 | D21: ='Key Numbers'!$B$22*D7 -> 47 | E21: ='Key Numbers'!$B$22*E7 -> 94 | F21: ='Key Numbers'!$B$22*F7 -> 141 | G21: ='Key Numbers'!$B$22*G7 -> 188 | H21: ='Key Numbers'!$B$22*H7 -> 235 | I21: ='Key Numbers'!$B$22*I7 -> 282 | J21: ='Key Numbers'!$B$22*J7 -> 329 | K21: ='Key Numbers'!$B$22*K7 -> 376 | L21: ='Key Numbers'!$B$22*L7 -> 423
A22: same in TB | B22: TB | C22: =C21*1000 -> 7430 | D22: =D21*1000 -> 47000 | E22: =E21*1000 -> 94000 | F22: =F21*1000 -> 141000 | G22: =G21*1000 -> 188000 | H22: =H21*1000 -> 235000 | I22: =I21*1000 -> 282000 | J22: =J21*1000 -> 329000 | ... L22: =L21*1000 -> 423000
A23: of which release products | B23: PB | C23: ='Key Numbers'!$B$21 -> 0.32 | D23: ='Key Numbers'!$B$23*D7 -> 1.6 | E23: ='Key Numbers'!$B$23*E7 -> 3.2 | F23: ='Key Numbers'!$B$23*F7 -> 4.8 | G23: ='Key Numbers'!$B$23*G7 -> 6.4 | H23: ='Key Numbers'!$B$23*H7 -> 8 | I23: ='Key Numbers'!$B$23*I7 -> 9.6 | J23: ='Key Numbers'!$B$23*J7 -> 11.2 | K23: ='Key Numbers'!$B$23*K7 -> 12.8 | L23: ='Key Numbers'!$B$23*L7 -> 14.4
A24: same in TB | B24: TB | C24: =C23*1000 -> 320 | D24: =D23*1000 -> 1600 | E24: =E23*1000 -> 3200 | F24: =F23*1000 -> 4800 | G24: =G23*1000 -> 6400 | H24: =H23*1000 -> 8000 | I24: =I23*1000 -> 9600 | J24: =J23*1000 -> 11200 | ... L24: =L23*1000 -> 14400
A25: Scratch / intermediates during campaign | B25: PB | C25: =C21*'Key Numbers'!$B$24 -> 2.6005 | D25: =D21*'Key Numbers'!$B$24 -> 16.45 | E25: =E21*'Key Numbers'!$B$24 -> 32.9 | F25: =F21*'Key Numbers'!$B$24 -> 49.35 | G25: =G21*'Key Numbers'!$B$24 -> 65.8 | H25: =H21*'Key Numbers'!$B$24 -> 82.25 | I25: =I21*'Key Numbers'!$B$24 -> 98.7 | J25: =J21*'Key Numbers'!$B$24 -> 115.15 | ... L25: =L21*'Key Numbers'!$B$24 -> 148.05
A26: same in TB | B26: TB | C26: =C25*1000 -> 2600.5 | D26: =D25*1000 -> 16450 | E26: =E25*1000 -> 32900 | F26: =F25*1000 -> 49350 | G26: =G25*1000 -> 65800 | H26: =H25*1000 -> 82250 | I26: =I25*1000 -> 98700 | J26: =J25*1000 -> 115150 | ... L26: =L25*1000 -> 148050
A27: Installed storage today (2026) | B27: PB | C27: ='Key Numbers'!$B$28 -> 30 | D27: ='Key Numbers'!$B$28 -> 30 | E27: ='Key Numbers'!$B$28 -> 30 | F27: ='Key Numbers'!$B$28 -> 30 | G27: ='Key Numbers'!$B$28 -> 30 | H27: ='Key Numbers'!$B$28 -> 30 | I27: ='Key Numbers'!$B$28 -> 30 | J27: ='Key Numbers'!$B$28 -> 30 | ... L27: ='Key Numbers'!$B$28 -> 30
A28: same in TB | B28: TB | C28: =C27*1000 -> 30000 | D28: =D27*1000 -> 30000 | E28: =E27*1000 -> 30000 | F28: =F27*1000 -> 30000 | G28: =G27*1000 -> 30000 | H28: =H27*1000 -> 30000 | I28: =I27*1000 -> 30000 | J28: =J27*1000 -> 30000 | ... L28: =L27*1000 -> 30000
A30: LOY1/FY2026 shows DP2 as completed: 970 node-days (2.79M core-hours, run on Milano) and 7.43 PB total output — within the 30 PB installed. From LOY2/FY2027 the DR1 campaign processes one survey-year (~16.4M core-hours) and produces ~47 PB of campaign output (release products + intermediates), which exceeds today's installed storage and drives FY2027+ purchases; retention windows in the full model determine how much of each campaign's output remains on disk.

Sheet Facility Split
A1: Scenario B — DRP split across data facilities (storage archived at USDF)
A2: Metric | B2: Unit | C2: LOY1 | D2: LOY2 | E2: LOY3 | F2: LOY4 | G2: LOY5 | H2: LOY6 | I2: LOY7 | J2: LOY8 | K2: LOY9 | L2: LOY10
A3: Fiscal Year | C3: FY2026 | D3: FY2027 | E3: FY2028 | F3: FY2029 | G3: FY2030 | H3: FY2031 | I3: FY2032 | J3: FY2033 | K3: FY2034 | L3: FY2035
A4: Milestone | C4: DP2 (actual) | D4: DR1 | E4: DR2 | F4: DR3 | G4: DR4 | H4: DR5 | I4: DR6 | J4: DR7 | K4: DR8 | L4: DR9
A6: SHARES BY YEAR (blue = edit; UK front-loads ~40%, tapering to ~25% aggregate)
A7: USDF share (residual) | B7: % | C7: =1-C8-C9 -> 1 | D7: =1-D8-D9 -> 0.2 | E7: =1-E8-E9 -> 0.2 | F7: =1-F8-F9 -> 0.36 | G7: =1-G8-G9 -> 0.36 | H7: =1-H8-H9 -> 0.36 | I7: =1-I8-I9 -> 0.36 | J7: =1-J8-J9 -> 0.36 | ... L7: =1-L8-L9 -> 0.36
A8: France / CC-IN2P3 share | B8: % | C8: 0 | D8: 0.4 | E8: 0.4 | F8: 0.4 | G8: 0.4 | H8: 0.4 | I8: 0.4 | J8: 0.4 | K8: 0.4 | L8: 0.4
A9: UK / UKDF share | B9: % | C9: 0 | D9: 0.4 | E9: 0.4 | F9: 0.24 | G9: 0.24 | H9: 0.24 | I9: 0.24 | J9: 0.24 | K9: 0.24 | L9: 0.24
A10: UK work-weighted aggregate (target ≈25%) | B10: =SUMPRODUCT(D9:L9,'All at USDF'!D7:L7)/SUM('All at USDF'!D7:L7) -> 0.25066667 | D10: LOY1 shares are 0/0: DP2 was processed entirely at USDF.
A12: DRP WORK BY FACILITY — CORE-HOURS
A13: Total DRP core-hours | B13: core-hrs | C13: ='All at USDF'!C9 -> 2793600 | D13: ='All at USDF'!D9 -> 16579199 | E13: ='All at USDF'!E9 -> 33158398 | F13: ='All at USDF'!F9 -> 49737597 | G13: ='All at USDF'!G9 -> 66316796 | H13: ='All at USDF'!H9 -> 82895995 | I13: ='All at USDF'!I9 -> 99475194 | J13: ='All at USDF'!J9 -> 1.1605439e+08 | ... L13: ='All at USDF'!L9 -> 1.4921279e+08
A14: USDF | B14: core-hrs | C14: =C13*C7 -> 2793600 | D14: =D13*D7 -> 3315839.8 | E14: =E13*E7 -> 6631679.6 | F14: =F13*F7 -> 17905535 | G14: =G13*G7 -> 23874047 | H14: =H13*H7 -> 29842558 | I14: =I13*I7 -> 35811070 | J14: =J13*J7 -> 41779582 | ... L14: =L13*L7 -> 53716605
A15: France / CC-IN2P3 | B15: core-hrs | C15: =C13*C8 -> 0 | D15: =D13*D8 -> 6631679.6 | E15: =E13*E8 -> 13263359 | F15: =F13*F8 -> 19895039 | G15: =G13*G8 -> 26526718 | H15: =H13*H8 -> 33158398 | I15: =I13*I8 -> 39790078 | J15: =J13*J8 -> 46421757 | ... L15: =L13*L8 -> 59685117
A16: UK / UKDF | B16: core-hrs | C16: =C13*C9 -> 0 | D16: =D13*D9 -> 6631679.6 | E16: =E13*E9 -> 13263359 | F16: =F13*F9 -> 11937023 | G16: =G13*G9 -> 15916031 | H16: =H13*H9 -> 19895039 | I16: =I13*I9 -> 23874047 | J16: =J13*J9 -> 27853054 | ... L16: =L13*L9 -> 35811070
A18: DRP WORK BY FACILITY — NODE-DAYS (@120 cores/node)
A19: USDF | B19: node-days | C19: =C14/(24*'Key Numbers'!$B$13) -> 970 | D19: =D14/(24*'Key Numbers'!$B$13) -> 1151.3333 | E19: =E14/(24*'Key Numbers'!$B$13) -> 2302.6665 | F19: =F14/(24*'Key Numbers'!$B$13) -> 6217.1996 | G19: =G14/(24*'Key Numbers'!$B$13) -> 8289.5995 | H19: =H14/(24*'Key Numbers'!$B$13) -> 10361.999 | I19: =I14/(24*'Key Numbers'!$B$13) -> 12434.399 | J19: =J14/(24*'Key Numbers'!$B$13) -> 14506.799 | ... L19: =L14/(24*'Key Numbers'!$B$13) -> 18651.599
A20: France / CC-IN2P3 | B20: node-days | C20: =C15/(24*'Key Numbers'!$B$13) -> 0 | D20: =D15/(24*'Key Numbers'!$B$13) -> 2302.6665 | E20: =E15/(24*'Key Numbers'!$B$13) -> 4605.3331 | F20: =F15/(24*'Key Numbers'!$B$13) -> 6907.9996 | G20: =G15/(24*'Key Numbers'!$B$13) -> 9210.6661 | H20: =H15/(24*'Key Numbers'!$B$13) -> 11513.333 | I20: =I15/(24*'Key Numbers'!$B$13) -> 13815.999 | J20: =J15/(24*'Key Numbers'!$B$13) -> 16118.666 | ... L20: =L15/(24*'Key Numbers'!$B$13) -> 20723.999
A21: UK / UKDF | B21: node-days | C21: =C16/(24*'Key Numbers'!$B$13) -> 0 | D21: =D16/(24*'Key Numbers'!$B$13) -> 2302.6665 | E21: =E16/(24*'Key Numbers'!$B$13) -> 4605.3331 | F21: =F16/(24*'Key Numbers'!$B$13) -> 4144.7998 | G21: =G16/(24*'Key Numbers'!$B$13) -> 5526.3997 | H21: =H16/(24*'Key Numbers'!$B$13) -> 6907.9996 | I21: =I16/(24*'Key Numbers'!$B$13) -> 8289.5995 | J21: =J16/(24*'Key Numbers'!$B$13) -> 9671.1994 | ... L21: =L16/(24*'Key Numbers'!$B$13) -> 12434.399
A23: DRP WORK BY FACILITY — PEAK CONCURRENT CORES (200-day window)
A24: USDF | B24: cores | C24: =ROUND('All at USDF'!C11*C7,0) -> 794 | D24: =ROUND('All at USDF'!D11*D7,0) -> 942 | E24: =ROUND('All at USDF'!E11*E7,0) -> 1884 | F24: =ROUND('All at USDF'!F11*F7,0) -> 5086 | G24: =ROUND('All at USDF'!G11*G7,0) -> 6782 | H24: =ROUND('All at USDF'!H11*H7,0) -> 8477 | I24: =ROUND('All at USDF'!I11*I7,0) -> 10173 | J24: =ROUND('All at USDF'!J11*J7,0) -> 11868 | ... L24: =ROUND('All at USDF'!L11*L7,0) -> 15259
A25: France / CC-IN2P3 | B25: cores | C25: =ROUND('All at USDF'!C11*C8,0) -> 0 | D25: =ROUND('All at USDF'!D11*D8,0) -> 1884 | E25: =ROUND('All at USDF'!E11*E8,0) -> 3768 | F25: =ROUND('All at USDF'!F11*F8,0) -> 5652 | G25: =ROUND('All at USDF'!G11*G8,0) -> 7535 | H25: =ROUND('All at USDF'!H11*H8,0) -> 9419 | I25: =ROUND('All at USDF'!I11*I8,0) -> 11303 | J25: =ROUND('All at USDF'!J11*J8,0) -> 13187 | ... L25: =ROUND('All at USDF'!L11*L8,0) -> 16954
A26: UK / UKDF | B26: cores | C26: =ROUND('All at USDF'!C11*C9,0) -> 0 | D26: =ROUND('All at USDF'!D11*D9,0) -> 1884 | E26: =ROUND('All at USDF'!E11*E9,0) -> 3768 | F26: =ROUND('All at USDF'!F11*F9,0) -> 3391 | G26: =ROUND('All at USDF'!G11*G9,0) -> 4521 | H26: =ROUND('All at USDF'!H11*H9,0) -> 5652 | I26: =ROUND('All at USDF'!I11*I9,0) -> 6782 | J26: =ROUND('All at USDF'!J11*J9,0) -> 7912 | ... L26: =ROUND('All at USDF'!L11*L9,0) -> 10173
A28: CAPACITY CHECKS
A29: USDF peak cores vs fleet (Milano-equivalent) | B29: % | C29: =C24/'Key Numbers'!$B$55 -> 0.036759259 | D29: =D24/'Key Numbers'!$B$55 -> 0.043611111 | E29: =E24/'Key Numbers'!$B$55 -> 0.087222222 | F29: =F24/'Key Numbers'!$B$55 -> 0.23546296 | G29: =G24/'Key Numbers'!$B$55 -> 0.31398148 | H29: =H24/'Key Numbers'!$B$55 -> 0.3924537 | I29: =I24/'Key Numbers'!$B$55 -> 0.47097222 | J29: =J24/'Key Numbers'!$B$55 -> 0.54944444 | ... L29: =L24/'Key Numbers'!$B$55 -> 0.70643519
A30: UK required vs provisioned 40M ch/yr | B30: % | C30: =C16/'Key Numbers'!$B$33 -> 0 | D30: =D16/'Key Numbers'!$B$33 -> 0.16579199 | E30: =E16/'Key Numbers'!$B$33 -> 0.33158398 | F30: =F16/'Key Numbers'!$B$33 -> 0.29842558 | G30: =G16/'Key Numbers'!$B$33 -> 0.39790078 | H30: =H16/'Key Numbers'!$B$33 -> 0.49737597 | I30: =I16/'Key Numbers'!$B$33 -> 0.59685117 | J30: =J16/'Key Numbers'!$B$33 -> 0.69632636 | ... L30: =L16/'Key Numbers'!$B$33 -> 0.89527675
A31: France required core-hours | B31: core-hrs | C31: =C15 -> 0 | D31: =D15 -> 6631679.6 | E31: =E15 -> 13263359 | F31: =F15 -> 19895039 | G31: =G15 -> 26526718 | H31: =H15 -> 33158398 | I31: =I15 -> 39790078 | J31: =J15 -> 46421757 | ... L31: =L15 -> 59685117
A32: France capacity TBD.
A34: STORAGE IMPLICATIONS OF SPLIT — PB and TB
A35: Scratch at France (share × scratch) | B35: PB | C35: ='All at USDF'!C25*C8 -> 0 | D35: ='All at USDF'!D25*D8 -> 6.58 | E35: ='All at USDF'!E25*E8 -> 13.16 | F35: ='All at USDF'!F25*F8 -> 19.74 | G35: ='All at USDF'!G25*G8 -> 26.32 | H35: ='All at USDF'!H25*H8 -> 32.9 | I35: ='All at USDF'!I25*I8 -> 39.48 | J35: ='All at USDF'!J25*J8 -> 46.06 | ... L35: ='All at USDF'!L25*L8 -> 59.22
A36: same in TB | B36: TB | C36: =C35*1000 -> 0 | D36: =D35*1000 -> 6580 | E36: =E35*1000 -> 13160 | F36: =F35*1000 -> 19740 | G36: =G35*1000 -> 26320 | H36: =H35*1000 -> 32900 | I36: =I35*1000 -> 39480 | J36: =J35*1000 -> 46060 | ... L36: =L35*1000 -> 59220
A37: Scratch at UK (share × scratch) | B37: PB | C37: ='All at USDF'!C25*C9 -> 0 | D37: ='All at USDF'!D25*D9 -> 6.58 | E37: ='All at USDF'!E25*E9 -> 13.16 | F37: ='All at USDF'!F25*F9 -> 11.844 | G37: ='All at USDF'!G25*G9 -> 15.792 | H37: ='All at USDF'!H25*H9 -> 19.74 | I37: ='All at USDF'!I25*I9 -> 23.688 | J37: ='All at USDF'!J25*J9 -> 27.636 | ... L37: ='All at USDF'!L25*L9 -> 35.532
A38: same in TB | B38: TB | C38: =C37*1000 -> 0 | D38: =D37*1000 -> 6580 | E38: =E37*1000 -> 13160 | F38: =F37*1000 -> 11844 | G38: =G37*1000 -> 15792 | H38: =H37*1000 -> 19740 | I38: =I37*1000 -> 23688 | J38: =J37*1000 -> 27636 | ... L38: =L37*1000 -> 35532
A39: Release archive at USDF (unchanged) | B39: PB | C39: ='All at USDF'!C21 -> 7.43 | D39: ='All at USDF'!D21 -> 47 | E39: ='All at USDF'!E21 -> 94 | F39: ='All at USDF'!F21 -> 141 | G39: ='All at USDF'!G21 -> 188 | H39: ='All at USDF'!H21 -> 235 | I39: ='All at USDF'!I21 -> 282 | J39: ='All at USDF'!J21 -> 329 | ... L39: ='All at USDF'!L21 -> 423
A40: same in TB | B40: TB | C40: =C39*1000 -> 7430 | D40: =D39*1000 -> 47000 | E40: =E39*1000 -> 94000 | F40: =F39*1000 -> 141000 | G40: =G39*1000 -> 188000 | H40: =H39*1000 -> 235000 | I40: =I39*1000 -> 282000 | J40: =J39*1000 -> 329000 | ... L40: =L39*1000 -> 423000
A42: Assumptions: partner DFs hold scratch/intermediates for their share only; all release products transfer back to USDF for the archive. The UK per-year profile is provisional (front-load 40% in the first two DR years, 24% thereafter ≈ 25% work-weighted aggregate); replace with UKDF's computed plan when available.

Sheet Qserv
A1: Qserv — Catalog Database Cluster (current) and LOY1-10 Projections
A3: CURRENT CLUSTER — TECHNICAL DESCRIPTION (as of July 2026)
A4: Deployments | C4: 35-node K8s prod (serves DP2) + 35-node K8s int + 6-node Docker int
A5: CPU per node | C5: 1 × AMD EPYC 7543P, 32 cores / 64 hardware threads (SMT enabled)
A6: RAM per node | C6: 256 GB
A7: Storage per node | C7: Local NVMe (shared-nothing), no network storage in query path: 12 of 24 slots populated = 32 TB raw; ZFS automatic compression ~2x -> ~64 TB effective; populating remaining slots would double raw capacity
A8: Internal network | C8: 100 GbE
A9: Data replication | C9: 3× across workers
A10: Procurement history | C10: 102 nodes purchased: 15 (del. 2023-01), 32 (del. 2023-07), 55 (del. 2024-10)
A11: Same class as K8s fleet | C11: Most USDF K8s nodes share this hardware configuration (EPYC 7543P / 256 GB)
A12: Metric | B12: Unit | C12: LOY1 | D12: LOY2 | E12: LOY3 | F12: LOY4 | G12: LOY5 | H12: LOY6 | I12: LOY7 | J12: LOY8 | K12: LOY9 | L12: LOY10
A13: Fiscal Year | C13: FY2026 | D13: FY2027 | E13: FY2028 | F13: FY2029 | G13: FY2030 | H13: FY2031 | I13: FY2032 | J13: FY2033 | K13: FY2034 | L13: FY2035
A14: Milestone | C14: DP2 | D14: DR1 | E14: DR2 | F14: DR3 | G14: DR4 | H14: DR5 | I14: DR6 | J14: DR7 | K14: DR8 | L14: DR9
A16: CATALOG SIZES BY RELEASE
A17: Objects | B17: billions | C17: 27.5 | D17: 32.5 | E17: 35.7 | F17: 38.2 | G17: 40.3 | H17: 42.2 | I17: 43.8 | J17: 45.3 | K17: 46.4 | L17: 47.4
A18: Sources | B18: billions | C18: 901 | D18: 1800 | E18: 2700 | F18: 3600 | G18: 4510 | H18: 5410 | I18: 6310 | J18: 7210 | K18: 8110 | L18: 9010
A19: Forced sources | B19: billions | C19: 2910 | D19: 6870 | E19: 11300 | F19: 16100 | G19: 21300 | H19: 26700 | I19: 32400 | J19: 38300 | K19: 44100 | L19: 50100
A21: QSERV DATABASE SIZE (replicated 3×) — TB and PB
A22: Czar / Object index | B22: TB | C22: =C17*1000000000*'Key Numbers'!$B$42*'Key Numbers'!$B$40/1000000000000 -> 156.42 | D22: =D17*1000000000*'Key Numbers'!$B$42*'Key Numbers'!$B$40/1000000000000 -> 184.86 | E22: =E17*1000000000*'Key Numbers'!$B$42*'Key Numbers'!$B$40/1000000000000 -> 203.0616 | F22: =F17*1000000000*'Key Numbers'!$B$42*'Key Numbers'!$B$40/1000000000000 -> 217.2816 | G22: =G17*1000000000*'Key Numbers'!$B$42*'Key Numbers'!$B$40/1000000000000 -> 229.2264 | H22: =H17*1000000000*'Key Numbers'!$B$42*'Key Numbers'!$B$40/1000000000000 -> 240.0336 | I22: =I17*1000000000*'Key Numbers'!$B$42*'Key Numbers'!$B$40/1000000000000 -> 249.1344 | J22: =J17*1000000000*'Key Numbers'!$B$42*'Key Numbers'!$B$40/1000000000000 -> 257.6664 | ... L22: =L17*1000000000*'Key Numbers'!$B$42*'Key Numbers'!$B$40/1000000000000 -> 269.6112
A23: Worker DB per release | B23: TB | C23: =(C17*('Key Numbers'!$B$42+'Key Numbers'!$B$43)+C18*'Key Numbers'!$B$44+C19*'Key Numbers'!$B$45)*1000000000*'Key Numbers'!$B$40/1000000000000 -> 3509.5635 | D23: =(D17*('Key Numbers'!$B$42+'Key Numbers'!$B$43)+D18*'Key Numbers'!$B$44+D19*'Key Numbers'!$B$45)*1000000000*'Key Numbers'!$B$40/1000000000000 -> 5599.6575 | E23: =(E17*('Key Numbers'!$B$42+'Key Numbers'!$B$43)+E18*'Key Numbers'!$B$44+E19*'Key Numbers'!$B$45)*1000000000*'Key Numbers'!$B$40/1000000000000 -> 7625.2971 | F23: =(F17*('Key Numbers'!$B$42+'Key Numbers'!$B$43)+F18*'Key Numbers'!$B$44+F19*'Key Numbers'!$B$45)*1000000000*'Key Numbers'!$B$40/1000000000000 -> 9648.3546 | G23: =(G17*('Key Numbers'!$B$42+'Key Numbers'!$B$43)+G18*'Key Numbers'!$B$44+G19*'Key Numbers'!$B$45)*1000000000*'Key Numbers'!$B$40/1000000000000 -> 11707.141 | H23: =(H17*('Key Numbers'!$B$42+'Key Numbers'!$B$43)+H18*'Key Numbers'!$B$44+H19*'Key Numbers'!$B$45)*1000000000*'Key Numbers'!$B$40/1000000000000 -> 13762.777 | I23: =(I17*('Key Numbers'!$B$42+'Key Numbers'!$B$43)+I18*'Key Numbers'!$B$44+I19*'Key Numbers'!$B$45)*1000000000*'Key Numbers'!$B$40/1000000000000 -> 15834.701 | J23: =(J17*('Key Numbers'!$B$42+'Key Numbers'!$B$43)+J18*'Key Numbers'!$B$44+J19*'Key Numbers'!$B$45)*1000000000*'Key Numbers'!$B$40/1000000000000 -> 17924.356 | ... L23: =(L17*('Key Numbers'!$B$42+'Key Numbers'!$B$43)+L18*'Key Numbers'!$B$44+L19*'Key Numbers'!$B$45)*1000000000*'Key Numbers'!$B$40/1000000000000 -> 22041.832
A24: Worker DB windowed (3-release sliding) | B24: TB | C24: =C23 -> 3509.5635 | D24: =C23+D23 -> 9109.221 | E24: =C23+D23+E23 -> 16734.518 | F24: =D23+E23+F23 -> 22873.309 | G24: =E23+F23+G23 -> 28980.793 | H24: =F23+G23+H23 -> 35118.272 | I24: =G23+H23+I23 -> 41304.619 | J24: =H23+I23+J23 -> 47521.834 | K24: =I23+J23+K23 -> 53733.287 | L24: =J23+K23+L23 -> 59940.417
A25: same in PB | B25: PB | C25: =C24/1000 -> 3.5095635 | D25: =D24/1000 -> 9.109221 | E25: =E24/1000 -> 16.734518 | F25: =F24/1000 -> 22.873309 | G25: =G24/1000 -> 28.980793 | H25: =H24/1000 -> 35.118272 | I25: =I24/1000 -> 41.304619 | J25: =J24/1000 -> 47.521834 | ... L25: =L24/1000 -> 59.940417
A27: NODE PROJECTION
A28: Data per node (drive-density ramp) | B28: TB/node | C28: 43.2 | D28: 43.2 | E28: 86.4 | F28: 86.4 | G28: 86.4 | H28: 86.4 | I28: 172.8 | J28: 172.8 | K28: 172.8 | L28: 172.8
A29: Qserv nodes needed | B29: nodes | C29: =ROUNDUP(C24/C28,0) -> 82 | D29: =ROUNDUP(D24/D28,0) -> 211 | E29: =ROUNDUP(E24/E28,0) -> 194 | F29: =ROUNDUP(F24/F28,0) -> 265 | G29: =ROUNDUP(G24/G28,0) -> 336 | H29: =ROUNDUP(H24/H28,0) -> 407 | I29: =ROUNDUP(I24/I28,0) -> 240 | J29: =ROUNDUP(J24/J28,0) -> 276 | ... L29: =ROUNDUP(L24/L28,0) -> 347
A30: Qserv nodes deployed today | B30: nodes | C30: ='Key Numbers'!$B$36 -> 92 | D30: ='Key Numbers'!$B$36 -> 92 | E30: ='Key Numbers'!$B$36 -> 92 | F30: ='Key Numbers'!$B$36 -> 92 | G30: ='Key Numbers'!$B$36 -> 92 | H30: ='Key Numbers'!$B$36 -> 92 | I30: ='Key Numbers'!$B$36 -> 92 | J30: ='Key Numbers'!$B$36 -> 92 | ... L30: ='Key Numbers'!$B$36 -> 92
A31: Surplus / (gap) | B31: nodes | C31: =C30-C29 -> 10 | D31: =D30-D29 -> -119 | E31: =E30-E29 -> -102 | F31: =F30-F29 -> -173 | G31: =G30-G29 -> -244 | H31: =H30-H29 -> -315 | I31: =I30-I29 -> -148 | J31: =J30-J29 -> -184 | ... L31: =L30-L29 -> -255
A33: Node count uses the usable TB/node ramp (43.2 → 86.4 → 172.8) as drives densify; replication already included.

Sheet DF Template
A1: Per-Facility Calculator — fill in the yellow cells for your facility
A3: Data release year to evaluate (LOY 1-10) | B3: 2 | C3: LOY2 = FY2027 = DR1
B5: USDF | C5: France (CC-IN2P3) | D5: UK (UKDF) | E5: Your DF
A6: DRP share (aggregate; per-year on Facility Split) | B6: ='Key Numbers'!$B$32 -> 0.35 | C6: ='Key Numbers'!$B$30 -> 0.4 | D6: ='Key Numbers'!$B$31 -> 0.25 | E6: 0.1
A7: Cores per node | B7: ='Key Numbers'!$B$13 -> 120 | C7: 120 | D7: 120 | E7: 128
A8: Processing window (days) | B8: ='Key Numbers'!$B$14 -> 200 | C8: ='Key Numbers'!$B$14 -> 200 | D8: ='Key Numbers'!$B$14 -> 200 | E8: 200
A9: Provisioned capacity (core-hrs/yr) | B9: ='Key Numbers'!$B$55*'Key Numbers'!$B$14*24 -> 103680000 | D9: ='Key Numbers'!$B$33 -> 40000000 | E9: 10000000
A10: COMPUTED
A11: Total DRP work (selected LOY) — core-hours | B11: =INDEX('All at USDF'!$C$9:$L$9,1,$B$3) -> 16579199 | C11: =INDEX('All at USDF'!$C$9:$L$9,1,$B$3) -> 16579199 | D11: =INDEX('All at USDF'!$C$9:$L$9,1,$B$3) -> 16579199 | E11: =INDEX('All at USDF'!$C$9:$L$9,1,$B$3) -> 16579199
A12: Your facility — core-hours | B12: =B11*B6 -> 5802719.7 | C12: =C11*C6 -> 6631679.6 | D12: =D11*D6 -> 4144799.8 | E12: =E11*E6 -> 1657919.9
A13: Your facility — node-days | B13: =B12/(24*B7) -> 2014.8332 | C13: =C12/(24*C7) -> 2302.6665 | D13: =D12/(24*D7) -> 1439.1666 | E13: =E12/(24*E7) -> 539.68747
A14: Your facility — peak concurrent cores | B14: =ROUND(B12/(B8*24)*'Key Numbers'!$B$15*(1+'Key Numbers'!$B$16),0) -> 1648 | C14: =ROUND(C12/(C8*24)*'Key Numbers'!$B$15*(1+'Key Numbers'!$B$16),0) -> 1884 | D14: =ROUND(D12/(D8*24)*'Key Numbers'!$B$15*(1+'Key Numbers'!$B$16),0) -> 1177 | E14: =ROUND(E12/(E8*24)*'Key Numbers'!$B$15*(1+'Key Numbers'!$B$16),0) -> 471
A15: Nodes needed | B15: =ROUNDUP(B14/B7,0) -> 14 | C15: =ROUNDUP(C14/C7,0) -> 16 | D15: =ROUNDUP(D14/D7,0) -> 10 | E15: =ROUNDUP(E14/E7,0) -> 4
A16: Utilization vs provisioned | B16: =IF(B9="","",B12/B9) -> 0.055967589 | C16: =IF(C9="","",C12/C9) | D16: =IF(D9="","",D12/D9) -> 0.10361999 | E16: =IF(E9="","",E12/E9) -> 0.16579199
A18: 'Your DF' column contains example values (10% share, 128-core nodes, 10M ch/yr) — replace with your facility's numbers. Yellow = edit; green = linked to Key Numbers tab. USDF provisioned capacity uses Milano-equivalent cores.
