Workbook
Name opsObjectCount: 'Ops Storage'!$4:$4
Name lossyCompression: Storage!$C$13
Name computeLifetime: Model!$B$127
Name rawCompression: Storage!$C$12
Name qservFac: Model!$H$77
Name opsCalsPerDay: 'Ops Storage'!$C$18
Name coreHoursPerTB: Compute!$C$8
Name sourceCount: Storage!$5:$5
Name visitsPerNight: Storage!$C$17
Name visitsPerNight: 'Ops Storage'!$C$16
Name opsObjectExtraRowSize: 'Ops Storage'!$24:$24
Name opsObjectRowSize: 'Ops Storage'!$23:$23
Name nightsPerYear: 'Ops Storage'!$C$15
Name nightsPerYear: Storage!$C$16
Name qservReplication: 'Ops Storage'!$C$27
Name reduceCPU: Model!$G$3
Name lsstCamImageToHscRatio: Storage!$C$14
Name imagesPerVisit: Storage!$C$18
Name sourceRowSize: Storage!$27:$27
Name cpuFac: Model!$H$75
Name objectCount: Storage!$4:$4
Name opsSourceCount: 'Ops Storage'!$5:$5
Name storageLifetime: Model!$B$128
Name opsImagesPerVisit: 'Ops Storage'!$C$17
Name opsSourceRowSize: 'Ops Storage'!$25:$25
Name diskFac: Model!$H$76
Name opsForcedSourceRowSize: 'Ops Storage'!$C$26:$L$26
Name objectRowSize: Storage!$25:$25
Name qservReplication: Storage!$29:$29
Name forcedSourceRowSize: Storage!$28:$28
Name lsstCamImageSize: Storage!$C$11
Name forcedSourceCount: Storage!$6:$6
Name lsstCamScienceImages: Storage!$20:$20
Name calsPerDay: Storage!$C$19
Name lsstCamScienceImages: 'Ops Storage'!$19:$19
Name opsForcedSourceCount: 'Ops Storage'!$6:$6
Name objectExtraRowSize: Storage!$26:$26
Name lossyCompression: 'Ops Storage'!$C$13
Name tbPerScienceUser: Storage!$9:$9
Name scaleYear: Model!$G$11
Name opsScienceUsers: 'Ops Storage'!$C$8:$L$8
Name opsTBPerScienceUser: 'Ops Storage'!$9:$9
Name scienceUsers: Storage!$8:$8
Name opsRawCompression: 'Ops Storage'!$C$12
Name lsstCamImageSize: 'Ops Storage'!$C$11
Name reduceDisk: Model!$G$4

Sheet Model
A1: Table Summary | B1: This table pulls together all the information in a high level summary - in this table Xeon pricing is used since that is the more expensive but better known option. Price factors, defined in \tabref{tab:Inputs} are applied post 2020. | C1: 4 | D1: 0 | G1: Factors
A2: Year | B2: 2021 | C2: =B2+1 -> 2022 | D2: =C2+1 -> 2023 | E2: =D2+1 -> 2024 | G2: Experimental | H2: should be or was
A3: Compute (2019 pricing) | B3: =B83 -> 690000 | C3: =C83 -> 0 | D3: =D83 -> 1500000 | E3: =E83 -> 5460000 | G3: 1 | H3: 1 | I3: Reduce DRP ONLY CPU by this factor
A4: Storage (2019 pricing) | B4: =B102 -> 101927.44 | C4: =C102 -> 95547.907 | D4: =D102 -> 523354.22 | E4: =E102 -> 3859657.6 | G4: 1 | H4: 1 | I4: Reduce Disk by this factor
A5: Qserv (2019 pricing) | D5: =(E59+E61)*$E$27 -> 280000 | E5: =(F59+F61)*$E$27 -> 3520000 | G5: 133 | H5: 45 | I5: Price of slow (latent) disk
A6: Total (2019 pricing) | B6: =sum(B3:B5) -> 791927.44 | C6: =sum(C3:C5) -> 95547.907 | D6: =sum(D3:D5) -> 2303354.2 | E6: =sum(E3:E5) -> 12839658 | G6: 0.05 | H6: 0.05 | I6: Price factor for disk
A7: Compute (applying price factor) | B7: =B$3*(1-( (B$2-2019)*$C$75)) -> 552000 | C7: =C$3*(1-( (C$2-2019)*$C$75)) -> 0 | D7: =D$3*(1-( (D$2-2019)*$C$75)) -> 900000 | E7: =E$3*(1-( (E$2-2019)*$C$75)) -> 2730000 | G7: 0.1 | H7: 0.1 | I7: Price factor for cpu
A8: IN2P3 (50% of compute in ops) | E8: =-(E7/2) -> -1365000 | G8: 1 | H8: 1 | I8: Forced Source Multiplier (ops)
A9: UKDF (25% of compute in ops) | E9: =-(E7/4) -> -682500 | G9: 0 | H9: 14 | I9: Qserv nodes in Chile 2022
A10: Storage (applying price factor) | B10: =B4*(1-( (B2-2019)*$C$76)) -> 91734.697 | C10: =C4*(1-( (C2-2019)*$C$76)) -> 81215.721 | D10: =D4*(1-( (D2-2019)*$C$76)) -> 418683.37 | E10: =E4*(1-( (E2-2019)*$C$76)) -> 2894743.2 | G10: 0 | H10: 26 | I10: DAC nodes Chile 2022
A11: Qserv (applying price factor) | D11: =D$5*(1-( (D$2-2019)*$C$77)) -> 196000 | E11: =E$5*(1-( (E$2-2019)*$C$77)) -> 2200000 | G11: 2020 | H11: 2019 | I11: Year for price estimates used in scaling
A12: Hosting cost NCSA | B12: =B113 -> 110802.27 | C12: =C113 -> 62802.272 | D12: =D113 -> 238012.35 | E12: =E113 -> 805839.55 | G12: 0.3 | H12: 0.2 | I12: Latent storage factor chile
A13: Total budget (using price factors) | B13: =sum(B7:B12) -> 754536.97 | C13: =sum(C7:C12) -> 144017.99 | D13: =sum(D7:D12) -> 1752695.7 | E13: =sum(E7:E12) -> 6583082.7 | F13: =sum(F7:F12) -> 0 | G13: 720 | H13: 720 | I13: Peso Rate
G14: 1.05 | H14: 1.05 | I14: Latent storage factor chile using RAW+Coadd
A17: Table Scope | B17: NOW OBSOLETE Scope option of delaying the purchase of LOY1 processing hardware and only purchasing what is needed for commissioning was enacted. We only purchase up to and including 2022 hardware of \tabref{tab:Summary}. If we consider that amount and the current remaining construction budget for hardware the potential worth of such a scope option is given in this table. | C17: 4 | D17: 2 | F17: This is now obsolete since the LCR already returnd 10M to ops
A18: Commissioning Budget (to 2022) | D18: =sum(B13:D13) -> 2651250.7
A19: DM construciton budet remaining | D19: 13892220 | E19: (from p6 - Klong email 17 dec 2019 12:52)
A20: Total potential to delay to ops | D20: =D19-D18 -> 11240969
A21: Includes Chilean Storage (2023) | D21: =($E$97+$E$100)*(1-( (E2-2020)*$C$76)) -> 980617.71
A22: Include Chilean Compute (2023) | D22: =0.1*E7 -> 273000
A24: Table Machines | B24: Machine types and costs used as inputs used for calculations | C24: 6 | D24: 0
A25: Type of machine | B25: Cores | C25: Memory(GB) | D25: Eff cores/node | E25: Cost | F25: purpose/use | G25: notes
A26: Xeon | B26: 32 | C26: 192 | D26: =CEILING(2*16*2.1*13.6/816*24,1) -> 27 | E26: 10000 | F26: current K8 node
A27: Qserv | B27: 12 | C27: 128 | D27: =ceiling(2*6*2.5*13.6/816*24,1) -> 12 | E27: 20000 | F27: current qserv node | G27: has 11 internal drives too
A28: small rome | B28: 64 | C28: =4*B28 -> 256 | D28: =CEILING(1484*0.85/816*24,1) -> 38 | E28: 13000 | F28: https://www.microway.com/product/navion-1u-amd-epyc-gpu-server/
A29: large rome | B29: 128 | C29: =4*B29 -> 512 | D29: =ceiling(4608*0.85/816*24,1) -> 116 | E29: 13000 | F29: from Richard
A30: current compute node | B30: 24 | C30: 128 | D30: =2*12*2.5*13.6/816*24 -> 24 | E30: 9000 | F30: current compute node | G30: FLOPS = sockets * (cores per socket) * (number of clock cycles per second) * (number of floating point operations per cycle).
G31: xeon flops real = 16*.85 = 13.6
A33: Table Storage | B33: Storage types and costs used as inputs used for calculations | C33: 3 | D33: 0
A34: Storage type | B34: Estimate(SLAC) | C34: Estimate(NCSA) | D34: note
A35: fast -- NVMe (50GB/s each) /TB | B35: 400 | C35: 1000 | D35: for each TB with file system servers to DDN NVME box with GPFS servers. TOP performer with best price also.
A36: normal - SATA GPFS file systems/TB | B36: 70 | C36: 135 | D36: for each TB with file system disks and servers locally attached to production resources.
A37: latency -- slower but on disk | B37: 70 | C37: =H5 -> 45 | D37: for each TB with file systems or potentially S3 bucket type. Can be mounted if needed but not for production worthy speeds. Based on recent LDF purchases. This is a capacity buy, doubling the storage behind a controller.
A38: high latency -- very slow -- on tape | B38: 15.65 | C38: 25 | D38: for each TB based on LT08 at $10 a cartridge plus cost of robot/cabinets .. i.e. assumes large storage of PB or more
G42: what is the process needed to do: | H42: Qserv, Consolided DB, LSP, DBB (Chile, LDF) | I42: DP0,DP1
A44: Table Inputs | B44: Various inputs for deriving costs - 2019 represents current holdings. | C44: 6 | D44: 0 | F44: DR1, Early alerts
A45: Year | B45: 2019 | C45: =B2 -> 2021 | D45: =C45+1 -> 2022 | E45: =D45+1 -> 2023 | F45: =E45+1 -> 2024
A46: Core-hours Needed Total (DRP) | C46: =Compute!C24 -> 4406677.7 | D46: =Compute!D24 -> 4406677.7 | E46: =Compute!E24 -> 11216345 | F46: =Compute!F24 -> 45264684
A47: Annual Increase | C47: =C46-B46 -> 4406677.7 | D47: =D46-C46 -> 0 | E47: =E46-D46 -> 6809667.8 | F47: =F46-E46 -> 34048339
A48: Time to Process days | C48: 100 | D48: 100 | E48: 100 | F48: 100
...

Sheet Cloud
A2: Table cloud | B2: We have on going cloud costs and assume some other activities may be on cloud in the future - we make an estimate of those costs here. | C2: 12 | D2: 0 | E2: | l |r |r |r |r |r |r |r |r |r |r |r |r |
A3: Year | B3: 2024 | C3: =B3+1 -> 2025 | D3: =C3+1 -> 2026 | E3: =D3+1 -> 2027 | F3: =E3+1 -> 2028 | G3: =F3+1 -> 2029 | H3: =G3+1 -> 2030 | I3: =H3+1 -> 2031 | J3: =I3+1 -> 2032 | ... M3: =L3+1 -> 2035
A4: Jira Cloud | B4: 80000 | C4: 80000 | D4: 80000 | E4: 80000 | F4: 80000 | G4: 80000 | H4: 80000 | I4: 80000 | J4: 80000 | K4: 80000 | L4: 80000 | M4: 80000
A5: Current actuals | B5: 20000 | C5: 20000 | D5: 20000 | E5: 20000 | F5: 20000 | G5: 20000 | H5: 20000 | I5: 20000 | J5: 20000 | K5: 20000 | L5: 20000 | M5: 20000
A6: RPF sims, V&V | B6: 10000 | C6: 10000 | D6: 10000 | E6: 10000 | F6: 10000 | G6: 10000 | H6: 10000 | I6: 10000 | J6: 10000 | K6: 10000 | L6: 0
A7: Total | B7: =sum(B4:B6) -> 110000 | C7: =sum(C4:C6) -> 110000 | D7: =sum(D4:D6) -> 110000 | E7: =sum(E4:E6) -> 110000 | F7: =sum(F4:F6) -> 110000 | G7: =sum(G4:G6) -> 110000 | H7: =sum(H4:H6) -> 110000 | I7: =sum(I4:I6) -> 110000 | ... M7: =sum(M4:M6) -> 100000
A11: As M$ | B11: =B7/1000000 -> 0.11 | C11: =C7/1000000 -> 0.11 | D11: =D7/1000000 -> 0.11 | E11: =E7/1000000 -> 0.11 | F11: =F7/1000000 -> 0.11 | G11: =G7/1000000 -> 0.11 | H11: =H7/1000000 -> 0.11 | I11: =I7/1000000 -> 0.11 | ... M11: =M7/1000000 -> 0.1
B13: Sims | C13: 8 nodes 12 CPUs 5 days
A15: Table cdacneeds | B15: Hybrid model USDF Cloud Data Access Center required resources. | C15: 4 | D15: 0 | E15: |l |r |r |r
A16: Resource | B16: Year 1 | C16: Year 2 | D16: Year 3
A17: concurrent users | B17: 500 | C17: 600 | D17: 750
A18: cores | B18: 500 | C18: 1000 | D18: 1500
A19: per user storage (GB) | B19: 360 | C19: 460 | D19: 560
A20: CoAdds objectstore (PB) | B20: 2.7 | C20: 2.7 | D20: 2.7
A21: parquet file cache (TB) | B21: 400 | C21: 800 | D21: 1200
A22: Total user storage (TB) | B22: =B17*B19/1000 -> 180 | C22: =C17*C19/1000 -> 276 | D22: =D17*D19/1000 -> 420

Sheet PreOps
A2: Table preOps | B2: This table builds a ramp for build up at SLAC as USDF. These would be purchases to get initial systems in place for the first year of operations. This is based on the Rome processor price and other construction inputs. | C2: 4 | D2: 0 | E2: |l |r |r |r |
A3: Year (Pricing $million) | B3: 2021 | C3: =B3+1 -> 2022 | D3: =C3+1 -> 2023
A4: =concat(concat("Compute (",Model!$G$11), " pricing)") -> Compute (2020 pricing) | B4: =B25 -> 0.02 | C4: =C25 -> 0.04 | D4: =D25 -> 0.43
A5: =concat(concat("Qserv (",Model!$G$11), " pricing)") -> Qserv (2020 pricing) | D5: =Model!D5/1000000 -> 0.28
A6: =concat(concat("Storage (",Model!$G$11), " pricing)") -> Storage (2020 pricing) | B6: =B38/1000000 -> 0.31192744 | C6: =C38/1000000 -> 0.095547907 | D6: =D38/1000000 -> 0.52335422
A7: =concat(concat("Total (",Model!$G$11), " pricing)") -> Total (2020 pricing) | B7: =sum(B4:B6) -> 0.33192744 | C7: =sum(C4:C6) -> 0.13554791 | D7: =sum(D4:D6) -> 1.2333542
A8: Applying price factor (CPU) | B8: =B$4*pow(cpuFac, B$3 -scaleYear) -> 0.018 | C8: =C$4*pow(cpuFac, C$3 -scaleYear) -> 0.0324 | D8: =D$4*pow(cpuFac, D$3 -scaleYear) -> 0.31347
A9: Qserv (applying factor) | B9: =B$5*pow(qservFac, B$3 -scaleYear) -> 0 | C9: =C$5*pow(qservFac, C$3 -scaleYear) -> 0 | D9: =D$5*pow(qservFac, D$3 -scaleYear) -> 0.22160688
A10: Applying price factor (Storage) | B10: =B$6*pow(diskFac, B$3 -scaleYear) -> 0.29633107 | C10: =C$6*pow(diskFac, C$3 -scaleYear) -> 0.086231986 | D10: =D$6*pow(diskFac, D$3 -scaleYear) -> 0.44871082
A11: Hosting Overhead SLAC | B11: =0.05*sum(B8:B10)+0.1 -> 0.11571655 | C11: =0.05*sum(C8:C10)+0.1 -> 0.1059316 | D11: =0.05*sum(D8:D10)+0.1 -> 0.14918938
A12: Total budget (using price factors) | B12: =sum(B8:B11) -> 0.43004762 | C12: =sum(C8:C11) -> 0.22456359 | D12: =sum(D8:D11) -> 1.1329771
A13: =concat("Total Pre Ops hardware to ", $D$3) -> Total Pre Ops hardware to 2023 | B13: =sum(B12:D12) -> 1.7875883 | C13: million
A17: Table preCompute | B17: Preoperations compute build up at USDF, cores we need to purchase per year. | C17: 4 | D17: 0
A18: Year | B18: =B3 -> 2021 | C18: =C3 -> 2022 | D18: =D3 -> 2023
A19: DRP cores (from construction) | B19: 0 | C19: =Model!C50 -> 1836.1157 | D19: =Model!E51 -> 2837.3616
A20: Alerts cores (from construction) | D20: =Model!E53 -> 1188.4091
A21: Dev Cores | B21: 100 | C21: =540-B21 -> 440 | E21: need to check
A22: K8S (science platform) | B22: 100 | D22: =(32*32) - B22 -> 924 | E22: need to check
A23: Total cores | B23: =sum(B19:B22) -> 200 | C23: =sum(C20:C22) -> 440 | D23: =sum(D19:D22) -> 4949.7707
A24: Number of Large Rome USDF | B24: =roundup((B23)/Model!$D$29,0) -> 2 | C24: =roundup((C23)/Model!$D$29,0) -> 4 | D24: =roundup((D23)/Model!$D$29,0) -> 43
A25: =concat(concat("Compute (",Model!$G$11), " pricing)") -> Compute (2020 pricing) | B25: =B24*Model!$E$26/1000000 -> 0.02 | C25: =C24*Model!$E$26/1000000 -> 0.04 | D25: =D24*Model!$E$26/1000000 -> 0.43
A28: Table preStorage | B28: Preoperations storage to be purchaed each year | C28: 4 | D28: 0
A29: Year | B29: =B3 -> 2021 | C29: =C3 -> 2022 | D29: =D3 -> 2023
A30: =Model!A63 -> Fast Storage (TB) | B30: =Model!C64 -> 11.842105 | C30: =Model!D64 -> 11.842105 | D30: =Model!E64 -> 26.07
A31: =Model!A65 -> Normal Storage (TB) | B31: =Model!C65 -> 3466.8175 | C31: =Model!D66 -> 68.146467 | D31: =Model!E66 -> 3094.61
A32: =Model!A67 -> Latent Storage (TB) | B32: =Model!C68 -> 318.52031 | C32: =Model!D68 -> 557.41054 | D32: =Model!E68 -> 2553.0243
A33: =Model!A69 -> High Latency (TB) | B33: =Model!C70 -> 2697.5687 | C33: =Model!D70 -> 3004.6054 | D33: =Model!E70 -> 7513.8542
A34: =concat(concat("Fast (",Model!$G$11), " pricing)") -> Fast (2020 pricing) | B34: =B30*Model!$B$35 -> 4736.8421 | C34: =C30*Model!$B$35 -> 4736.8421 | D34: =D30*Model!$B$35 -> 10428
A35: =concat(concat("Normal (",Model!$G$11), " pricing)") -> Normal (2020 pricing) | B35: =B31*Model!$B$36 -> 242677.23 | C35: =C31*Model!$B$36 -> 4770.2527 | D35: =D31*Model!$B$36 -> 216622.7
A36: =concat(concat("Latent (",Model!$G$11), " pricing)") -> Latent (2020 pricing) | B36: =B32*Model!$B$37 -> 22296.421 | C36: =C32*Model!$B$37 -> 39018.738 | D36: =D32*Model!$B$37 -> 178711.7
A37: =concat(concat("High Latency (",Model!$G$11), " pricing)") -> High Latency (2020 pricing) | B37: =B33*Model!$B$38 -> 42216.95 | C37: =C33*Model!$B$38 -> 47022.075 | D37: =D33*Model!$B$38 -> 117591.82
A38: =concat(concat("Total Storage PreOps (",Model!$G$11), " pricing)") -> Total Storage PreOps (2020 pricing) | B38: =sum(B34:B37) -> 311927.44 | C38: =sum(C34:C37) -> 95547.907 | D38: =sum(D34:D37) -> 523354.22

Sheet Ops Costs
A2: Table opsSummary | B2: This table adds the USDF (see \tabref{tab:opsSumUSDF}) and \tabref{tab:opsChileR} to give total operations hardware costs. | C2: 11 | D2: 0
A3: Year (all prices Million$) | B3: 2024 | C3: =B3+1 -> 2025 | D3: =C3+1 -> 2026 | E3: =D3+1 -> 2027 | F3: =E3+1 -> 2028 | G3: =F3+1 -> 2029 | H3: =G3+1 -> 2030 | I3: =H3+1 -> 2031 | J3: =I3+1 -> 2032 | ... M3: =L3+1 -> 2035
A4: USDF hardware | B4: =B50 -> 4.1975833 | C4: =C50 -> 4.9866885 | D4: =D50 -> 4.9873463 | E4: =E50 -> 5.1334159 | F4: =F50 -> 5.505049 | G4: =G50 -> 7.2092778 | H4: =H50 -> 6.2862525 | I4: =I50 -> 6.3718347 | ... M4: =M50 -> 1.6747273
A5: Chile hardware | B5: =B31 -> 0.96485544 | C5: =C31 -> 0.86578121 | D5: =D31 -> 0.83655788 | E5: =E31 -> 0.70058055 | F5: =F31 -> 0.74634181 | G5: =G31 -> 1.414428 | H5: =H31 -> 1.1461369 | I5: =I31 -> 1.1325883 | ... M5: =M31 -> 0.10987718
A6: Total budget (using price factors) | B6: =sum(B4:B5) -> 5.1624387 | C6: =sum(C4:C5) -> 5.8524698 | D6: =sum(D4:D5) -> 5.8239042 | E6: =sum(E4:E5) -> 5.8339965 | F6: =sum(F4:F5) -> 6.2513908 | G6: =sum(G4:G5) -> 8.6237058 | H6: =sum(H4:H5) -> 7.4323894 | I6: =sum(I4:I5) -> 7.5044231 | ... M6: =sum(M4:M5) -> 1.7846045
A7: =concat("Total Operations hardware to ", $K$3) -> Total Operations hardware to 2033 | B7: =sum(B6:K6) -> 67.170511 | C7: million | D7: =concat("to ",$M$3) -> to 2035 | E7: =sum(B6:M6) -> 72.841942
A9: Table opsSumChile | B9: This table pulls together all the information in a high level summary for Chile operations - in this table Xeon pricing(see \tabref{tab:opsXeonChile}) is used since that is the more expensive but better known option. Price factors, defined in \tabref{tab:Inputs} are applied in all cases - other input values come from \tabref{tab:opsInputs}, \tabref{tab:opsStorageChile}. | C9: 11 | D9: 0
A10: Year (all prices Million$) | B10: =B3 -> 2024 | C10: =C3 -> 2025 | D10: =D3 -> 2026 | E10: =E3 -> 2027 | F10: =F3 -> 2028 | G10: =G3 -> 2029 | H10: =H3 -> 2030 | I10: =I3 -> 2031 | ... M10: =M3 -> 2035 | N10: Total 12 years
A11: =concat(concat("Compute (",Model!$G$11), " pricing)") -> Compute (2020 pricing) | B11: =B115 -> 0.04 | C11: =C115 -> 0.04 | D11: =D115 -> 0.04 | E11: =E115 -> 0.08 | F11: =F115 -> 0.07 | G11: =G115 -> 0.07 | H11: =H115 -> 0.07 | I11: =I115 -> 0.07 | ... K11: =K115 -> 0.07 | L11: =0.5*K11 -> 0.035 | N11: =sum(B11:M11) -> 0.655
A12: =concat(concat("Qserv (",Model!$G$11), " pricing)") -> Qserv (2020 pricing) | B12: =B76 *Model!$E$27/1000000 -> 1.9 | C12: =C76 *Model!$E$27/1000000 -> 2.42 | D12: =D76 *Model!$E$27/1000000 -> 1.86 | E12: =E76 *Model!$E$27/1000000 -> 2.68 | F12: =F76 *Model!$E$27/1000000 -> 2.74 | G12: =G76 *Model!$E$27/1000000 -> 3.6 | H12: =H76 *Model!$E$27/1000000 -> 2.38 | I12: =I76 *Model!$E$27/1000000 -> 2.18 | ... K12: =K76 *Model!$E$27/1000000 -> 3.4 | L12: =0.5*K12 -> 1.7 | N12: =sum(B12:M12) -> 27.64
A13: =concat(concat("Storage (",Model!$G$11), " pricing)") -> Storage (2020 pricing) | B13: =B152 -> 0.8418 | C13: =C152 -> 0.61957 | D13: =D152 -> 0.60393 | E13: =E152 -> 0.42319 | F13: =F152 -> 0.41072 | G13: =G152 -> 1.25299 | H13: =H152 -> 1.03036 | I13: =I152 -> 1.01472 | ... K13: =K152 -> 0.82151 | L13: =0.5*K13 -> 0.410755 | N13: =sum(B13:M13) -> 8.263925
A14: =concat(concat("Total (",Model!$G$11), " pricing)") -> Total (2020 pricing) | B14: =sum(B11:B13) -> 2.7818 | C14: =sum(C11:C13) -> 3.07957 | D14: =sum(D11:D13) -> 2.50393 | E14: =sum(E11:E13) -> 3.18319 | F14: =sum(F11:F13) -> 3.22072 | G14: =sum(G11:G13) -> 4.92299 | H14: =sum(H11:H13) -> 3.48036 | I14: =sum(I11:I13) -> 3.26472 | ... L14: =sum(L11:L13) -> 2.145755 | N14: =sum(B14:M14) -> 36.558925
A15: Applying price factor (CPU) | B15: =B$11*pow(cpuFac, B$10 -scaleYear) -> 0.026244 | C15: =C$11*pow(cpuFac, C$10 -scaleYear) -> 0.0236196 | D15: =D$11*pow(cpuFac, D$10 -scaleYear) -> 0.02125764 | E15: =E$11*pow(cpuFac, E$10 -scaleYear) -> 0.038263752 | F15: =F$11*pow(cpuFac, F$10 -scaleYear) -> 0.030132705 | G15: =G$11*pow(cpuFac, G$10 -scaleYear) -> 0.027119434 | H15: =H$11*pow(cpuFac, H$10 -scaleYear) -> 0.024407491 | I15: =I$11*pow(cpuFac, I$10 -scaleYear) -> 0.021966742 | ... K15: =K$11*pow(cpuFac, K$10 -scaleYear) -> 0.017793061 | L15: =0.5*K15 -> 0.0088965304 | N15: =sum(B15:M15) -> 0.25947102
A16: Qserv (applying factor) | B16: =B$12*pow(qservFac, B$10 -scaleYear) -> 1.3909789 | C16: =C$12*pow(qservFac, C$10 -scaleYear) -> 1.6387927 | D16: =D$12*pow(qservFac, D$10 -scaleYear) -> 1.1651004 | E16: =E$12*pow(qservFac, E$10 -scaleYear) -> 1.5528408 | F16: =F$12*pow(qservFac, F$10 -scaleYear) -> 1.4685354 | G16: =G$12*pow(qservFac, G$10 -scaleYear) -> 1.7847529 | H16: =H$12*pow(qservFac, H$10 -scaleYear) -> 1.091426 | I16: =I$12*pow(qservFac, I$10 -scaleYear) -> 0.92473129 | ... K16: =K$12*pow(qservFac, K$10 -scaleYear) -> 1.2340179 | L16: =0.5*K16 -> 0.61700893 | N16: =sum(B16:M16) -> 13.958986
A17: Applying price factor (Storage) | B17: =B$13*pow(diskFac, B$10 -scaleYear) -> 0.68565136 | C17: =C$13*pow(diskFac, C$10 -scaleYear) -> 0.47941146 | D17: =D$13*pow(diskFac, D$10 -scaleYear) -> 0.44394405 | E17: =E$13*pow(diskFac, E$10 -scaleYear) -> 0.29552936 | F17: =F$13*pow(diskFac, F$10 -scaleYear) -> 0.27248004 | G17: =G$13*pow(diskFac, G$10 -scaleYear) -> 0.78969621 | H17: =H$13*pow(diskFac, H$10 -scaleYear) -> 0.61691459 | I17: =I$13*pow(diskFac, I$10 -scaleYear) -> 0.57717283 | ... K17: =K$13*pow(diskFac, K$10 -scaleYear) -> 0.42171565 | L17: =0.5*K17 -> 0.21085783 | N17: =sum(B17:M17) -> 5.244239
A18: Overhead hosting Chile | B18: =B$188/1000000 -> 0.25296008 | C18: =C188/1000000 -> 0.36275015 | D18: =D188/1000000 -> 0.3713562 | E18: =E188/1000000 -> 0.36678743 | F18: =F188/1000000 -> 0.44372907 | G18: =G188/1000000 -> 0.59761233 | H18: =H188/1000000 -> 0.50481477 | I18: =I188/1000000 -> 0.53344877 | J18: =J188/1000000 -> 0.53344877 | ... L18: =L188/1000000 -> 0.46761789 | N18: =sum(B18:M18) -> 5.0482739
A19: Total budget (using price factors) | B19: =sum(B15:B18) -> 2.3558343 | C19: =sum(C15:C18) -> 2.5045739 | D19: =sum(D15:D18) -> 2.0016583 | E19: =sum(E15:E18) -> 2.2534213 | F19: =sum(F15:F18) -> 2.2148772 | G19: =sum(G15:G18) -> 3.1991809 | H19: =sum(H15:H18) -> 2.2375628 | I19: =sum(I15:I18) -> 2.0573196 | ... L19: =sum(L15:L18) -> 1.3043812 | N19: =sum(B19:M19) -> 24.51097
A20: =concat("Total Operations hardware to ", $K$3) -> Total Operations hardware to 2033 | B20: =sum(B19:K19) -> 23.206589 | C20: million | D20: =concat("to ",$M$3) -> to 2035 | E20: =sum(B19:M19) -> 24.51097
A23: Table opsChileR | B23: "This table pulls together all the information in a high level summary for Chile operations - in this table Rome pricing(see \tabref{tab:opsRomeChile}) is used Price factors, defined in \tabref{tab:Inputs} are applied in all cases - other input values come from \tabref{tab:opsInputs}, \tabref{tab:opsStorageChile}. | C23: 11 | D23: 0
A24: Year (all prices Million$) | B24: =B$3 -> 2024 | C24: =C$3 -> 2025 | D24: =D$3 -> 2026 | E24: =E$3 -> 2027 | F24: =F$3 -> 2028 | G24: =G$3 -> 2029 | H24: =H$3 -> 2030 | I24: =I$3 -> 2031 | ... M24: =M$3 -> 2035 | N24: Total 12 years
A25: =concat(concat("Compute (",Model!$G$11), " pricing)") -> Compute (2020 pricing) | B25: =B136 -> 0.039 | C25: =C136 -> 0.039 | D25: =D136 -> 0.039 | E25: =E136 -> 0.078 | F25: =F136 -> 0.078 | G25: =G136 -> 0.078 | H25: =H136 -> 0.078 | I25: =I136 -> 0.078 | ... K25: =K136 -> 0.078 | L25: =0.5*K25 -> 0.039 | M25: =0.5*L25 -> 0.0195 | N25: =sum(B25:M25) -> 0.7215
A26: =concat(concat("Storage (",Model!$G$11), " pricing)") -> Storage (2020 pricing) | B26: =B152 -> 0.8418 | C26: =C152 -> 0.61957 | D26: =D152 -> 0.60393 | E26: =E152 -> 0.42319 | F26: =F152 -> 0.41072 | G26: =G152 -> 1.25299 | H26: =H152 -> 1.03036 | I26: =I152 -> 1.01472 | ... K26: =K152 -> 0.82151 | L26: =0.5*K26 -> 0.410755 | M26: =0.5*L26 -> 0.2053775 | N26: =sum(B26:M26) -> 8.4693025
A27: =concat(concat("Total (",Model!$G$11), " pricing)") -> Total (2020 pricing) | B27: =sum(B25:B26) -> 0.8808 | C27: =sum(C25:C26) -> 0.65857 | D27: =sum(D25:D26) -> 0.64293 | E27: =sum(E25:E26) -> 0.50119 | F27: =sum(F25:F26) -> 0.48872 | G27: =sum(G25:G26) -> 1.33099 | H27: =sum(H25:H26) -> 1.10836 | I27: =sum(I25:I26) -> 1.09272 | ... K27: =sum(K25:K26) -> 0.89951 | L27: =0.5*K27 -> 0.449755 | M27: =0.5*L27 -> 0.2248775 | N27: =sum(B27:M27) -> 9.1908025
A28: Applying price factor (CPU) | B28: =B$11*pow(cpuFac, B$10 -scaleYear) -> 0.026244 | C28: =C$11*pow(cpuFac, C$10 -scaleYear) -> 0.0236196 | D28: =D$11*pow(cpuFac, D$10 -scaleYear) -> 0.02125764 | E28: =E$11*pow(cpuFac, E$10 -scaleYear) -> 0.038263752 | F28: =F$11*pow(cpuFac, F$10 -scaleYear) -> 0.030132705 | G28: =G$11*pow(cpuFac, G$10 -scaleYear) -> 0.027119434 | H28: =H$11*pow(cpuFac, H$10 -scaleYear) -> 0.024407491 | I28: =I$11*pow(cpuFac, I$10 -scaleYear) -> 0.021966742 | ... K28: =K$11*pow(cpuFac, K$10 -scaleYear) -> 0.017793061 | L28: =0.5*K28 -> 0.0088965304 | M28: =0.5*L28 -> 0.0044482652 | N28: =sum(B28:M28) -> 0.26391929
A29: Applying price factor (Storage) | B29: =B$26*pow(diskFac, B$10 -scaleYear) -> 0.68565136 | C29: =C$26*pow(diskFac, C$10 -scaleYear) -> 0.47941146 | D29: =D$26*pow(diskFac, D$10 -scaleYear) -> 0.44394405 | E29: =E$26*pow(diskFac, E$10 -scaleYear) -> 0.29552936 | F29: =F$26*pow(diskFac, F$10 -scaleYear) -> 0.27248004 | G29: =G$26*pow(diskFac, G$10 -scaleYear) -> 0.78969621 | H29: =H$26*pow(diskFac, H$10 -scaleYear) -> 0.61691459 | I29: =I$26*pow(diskFac, I$10 -scaleYear) -> 0.57717283 | ... K29: =K$26*pow(diskFac, K$10 -scaleYear) -> 0.42171565 | L29: =0.5*K29 -> 0.21085783 | M29: =0.5*L29 -> 0.10542891 | N29: =sum(B29:M29) -> 5.3496679
A30: Overhead hosting Chile | B30: =B$188/1000000 -> 0.25296008 | C30: =C$188/1000000 -> 0.36275015 | D30: =D$188/1000000 -> 0.3713562 | E30: =E$188/1000000 -> 0.36678743 | F30: =F$188/1000000 -> 0.44372907 | G30: =G$188/1000000 -> 0.59761233 | H30: =H$188/1000000 -> 0.50481477 | I30: =I$188/1000000 -> 0.53344877 | ... M30: =M$188/1000000 -> 0 | N30: =sum(B30:M30) -> 5.0482739
A31: Total budget (using price factors) | B31: =sum(B28:B30) -> 0.96485544 | C31: =sum(C28:C30) -> 0.86578121 | D31: =sum(D28:D30) -> 0.83655788 | E31: =sum(E28:E30) -> 0.70058055 | F31: =sum(F28:F30) -> 0.74634181 | G31: =sum(G28:G30) -> 1.414428 | H31: =sum(H28:H30) -> 1.1461369 | I31: =sum(I28:I30) -> 1.1325883 | ... M31: =sum(M28:M30) -> 0.10987718 | N31: =sum(B31:M31) -> 10.661861
A32: =concat("Total Chile hardware to ", $K$3) -> Total Chile hardware to 2033 | B32: =sum(B31:K31) -> 9.8646117 | C32: million | D32: =concat("to ",$M$3) -> to 2035 | E32: =sum(B31:M31) -> 10.661861
A34: Table opsSumUSDF | B34: This table pulls together all the information in a high level summary for USDF operations - in this table Rome pricing(see \tabref{tab:opsRomeUSDF}). Price factors, defined in \tabref{tab:Inputs} are applied in all cases - other input values come from \tabref{tab:opsInputs}, \tabref{tab:opsStorageUSDF}. | C34: 11 | D34: 0
A35: Year (all prices Million$) | B35: =B3 -> 2024 | C35: =C3 -> 2025 | D35: =D3 -> 2026 | E35: =E3 -> 2027 | F35: =F3 -> 2028 | G35: =G3 -> 2029 | H35: =H3 -> 2030 | I35: =I3 -> 2031 | ... M35: =M3 -> 2035 | N35: 10-year Total | O35: 12-year Total
A36: =concat(concat("Compute (",Model!$G$11), " pricing) DRP") -> Compute (2020 pricing) DRP | B36: =B127 -> 0.806 | C36: =C127 -> 0.858 | D36: =D127 -> 1.274 | E36: =E127 -> 1.755 | F36: =F127 -> 1.807 | G36: =G127 -> 1.911 | H36: =H127 -> 1.911 | I36: =I127 -> 1.911 | ... K36: =K127 -> 1.911 | L36: =0.5*K36 -> 0.9555 | M36: =0.5*L36 -> 0.47775 | N36: =sum(B36:K36) -> 16.055 | O36: =sum(B36:M36) -> 17.48825
A37: =concat(concat("Compute (",Model!$G$11), " pricing) DAC") -> Compute (2020 pricing) DAC | B37: =B129 -> 0.052 | C37: =C129 -> 0.052 | D37: =D129 -> 0.078 | E37: =E129 -> 0.104 | F37: =F129 -> 0.104 | G37: =G129 -> 0.117 | H37: =H129 -> 0.117 | I37: =I129 -> 0.117 | ... K37: =K129 -> 0.117 | L37: =0.5*K37 -> 0.0585 | M37: =0.5*L37 -> 0.02925 | N37: =sum(B37:K37) -> 0.975 | O37: =sum(B37:M37) -> 1.06275
A38: =concat(concat("Compute (",Model!$G$11), " pricing) AP") -> Compute (2020 pricing) AP | B38: =B131 -> 0 | C38: =C131 -> 0 | D38: =D131 -> 0.143 | E38: =E131 -> 0 | F38: =F131 -> 0 | G38: =G131 -> 0.143 | H38: =H131 -> 0 | I38: =I131 -> 0 | ... K38: =K131 -> 0 | L38: =0.5*K38 -> 0 | M38: =0.5*L38 -> 0 | N38: =sum(B38:K38) -> 0.429 | O38: =sum(B38:M38) -> 0.429
A39: =concat(concat("Qserv (",Model!$G$11), " pricing)") -> Qserv (2020 pricing) | B39: =(B74)*Model!$E$27/1000000 -> 1.62 | C39: =(C74)*Model!$E$27/1000000 -> 2.42 | D39: =(D74)*Model!$E$27/1000000 -> 1.86 | E39: =(E74)*Model!$E$27/1000000 -> 2.4 | F39: =(F74)*Model!$E$27/1000000 -> 2.74 | G39: =(G74)*Model!$E$27/1000000 -> 3.6 | H39: =(H74)*Model!$E$27/1000000 -> 2.1 | I39: =(I74)*Model!$E$27/1000000 -> 2.18 | ... K39: =(K74)*Model!$E$27/1000000 -> 3.12 | L39: =0.5*K39 -> 1.56 | M39: =0.5*L39 -> 0.78 | N39: =sum(B39:K39) -> 24.82 | O39: =sum(B39:M39) -> 27.16
A40: =concat(concat("Storage (",Model!$G$11), " pricing)") -> Storage (2020 pricing) | B40: =B160 -> 2.6338854 | C40: =C160 -> 3.0963374 | D40: =D160 -> 3.7053434 | E40: =E160 -> 3.776509 | F40: =F160 -> 4.38916 | G40: =G160 -> 6.4224425 | H40: =H160 -> 6.9239854 | I40: =I160 -> 7.535882 | ... K40: =K160 -> 7.8267012 | L40: =0.5*K40 -> 3.9133506 | M40: =0.5*L40 -> 1.9566753 | N40: =sum(B40:K40) -> 53.918829 | O40: =sum(B40:M40) -> 59.788855
A41: Total (2019 pricing) | B41: =sum(B36:B40) -> 5.1118854 | C41: =sum(C36:C40) -> 6.4263374 | D41: =sum(D36:D40) -> 7.0603434 | E41: =sum(E36:E40) -> 8.035509 | F41: =sum(F36:F40) -> 9.04016 | G41: =sum(G36:G40) -> 12.193442 | H41: =sum(H36:H40) -> 11.051985 | I41: =sum(I36:I40) -> 11.743882 | ... M41: =sum(M36:M40) -> 3.2436753 | N41: =sum(B41:K41) -> 96.197829 | O41: =sum(B41:M41) -> 105.92885
A42: Applying price factor - DRP (CPU) | B42: =B36*pow(cpuFac, B35 -scaleYear) -> 0.5288166 | C42: =C36*pow(cpuFac, C35 -scaleYear) -> 0.50664042 | D42: =D36*pow(cpuFac, D35 -scaleYear) -> 0.67705583 | E42: =E36*pow(cpuFac, E35 -scaleYear) -> 0.83941106 | F42: =F36*pow(cpuFac, F35 -scaleYear) -> 0.77785425 | G42: =G36*pow(cpuFac, G35 -scaleYear) -> 0.74036055 | H42: =H36*pow(cpuFac, H35 -scaleYear) -> 0.6663245 | I42: =I36*pow(cpuFac, I35 -scaleYear) -> 0.59969205 | ... K42: =K36*pow(cpuFac, K35 -scaleYear) -> 0.48575056 | L42: =0.5*K42 -> 0.24287528 | M42: =0.5*L42 -> 0.12143764 | N42: =sum(B42:K42) -> 6.3616287 | O42: =sum(B42:M42) -> 6.7259416
A43: Applying price factor - DAC (CPU) | B43: =B37*pow(cpuFac, B35 -scaleYear) -> 0.0341172 | C43: =C37*pow(cpuFac, C35 -scaleYear) -> 0.03070548 | D43: =D37*pow(cpuFac, D35 -scaleYear) -> 0.041452398 | E43: =E37*pow(cpuFac, E35 -scaleYear) -> 0.049742878 | F43: =F37*pow(cpuFac, F35 -scaleYear) -> 0.04476859 | G43: =G37*pow(cpuFac, G35 -scaleYear) -> 0.045328197 | H43: =H37*pow(cpuFac, H35 -scaleYear) -> 0.040795377 | I43: =I37*pow(cpuFac, I35 -scaleYear) -> 0.03671584 | ... K43: =K37*pow(cpuFac, K35 -scaleYear) -> 0.02973983 | L43: =0.5*K43 -> 0.014869915 | M43: =0.5*L43 -> 0.0074349575 | N43: =sum(B43:K43) -> 0.38641005 | O43: =sum(B43:M43) -> 0.40871492
A44: Applying price factor - AP (CPU) | B44: =B38*pow(cpuFac, B35 -scaleYear) -> 0 | C44: =C38*pow(cpuFac, C35 -scaleYear) -> 0 | D44: =D38*pow(cpuFac, D35 -scaleYear) -> 0.075996063 | E44: =E38*pow(cpuFac, E35 -scaleYear) -> 0 | F44: =F38*pow(cpuFac, F35 -scaleYear) -> 0 | G44: =G38*pow(cpuFac, G35 -scaleYear) -> 0.05540113 | H44: =H38*pow(cpuFac, H35 -scaleYear) -> 0 | I44: =I38*pow(cpuFac, I35 -scaleYear) -> 0 | ... K44: =K38*pow(cpuFac, K35 -scaleYear) -> 0 | L44: =0.5*K44 -> 0 | M44: =0.5*L44 -> 0 | N44: =sum(B44:K44) -> 0.17178462 | O44: =sum(B44:M44) -> 0.17178462
A45: IN2P3 (40% of compute) | B45: =-(B42*0.4) -> -0.21152664 | C45: =-(C42*0.4) -> -0.20265617 | D45: =-(D42*0.4) -> -0.27082233 | E45: =-(E42*0.4) -> -0.33576442 | F45: =-(F42*0.4) -> -0.3111417 | G45: =-(G42*0.4) -> -0.29614422 | H45: =-(H42*0.4) -> -0.2665298 | I45: =-(I42*0.4) -> -0.23987682 | ... M45: =-(M42*0.4) -> -0.048575056 | N45: =sum(B45:K45) -> -2.5446515 | O45: =sum(B45:M45) -> -2.6903766
...

Sheet Comissioning
C4: Estimated | D4: AMD Rome 7502P | E4: 50 x AMD Rome 7502P + 10 U2 Nvme | F4: 25 x AMD Rome 7252 + 10 SSD 4TB
A5: Storage SSD (TB) | B5: 1000 | C5: =Model!B35*B5 -> 400000 | E5: 925000 | F5: 237500
A6: Compute cores | B6: =Model!$B$26*B7 -> 1152
A7: Compute nodes | B7: =Model!$B$117 -> 36 | C7: =Model!E26*B7 -> 360000 | D7: 200000
A8: racks | B8: 2 | C8: ='Ops Costs'!E197*B8 -> 57268
A9: total | C9: =SUM(C5:C8) -> 817268
A13: AMD Rome 7502P 32C/64T - 64GB Ram - 10G Net - 500GB M2 = ~$5,500
A15: U2 nvme 2TB = $1300
A17: AMD Rome 7252 16C/32T - 256RAM - 10G Net - 500GB M2 = ~$4400
A19: SSD Sata3 4TB = $500

Sheet Storage
A1: Table storageSizing | B1: Inputs used to calculate storage needs | C1: 7 | D1: 0
A2: Parameters | B2: unit | C2: FY2020 | D2: FY2021 | E2: FY2022 | F2: FY2023 | G2: Notes
A4: Objects | B4: number | E4: =F4*2/12 -> 4583333333 | F4: 27500000000 | G4: from LSE-81, scaled to 2 months for 2022, ComCam ignored
A5: Sources | B5: number | E5: =F5*2/12 -> 150166666667 | F5: 901000000000 | G5: from LSE-81, scaled to 2 months for 2022, ComCam ignored
A6: ForcedSources | B6: number | E6: =F6*2/12 -> 485000000000 | F6: 2910000000000 | G6: from LSE-81, scaled to 2 months for 2022, ComCam ignored
A8: Science users | B8: users | C8: 50 | D8: 100 | E8: 5000 | F8: 5000 | G8: "Stack Club" to 2021, DP users thereafter
A9: Storage per science user | B9: TB | C9: 0.1 | D9: 0.2 | E9: 0.2 | F9: 0.4 | G9: ramp to LSE-81 number; includes oversubscription
A11: LSSTCam image size | B11: TB | C11: =16*562*2098*(189+12)*4/1000000000000 -> 0.015167634 | G11: uncompressed, 32 bit, with overscan and corner rafts
A12: Raw image compression | B12: factor | C12: 0.42 | G12: lossless-compressed divided by uncompressed for raws
A13: Lossy image compression | B13: factor | C13: 0.25 | G13: lossy-compressed divided by lossless-compressed for PVIs
A14: LSSTCam/HSC pixel ratio | B14: factor | C14: =C11/C39/2 -> 0.0093647346 | G14: single LSSTCam image divided by all HSC images, /2 for pixel bytes (4 for LSSTCam, 2 for HSC)
A16: Observing nights per year | B16: nights | C16: 300 | G16: maximum
A17: Visits per night | B17: visits | C17: 1000 | G17: maximum
A18: Images per visit | B18: images | C18: 2
A19: Calibration images per day | B19: images | C19: 500
A20: LSSTCam Science images | B20: images | E20: =F20*2/12 -> 100000 | F20: =nightsPerYear*visitsPerNight*imagesPerVisit -> 600000 | G20: test images until 2 months of science in 2022
A21: LSSTCam Test images | B21: images | C21: =0.5*D21 -> 25000 | D21: =E21 -> 50000 | E21: =0.5*E20 -> 50000 | G21: ramp to science images
A22: LSSTCam Engineering images | B22: images | C22: =0.5*(C20+C21) -> 12500 | D22: =0.25*(D20+D21) -> 12500 | E22: =0.1*(E20+E21) -> 15000 | F22: =0.01*F20 -> 6000 | G22: decreasing ramp
A23: LSSTCam Calibration images | B23: images | C23: =(C20+C21)*0.5 -> 12500 | D23: =(D20+D21)*0.5 -> 25000 | E23: =(E20+E21)*0.25 -> 37500 | F23: =nightsPerYear*calsPerDay -> 150000 | G23: estimates based on science and test images; actual for 2023
A24: Number of coadd data products | B24: number | C24: 2 | G24: deep and good-seeing
A25: Object table row size | B25: bytes | E25: 1896 | F25: 1896 | G25: from LDM-141
A26: Object_Extra tables row size | B26: bytes | E26: 21005 | F26: 21005 | G26: from LDM-141
A27: Source table row size | B27: bytes | E27: 467 | F27: 467 | G27: from LDM-141
A28: ForcedSource table row size | B28: bytes | E28: 41 | F28: 41 | G28: from LDM-141
A29: Qserv replication factor | B29: factor | C29: 3 | D29: 3 | E29: 3 | F29: 3
A31: Table datasetSizing | B31: Inputs on dataset sizes used to calculate storage needs | C31: 7 | D31: 0
A32: Dataset Sizing | B32: unit | C32: FY2020 | D32: FY2021 | E32: FY2022 | F32: FY2023 | G32: Notes
A33: HSC RC2 Area | B33: deg^2 | C33: 8.5 | D33: 8.5 | E33: 8.5 | F33: 8.5
A34: HSC SSP PDR2 Area | B34: deg^2 | C34: 300 | D34: 300 | E34: 300 | F34: 300
A35: DESC DC2 Area | B35: deg^2 | C35: 300 | D35: 300 | E35: 300 | F35: 300
A36: LSSTCam Area | B36: deg^2 | E36: 2000 | F36: 17000
A38: APDB | B38: TB | C38: =4.5/57000*visitsPerNight*nightsPerYear*0.5 -> 11.842105 | D38: =4.5/57000*visitsPerNight*nightsPerYear -> 23.684211 | E38: =4.5/57000*visitsPerNight*nightsPerYear -> 23.684211 | F38: =4.5/57000*visitsPerNight*nightsPerYear -> 23.684211 | G38: 4.5/57K TB per visit; 1 year retention; 6 months in 2020
A39: HSC RC2 Input Images | B39: TB | C39: =44496*18.2/1000000 -> 0.8098272 | D39: =C39 -> 0.8098272 | E39: =D39 -> 0.8098272 | F39: =E39 -> 0.8098272 | G39: 432 visits * 103 CCDs * 18.2 MB uncompressed
A40: HSC RC2 Output Images | B40: TB | C40: 2.4 | D40: =C40 -> 2.4 | E40: =D40 -> 2.4 | F40: =E40 -> 2.4 | G40: lossless-compressed, not including warps
A41: HSC RC2 Output Coadd Images | B41: TB | C41: 0.675 | D41: =C41 -> 0.675 | E41: =D41 -> 0.675 | F41: =E41 -> 0.675 | G41: lossless-compressed
A42: HSC RC2 Output Catalogs | B42: TB | C42: =(221+486+540+172)/1000 -> 1.419 | D42: =C42 -> 1.419 | E42: =D42 -> 1.419 | F42: =E42 -> 1.419
A43: HSC SSP PDR2 Input Images | B43: TB | C43: =2564358*2*18.2/1000000 -> 93.342631 | D43: =C43 -> 93.342631 | E43: =D43 -> 93.342631 | F43: =E43 -> 93.342631 | G43: 2564358 CCDs * 18.2 MB uncompressed (3 * PDR1)
A44: DESC DC2 Input Images | B44: TB | C44: =300/10*1000*lsstCamImageSize -> 455.02901 | D44: =300/10*1000*lsstCamImageSize -> 455.02901 | E44: =300/10*1000*lsstCamImageSize -> 455.02901 | F44: =300/10*1000*lsstCamImageSize -> 455.02901 | G44: 300 sq deg, 10 year depth
A45: Object store datasets:
A46: LSSTCam Raw Images | B46: TB | C46: =sum(C20:C23)*lsstCamImageSize*rawCompression -> 318.52031 | D46: =sum(D20:D23)*lsstCamImageSize*rawCompression -> 557.41054 | E46: =sum(E20:E23)*lsstCamImageSize*rawCompression -> 1290.0072 | F46: =sum(F20:F23)*lsstCamImageSize*rawCompression -> 4816.027 | G46: compressed, immediate object store
...

Sheet Compute
A1: Table computeSizing | B1: Inputs used to calculate compute needs | C1: 7 | D1: 0
A2: Parameters | B2: units | G2: Notes
A3: HSC PDR1 Input Images | B3: TB | C3: =7238*104*18.2/1000000 -> 13.700086 | G3: 7238 visits of 104 CCDs
A4: HSC PDR1 small-memory compute | B4: core-hours | C4: =(9227-6544)*24 -> 64392 | G4: measured on E5-2680 v3 @ 2.50GHz
A5: HSC PDR1 high-memory compute | B5: core-hours | C5: =6543.57*12 -> 78522.84 | G5: measured on E5-2680 v3 @ 2.50GHz
A6: Small-memory DRP algorithm ratio | B6: factor | C6: 1.5 | G6: image differencing, etc.
A7: High-memory DRP algorithm ratio | B7: factor | C7: 2.5 | G7: stackfit, etc.
A8: DRP compute per TB | B8: core-hours/TB | C8: =(C4*C6+C5*C7)/C3 -> 21379.07
A9: Percent DRP on high-memory | B9: factor | C9: =C5*C7/(C5*C7+C4*C6) -> 0.67023006
A11: ap_pipe single-core sec/CCD | B11: core-sec/CCD | C11: =83*2 -> 166 | G11: measured 83 on DECam 2Kx4K CCD
A12: Additional AP steps | B12: factor | C12: 1.25 | G12: DCR, real_bogus, etc.
A13: AP compute per visit | B13: core-hours/visit | C13: =C11*189*C12/3600 -> 10.89375
A15: Qserv data/node | B15: TB | C15: =12*3600/1000 -> 43.2 | G15: 1 GB/sec for 12 hours
A17: Table drpAndAlertSizing | B17: Compute needs for DRP and AP | C17: 7 | D17: 0
A18: Data Release Production | B18: units | C18: FY20 | D18: FY21 | E18: FY22 | F18: FY23 | G18: Notes
A19: Precursor input size | B19: TB | C19: =Storage!C39*12*2+Storage!C43*2 -> 206.12112 | D19: =Storage!D39*12*2+Storage!D43*2 -> 206.12112 | E19: =Storage!E39*12*2+Storage!E43*2 -> 206.12112 | F19: =Storage!F39*12*2+Storage!F43*2 -> 206.12112
A20: LSSTCam visit input size | B20: TB | E20: =lsstCamScienceImages*lsstCamImageSize/imagesPerVisit*rawCompression -> 318.52031 | F20: =lsstCamScienceImages*lsstCamImageSize/imagesPerVisit*rawCompression -> 1911.1218 | G20: raw images / images/visit, lossless-compressed
A21: Precursor compute | B21: core-hours | C21: =coreHoursPerTB*C19 -> 4406677.7 | D21: =coreHoursPerTB*D19 -> 4406677.7 | E21: =coreHoursPerTB*E19 -> 4406677.7 | F21: =coreHoursPerTB*F19 -> 4406677.7
A22: LSSTCam compute | B22: core-hours | E22: =coreHoursPerTB*E20 -> 6809667.8 | F22: =coreHoursPerTB*F20 -> 40858007
A24: Total DRP compute | B24: core-hours | C24: =C21+C22 -> 4406677.7 | D24: =D21+D22 -> 4406677.7 | E24: =E21+E22 -> 11216345 | F24: =(F21+F22)/Model!$G$3 -> 45264684
A26: Alert Production | B26: units | C26: FY20 | D26: FY21 | E26: FY22 | F26: FY23 | G26: Notes
A27: AP cores | B27: cores | E27: =C13*3600/33 -> 1188.4091 | F27: =E27 -> 1188.4091 | G27: minimum necessary to keep up
A29: Table lspSizing | B29: Compute needs for the Science Platform instances | C29: 7 | D29: 0
A30: US DAC | B30: units | C30: FY20 | D30: FY21 | E30: FY22 | F30: FY23 | G30: Notes
A31: LSP cores | B31: cores | E31: =E24*0.1/24/365 -> 128.04047 | F31: =F24*0.1/24/365 -> 516.72014 | G31: 10% of DRP, over a year
A32: Qserv nodes | B32: nodes | E32: =CEILING(Storage!E68/$C$15,1) -> 14 | F32: =CEILING(Storage!F68/$C$15,1) -> 95
A33: LSP cores/science user | B33: cores/user | E33: =E31/scienceUsers -> 0.025608095 | F33: =F31/scienceUsers -> 0.10334403 | G33: includes oversubscription
A35: Chilean DAC | B35: units | C35: FY20 | D35: FY21 | E35: FY22 | F35: FY23 | G35: Notes
A36: LSP cores | B36: cores | E36: =0.2*E31 -> 25.608095 | F36: =0.2*F31 -> 103.34403 | G36: 20% of US DAC
A37: Qserv nodes | B37: nodes | E37: =E32 -> 14 | F37: =F32 -> 95
A39: Staff LSP | B39: units | C39: FY20 | D39: FY21 | E39: FY22 | F39: FY23 | G39: Notes
A40: LSP cores | B40: cores | E40: =0.1*E31 -> 12.804047 | F40: =0.1*F31 -> 51.672014 | G40: 10% of US DAC
A43: Table desComparison | B43: Comparison with DES compute | C43: 7 | D43: 0
A44: DES Comparison | B44: units | G44: Notes
A45: Input data size | B45: TB | C45: 50
A46: Single-frame data size | B46: TB | C46: =2048*4096*2*60/1000000000000 -> 0.001006633
A47: Single-frame processing | B47: core-hours/visit | C47: 5.23 | G47: Xeon E5-2680 v4 2.4GHz
A48: Coadd processing | B48: core-hours/deg^2 | C48: =19.52/(0.75*0.75) -> 34.702222 | G48: Xeon E5-2680 v4 2.4GHz
A49: MOF/SOF measurement | B49: core-hours/deg^2 | C49: =(1700000*313.6/32/40 + 200000)/(0.75*0.75*10146) -> 108.02287 | G49: AMD 6276 (313 GFLOPS/32 scheduled cores) and Xeon E5-2680 v4
A50: Sky area | B50: deg^2 | C50: =10146*0.75*0.75 -> 5707.125
...

Sheet Ops Storage
A1: Table storageSizingOps | B1: Inputs used to calculate storage needs during Operations | C1: 12 | D1: 0
A2: Parameters | B2: unit | C2: LOY1 | D2: LOY2 | E2: LOY3 | F2: LOY4 | G2: LOY5 | H2: LOY6 | I2: LOY7 | J2: LOY8 | K2: LOY9 | L2: LOY10 | M2: Notes
A4: Objects | B4: number | C4: 27500000000 | D4: 32500000000 | E4: 35700000000 | F4: 38200000000 | G4: 40300000000 | H4: 42200000000 | I4: 43800000000 | J4: 45300000000 | K4: 46400000000 | L4: 47400000000 | M4: from LSE-81
A5: Sources | B5: number | C5: 901000000000 | D5: 1800000000000 | E5: 2700000000000 | F5: 3600000000000 | G5: 4510000000000 | H5: 5410000000000 | I5: 6310000000000 | J5: 7210000000000 | K5: 8110000000000 | L5: 9010000000000 | M5: from LSE-81
A6: ForcedSources | B6: number | C6: =Model!G8*2910000000000 -> 2910000000000 | D6: =Model!G8* 6870000000000 -> 6870000000000 | E6: =Model!G8*11300000000000 -> 11300000000000 | F6: =Model!G8*16100000000000 -> 16100000000000 | G6: =Model!G8*21300000000000 -> 21300000000000 | H6: =Model!G8*26700000000000 -> 26700000000000 | I6: =Model!G8*32400000000000 -> 32400000000000 | J6: =Model!G8*38300000000000 -> 38300000000000 | K6: =Model!G8*44100000000000 -> 44100000000000 | L6: =Model!G8*50100000000000 -> 50100000000000 | M6: from LSE-81
A8: Science users | B8: users | C8: 5000 | D8: 6000 | E8: 7000 | F8: 7500 | G8: 7500 | H8: 7500 | I8: 7500 | J8: 7500 | K8: 7500 | L8: 7500 | M8: ramp to LSE-81 number
A9: Storage per science user | B9: TB | C9: 0.4 | D9: 0.5 | E9: 0.6 | F9: 0.7 | G9: 0.8 | H9: 0.9 | I9: 1 | J9: 1.1 | K9: 1.2 | L9: 1.3 | M9: ramp starting at LSE-81 number; includes oversubscription
A11: LSSTCam image size | B11: TB | C11: =16*562*2098*(189+12)*4/1000000000000 -> 0.015167634 | D11: =C11 -> 0.015167634 | E11: =D11 -> 0.015167634 | F11: =E11 -> 0.015167634 | G11: =F11 -> 0.015167634 | H11: =G11 -> 0.015167634 | I11: =H11 -> 0.015167634 | J11: =I11 -> 0.015167634 | K11: =J11 -> 0.015167634 | L11: =K11 -> 0.015167634 | M11: uncompressed, 32 bit, with overscan and corner rafts
A12: Raw image compression | B12: factor | C12: 0.42 | D12: =C12 -> 0.42 | E12: =D12 -> 0.42 | F12: =E12 -> 0.42 | G12: =F12 -> 0.42 | H12: =G12 -> 0.42 | I12: =H12 -> 0.42 | J12: =I12 -> 0.42 | K12: =J12 -> 0.42 | L12: =K12 -> 0.42 | M12: lossless-compressed divided by uncompressed for raws
A13: Lossy image compression | B13: factor | C13: 0.25 | D13: =C13 -> 0.25 | E13: =D13 -> 0.25 | F13: =E13 -> 0.25 | G13: =F13 -> 0.25 | H13: =G13 -> 0.25 | I13: =H13 -> 0.25 | J13: =I13 -> 0.25 | K13: =J13 -> 0.25 | L13: =K13 -> 0.25 | M13: lossy-compressed divided by lossless-compressed for PVIs
A15: Observing nights per year | B15: nights | C15: 300 | D15: =C15 -> 300 | E15: =D15 -> 300 | F15: =E15 -> 300 | G15: =F15 -> 300 | H15: =G15 -> 300 | I15: =H15 -> 300 | J15: =I15 -> 300 | K15: =J15 -> 300 | L15: =K15 -> 300 | M15: maximum
A16: Visits per night | B16: visits | C16: 1000 | D16: =C16 -> 1000 | E16: =D16 -> 1000 | F16: =E16 -> 1000 | G16: =F16 -> 1000 | H16: =G16 -> 1000 | I16: =H16 -> 1000 | J16: =I16 -> 1000 | K16: =J16 -> 1000 | L16: =K16 -> 1000 | M16: maximum
A17: Images per visit | B17: images | C17: 2 | D17: =C17 -> 2 | E17: =D17 -> 2 | F17: =E17 -> 2 | G17: =F17 -> 2 | H17: =G17 -> 2 | I17: =H17 -> 2 | J17: =I17 -> 2 | K17: =J17 -> 2 | L17: =K17 -> 2
A18: Calibration images per day | B18: images | C18: 500 | D18: =C18 -> 500 | E18: =D18 -> 500 | F18: =E18 -> 500 | G18: =F18 -> 500 | H18: =G18 -> 500 | I18: =H18 -> 500 | J18: =I18 -> 500 | K18: =J18 -> 500 | L18: =K18 -> 500
A19: LSSTCam Science images | B19: images | C19: =C15*C16*C17*(column()-2) -> 600000 | D19: =D15*D16*D17*(column()-2) -> 1200000 | E19: =E15*E16*E17*(column()-2) -> 1800000 | F19: =F15*F16*F17*(column()-2) -> 2400000 | G19: =G15*G16*G17*(column()-2) -> 3000000 | H19: =H15*H16*H17*(column()-2) -> 3600000 | I19: =I15*I16*I17*(column()-2) -> 4200000 | J19: =J15*J16*J17*(column()-2) -> 4800000 | ... L19: =L15*L16*L17*(column()-2) -> 6000000
A20: LSSTCam Engineering images | B20: images | C20: =0.01*C19 -> 6000 | D20: =0.01*D19 -> 12000 | E20: =0.01*E19 -> 18000 | F20: =0.01*F19 -> 24000 | G20: =0.01*G19 -> 30000 | H20: =0.01*H19 -> 36000 | I20: =0.01*I19 -> 42000 | J20: =0.01*J19 -> 48000 | ... L20: =0.01*L19 -> 60000 | M20: 1% of science
A21: LSSTCam Calibration images | B21: images | C21: =C15*C18*(column()-2) -> 150000 | D21: =D15*D18*(column()-2) -> 300000 | E21: =E15*E18*(column()-2) -> 450000 | F21: =F15*F18*(column()-2) -> 600000 | G21: =G15*G18*(column()-2) -> 750000 | H21: =H15*H18*(column()-2) -> 900000 | I21: =I15*I18*(column()-2) -> 1050000 | J21: =J15*J18*(column()-2) -> 1200000 | ... L21: =L15*L18*(column()-2) -> 1500000
A22: Number of coadd data products | B22: number | C22: 2 | D22: 2 | E22: 2 | F22: 2 | G22: 2 | H22: 2 | I22: 2 | J22: 2 | K22: 2 | L22: 2 | M22: deep and good-seeing
A23: Object table row size | B23: bytes | C23: 1896 | D23: 1953 | E23: 2012 | F23: 2073 | G23: 2136 | H23: 2201 | I23: 2268 | J23: 2337 | K23: 2408 | L23: 2481 | M23: from LDM-141
A24: Object_Extra tables row size | B24: bytes | C24: 21005 | D24: 21636 | E24: 22286 | F24: 22955 | G24: 23644 | H24: 24354 | I24: 25085 | J24: 25838 | K24: 26614 | L24: 27413 | M24: from LDM-141
A25: Source table row size | B25: bytes | C25: 467 | D25: 482 | E25: 497 | F25: 512 | G25: 528 | H25: 544 | I25: 561 | J25: 578 | K25: 596 | L25: 614 | M25: from LDM-141
A26: ForcedSource table row size | B26: bytes | C26: 41 | D26: 41 | E26: 41 | F26: 41 | G26: 41 | H26: 41 | I26: 41 | J26: 41 | K26: 41 | L26: 41 | M26: from LDM-141
A27: Qserv replication factor | B27: factor | C27: 3 | D27: 3 | E27: 3 | F27: 3 | G27: 3 | H27: 3 | I27: 3 | J27: 3 | K27: 3 | L27: 3
A29: Table datasetSizingOps | B29: Dataset sizes used to calculate storage needs during Operations | C29: 12 | D29: 0
A30: Dataset Sizing | B30: unit | C30: LOY1 | D30: LOY2 | E30: LOY3 | F30: LOY4 | G30: LOY5 | H30: LOY6 | I30: LOY7 | J30: LOY8 | K30: LOY9 | L30: LOY10 | M30: Notes
A31: LSSTCam Area | B31: deg^2 | C31: 17000 | D31: 17000 | E31: 17000 | F31: 17000 | G31: 17000 | H31: 17000 | I31: 17000 | J31: 17000 | K31: 17000 | L31: 17000
A33: APDB | B33: TB | C33: =4.5/57000*'Ops Storage'!visitsPerNight*'Ops Storage'!nightsPerYear -> 23.684211 | D33: =4.5/57000*'Ops Storage'!visitsPerNight*'Ops Storage'!nightsPerYear -> 23.684211 | E33: =4.5/57000*'Ops Storage'!visitsPerNight*'Ops Storage'!nightsPerYear -> 23.684211 | F33: =4.5/57000*'Ops Storage'!visitsPerNight*'Ops Storage'!nightsPerYear -> 23.684211 | G33: =4.5/57000*'Ops Storage'!visitsPerNight*'Ops Storage'!nightsPerYear -> 23.684211 | H33: =4.5/57000*'Ops Storage'!visitsPerNight*'Ops Storage'!nightsPerYear -> 23.684211 | I33: =4.5/57000*'Ops Storage'!visitsPerNight*'Ops Storage'!nightsPerYear -> 23.684211 | J33: =4.5/57000*'Ops Storage'!visitsPerNight*'Ops Storage'!nightsPerYear -> 23.684211 | ... L33: =4.5/57000*'Ops Storage'!visitsPerNight*'Ops Storage'!nightsPerYear -> 23.684211 | M33: 4.5/57K TB per visit; 1 year retention; 6 months in 2020
A34: Object store datasets:
A35: Incremental LSSTCam Raw Images | B35: TB | C35: =sum(C19:C21)*C11*C12 -> 4816.027 | D35: =sum(D19:D21)*D11*D12-sum(C19:C21)*C11*C12 -> 4816.027 | E35: =sum(E19:E21)*E11*E12-sum(D19:D21)*D11*D12 -> 4816.027 | F35: =sum(F19:F21)*F11*F12-sum(E19:E21)*E11*E12 -> 4816.027 | G35: =sum(G19:G21)*G11*G12-sum(F19:F21)*F11*F12 -> 4816.027 | H35: =sum(H19:H21)*H11*H12-sum(G19:G21)*G11*G12 -> 4816.027 | I35: =sum(I19:I21)*I11*I12-sum(H19:H21)*H11*H12 -> 4816.027 | J35: =sum(J19:J21)*J11*J12-sum(I19:I21)*I11*I12 -> 4816.027 | K35: =sum(K19:K21)*K11*K12-sum(J19:J21)*J11*J12 -> 4816.027 | L35: =sum(L19:L21)*L11*L12-sum(K19:K21)*K11*K12 -> 4816.027 | M35: compressed, immediate object store
A36: LSSTCam Output Coadd Images | B36: TB | C36: =Storage!$C$41/Storage!$C$33*C31*C22 -> 2700 | D36: =Storage!$C$41/Storage!$C$33*D31*D22 -> 2700 | E36: =Storage!$C$41/Storage!$C$33*E31*E22 -> 2700 | F36: =Storage!$C$41/Storage!$C$33*F31*F22 -> 2700 | G36: =Storage!$C$41/Storage!$C$33*G31*G22 -> 2700 | H36: =Storage!$C$41/Storage!$C$33*H31*H22 -> 2700 | I36: =Storage!$C$41/Storage!$C$33*I31*I22 -> 2700 | J36: =Storage!$C$41/Storage!$C$33*J31*J22 -> 2700 | ... L36: =Storage!$C$41/Storage!$C$33*L31*L22 -> 2700 | M36: lossless-compressed, immediate object store
A37: Normal disk datasets:
A38: LSSTCam Output Images | B38: TB | C38: =Storage!$C$40*lsstCamImageToHscRatio*C19/C17 -> 6742.6089 | D38: =Storage!$C$40*lsstCamImageToHscRatio*D19/D17 -> 13485.218 | E38: =Storage!$C$40*lsstCamImageToHscRatio*E19/E17 -> 20227.827 | F38: =Storage!$C$40*lsstCamImageToHscRatio*F19/F17 -> 26970.436 | G38: =Storage!$C$40*lsstCamImageToHscRatio*G19/G17 -> 33713.045 | H38: =Storage!$C$40*lsstCamImageToHscRatio*H19/H17 -> 40455.654 | I38: =Storage!$C$40*lsstCamImageToHscRatio*I19/I17 -> 47198.263 | J38: =Storage!$C$40*lsstCamImageToHscRatio*J19/J17 -> 53940.872 | ... L38: =Storage!$C$40*lsstCamImageToHscRatio*L19/L17 -> 67426.089 | M38: lossless-compressed, moves to object store
A39: LSSTCam Output Parquet | B39: TB | C39: =Storage!$C$42*lsstCamImageToHscRatio*C19/C17 -> 3986.5675 | D39: =Storage!$C$42*lsstCamImageToHscRatio*D19/D17 -> 7973.1351 | E39: =Storage!$C$42*lsstCamImageToHscRatio*E19/E17 -> 11959.703 | F39: =Storage!$C$42*lsstCamImageToHscRatio*F19/F17 -> 15946.27 | G39: =Storage!$C$42*lsstCamImageToHscRatio*G19/G17 -> 19932.838 | H39: =Storage!$C$42*lsstCamImageToHscRatio*H19/H17 -> 23919.405 | I39: =Storage!$C$42*lsstCamImageToHscRatio*I19/I17 -> 27905.973 | J39: =Storage!$C$42*lsstCamImageToHscRatio*J19/J17 -> 31892.54 | ... L39: =Storage!$C$42*lsstCamImageToHscRatio*L19/L17 -> 39865.675 | M39: moves to object store
A40: Sims output | B40: TB | C40: 5 | D40: 5 | E40: 5 | F40: 5 | G40: 5 | H40: 5 | I40: 5 | J40: 5 | K40: 5 | L40: 5 | M40: Output of RPF simulations
A41: Scratch | B41: TB | C41: =0.1*C38 -> 674.26089 | D41: =0.1*D38 -> 1348.5218 | E41: =0.1*E38 -> 2022.7827 | F41: =0.1*F38 -> 2697.0436 | G41: =0.1*G38 -> 3371.3045 | H41: =0.1*H38 -> 4045.5654 | I41: =0.1*I38 -> 4719.8263 | J41: =0.1*J38 -> 5394.0872 | ... L41: =0.1*L38 -> 6742.6089 | M41: 10% of output images
A42: Qserv Czar/Object | B42: TB | C42: =C4*C23*'Ops Storage'!qservReplication/1000000000000 -> 156.42 | D42: =D4*D23*'Ops Storage'!qservReplication/1000000000000 -> 190.4175 | E42: =E4*E23*'Ops Storage'!qservReplication/1000000000000 -> 215.4852 | F42: =F4*F23*'Ops Storage'!qservReplication/1000000000000 -> 237.5658 | G42: =G4*G23*'Ops Storage'!qservReplication/1000000000000 -> 258.2424 | H42: =H4*H23*'Ops Storage'!qservReplication/1000000000000 -> 278.6466 | I42: =I4*I23*'Ops Storage'!qservReplication/1000000000000 -> 298.0152 | J42: =J4*J23*'Ops Storage'!qservReplication/1000000000000 -> 317.5983 | ... L42: =L4*L23*'Ops Storage'!qservReplication/1000000000000 -> 352.7982 | M42: based on row sizes and counts
A43: Qserv Database | B43: TB | C43: =(C4*(C23+C24)+C5*C25+C6*C26)*C27/1000000000000 -> 3509.5635 | D43: =(D4*(D23+D24)+D5*D25+D6*D26)*D27/1000000000000 -> 5747.7375 | E43: =(E4*(E23+E24)+E5*E25+E6*E26)*E27/1000000000000 -> 8017.9158 | F43: =(F4*(F23+F24)+F5*F25+F6*F26)*F27/1000000000000 -> 10378.109 | G43: =(G4*(G23+G24)+G5*G25+G6*G26)*G27/1000000000000 -> 12880.542 | H43: =(H4*(H23+H24)+H5*H25+H6*H26)*H27/1000000000000 -> 15475.083 | I43: =(I4*(I23+I24)+I5*I25+I6*I26)*I27/1000000000000 -> 18199.114 | J43: =(J4*(J23+J24)+J5*J25+J6*J26)*J27/1000000000000 -> 21042.022 | ... L43: =(L4*(L23+L24)+L5*L25+L6*L26)*L27/1000000000000 -> 27009.647 | M43: based on row sizes and counts
A44: Science User Home | B44: TB | C44: ='Ops Storage'!opsScienceUsers*'Ops Storage'!opsTBPerScienceUser -> 2000 | D44: ='Ops Storage'!opsScienceUsers*'Ops Storage'!opsTBPerScienceUser -> 3000 | E44: ='Ops Storage'!opsScienceUsers*'Ops Storage'!opsTBPerScienceUser -> 4200 | F44: ='Ops Storage'!opsScienceUsers*'Ops Storage'!opsTBPerScienceUser -> 5250 | G44: ='Ops Storage'!opsScienceUsers*'Ops Storage'!opsTBPerScienceUser -> 6000 | H44: ='Ops Storage'!opsScienceUsers*'Ops Storage'!opsTBPerScienceUser -> 6750 | I44: ='Ops Storage'!opsScienceUsers*'Ops Storage'!opsTBPerScienceUser -> 7500 | J44: ='Ops Storage'!opsScienceUsers*'Ops Storage'!opsTBPerScienceUser -> 8250 | ... L44: ='Ops Storage'!opsScienceUsers*'Ops Storage'!opsTBPerScienceUser -> 9750
A45: Other/Misc | B45: TB | C45: =0.2*sum(C33:C44) -> 4922.8264 | D45: =0.2*sum(D33:D44) -> 7857.9482 | E45: =0.2*sum(E33:E44) -> 10837.685 | F45: =0.2*sum(F33:F44) -> 13804.827 | G45: =0.2*sum(G33:G44) -> 16740.137 | H45: =0.2*sum(H33:H44) -> 19693.813 | I45: =0.2*sum(I33:I44) -> 22673.18 | J45: =0.2*sum(J33:J44) -> 25676.366 | ... L45: =0.2*sum(L33:L44) -> 31738.306 | M45: 20% of total
A47: Table storageFloorOps | B47: On floor LDF storage estimates during Operations | C47: 12 | D47: 0
...

Sheet Ops Compute
A1: Table computeSizingOps | B1: Compute needs during Operations | C1: 12 | D1: 0 | I1: 7 | J1: 0
A2: Data Release Production | B2: units | C2: LOY1 | D2: LOY2 | E2: LOY3 | F2: LOY4 | G2: LOY5 | H2: LOY6 | I2: LOY7 | J2: LOY8 | K2: LOY9 | L2: LOY10 | M2: Notes
A3: LSSTCam visit input size | B3: TB | C3: =Storage!$F$20*lsstCamImageSize/imagesPerVisit*(column()-2)*rawCompression -> 1911.1218 | D3: =Storage!$F$20*lsstCamImageSize/imagesPerVisit*(column()-2)*rawCompression -> 3822.2437 | E3: =Storage!$F$20*lsstCamImageSize/imagesPerVisit*(column()-2)*rawCompression -> 5733.3655 | F3: =Storage!$F$20*lsstCamImageSize/imagesPerVisit*(column()-2)*rawCompression -> 7644.4874 | G3: =Storage!$F$20*lsstCamImageSize/imagesPerVisit*(column()-2)*rawCompression -> 9555.6092 | H3: =Storage!$F$20*lsstCamImageSize/imagesPerVisit*(column()-2)*rawCompression -> 11466.731 | I3: =Storage!$F$20*lsstCamImageSize/imagesPerVisit*(column()-2)*rawCompression -> 13377.853 | J3: =Storage!$F$20*lsstCamImageSize/imagesPerVisit*(column()-2)*rawCompression -> 15288.975 | ... L3: =Storage!$F$20*lsstCamImageSize/imagesPerVisit*(column()-2)*rawCompression -> 19111.218
A4: DRP compute | B4: core-hours | C4: =C3*Compute!$C$8+Compute!$F$21 -> 45264684 | D4: =D3*Compute!$C$8 -> 81716014 | E4: =E3*Compute!$C$8 -> 1.2257402e+08 | F4: =F3*Compute!$C$8 -> 1.6343203e+08 | G4: =G3*Compute!$C$8 -> 2.0429003e+08 | H4: =H3*Compute!$C$8 -> 2.4514804e+08 | I4: =I3*Compute!$C$8 -> 2.8600605e+08 | J4: =J3*Compute!$C$8 -> 3.2686405e+08 | K4: =K3*Compute!$C$8 -> 367722061 | L4: =L3*Compute!$C$8 -> 4.0858007e+08
A6: Alert Production | B6: units | C6: =C2 -> LOY1 | D6: =D2 -> LOY2 | E6: =E2 -> LOY3 | F6: =F2 -> LOY4 | G6: =G2 -> LOY5 | H6: =H2 -> LOY6 | I6: =I2 -> LOY7 | J6: =J2 -> LOY8 | ... L6: =L2 -> LOY10 | M6: Notes
A7: AP cores | B7: cores | C7: =Compute!$F$27 -> 1188.4091 | D7: =C7 -> 1188.4091 | E7: =D7 -> 1188.4091 | F7: =E7 -> 1188.4091 | G7: =F7 -> 1188.4091 | H7: =G7 -> 1188.4091 | I7: =H7 -> 1188.4091 | J7: =I7 -> 1188.4091 | K7: =J7 -> 1188.4091 | L7: =K7 -> 1188.4091 | M7: minimum necessary to keep up
A9: US DAC | B9: units | C9: LOY1 | D9: LOY2 | E9: LOY3 | F9: LOY4 | G9: LOY5 | H9: LOY6 | I9: LOY7 | J9: LOY8 | K9: LOY9 | L9: LOY10 | M9: Notes
A10: LSP cores | B10: cores | C10: =C4*0.1/24/365 -> 516.72014 | D10: =D4*0.1/24/365 -> 932.8312 | E10: =E4*0.1/24/365 -> 1399.2468 | F10: =F4*0.1/24/365 -> 1865.6624 | G10: =G4*0.1/24/365 -> 2332.078 | H10: =H4*0.1/24/365 -> 2798.4936 | I10: =I4*0.1/24/365 -> 3264.9092 | J10: =J4*0.1/24/365 -> 3731.3248 | ... L10: =L4*0.1/24/365 -> 4664.156 | M10: 10% of DRP, over a year
A11: Qserv data per node | B11: TB/node | C11: =12*3600/1000 -> 43.2 | D11: =12*3600/1000 -> 43.2 | E11: =12*3600/1000*2 -> 86.4 | F11: =12*3600/1000*2 -> 86.4 | G11: =12*3600/1000*2 -> 86.4 | H11: =12*3600/1000*2 -> 86.4 | I11: =12*3600/1000*4 -> 172.8 | J11: =12*3600/1000*4 -> 172.8 | K11: =12*3600/1000*4 -> 172.8 | L11: =12*3600/1000*4 -> 172.8
A12: Qserv nodes | B12: nodes | C12: =CEILING('Ops Storage'!C$55/C$11,1) -> 95 | D12: =CEILING('Ops Storage'!D$43/D$11,1)+CEILING('Ops Storage'!C$43/C$11,1) -> 216 | E12: =CEILING('Ops Storage'!E$43/E$11,1)+CEILING('Ops Storage'!D$43/D$11,1)+CEILING('Ops Storage'!C$43/C$11,1) -> 309 | F12: =CEILING('Ops Storage'!F$43/F$11,1)+CEILING('Ops Storage'!E$43/E$11,1)+CEILING('Ops Storage'!D$43/D$11,1) -> 348 | G12: =CEILING('Ops Storage'!G$43/G$11,1)+CEILING('Ops Storage'!F$43/F$11,1)+CEILING('Ops Storage'!E$43/E$11,1) -> 364 | H12: =CEILING('Ops Storage'!H$43/H$11,1)+CEILING('Ops Storage'!G$43/G$11,1)+CEILING('Ops Storage'!F$43/F$11,1) -> 451 | I12: =CEILING('Ops Storage'!I$43/I$11,1)+CEILING('Ops Storage'!H$43/H$11,1)+CEILING('Ops Storage'!G$43/G$11,1) -> 436 | J12: =CEILING('Ops Storage'!J$43/J$11,1)+CEILING('Ops Storage'!I$43/I$11,1)+CEILING('Ops Storage'!H$43/H$11,1) -> 408 | K12: =CEILING('Ops Storage'!K$43/K$11,1)+CEILING('Ops Storage'!J$43/J$11,1)+CEILING('Ops Storage'!I$43/I$11,1) -> 367 | L12: =CEILING('Ops Storage'!L$43/L$11,1)+CEILING('Ops Storage'!K$43/K$11,1)+CEILING('Ops Storage'!J$43/J$11,1) -> 418 | M12: staff Qserv nodes included
A13: LSP cores/science user | B13: cores/user | C13: =C10/'Ops Storage'!opsScienceUsers -> 0.10334403 | D13: =D10/'Ops Storage'!opsScienceUsers -> 0.15547187 | E13: =E10/'Ops Storage'!opsScienceUsers -> 0.1998924 | F13: =F10/'Ops Storage'!opsScienceUsers -> 0.24875499 | G13: =G10/'Ops Storage'!opsScienceUsers -> 0.31094373 | H13: =H10/'Ops Storage'!opsScienceUsers -> 0.37313248 | I13: =I10/'Ops Storage'!opsScienceUsers -> 0.43532123 | J13: =J10/'Ops Storage'!opsScienceUsers -> 0.49750998 | ... L13: =L10/'Ops Storage'!opsScienceUsers -> 0.62188747 | M13: includes oversubscription
A15: Chilean DAC | B15: units | C15: LOY1 | D15: LOY2 | E15: LOY3 | F15: LOY4 | G15: LOY5 | H15: LOY6 | I15: LOY7 | J15: LOY8 | K15: LOY9 | L15: LOY10 | M15: Notes
A16: LSP cores | B16: cores | C16: =0.2*C10 -> 103.34403 | D16: =0.2*D10 -> 186.56624 | E16: =0.2*E10 -> 279.84936 | F16: =0.2*F10 -> 373.13248 | G16: =0.2*G10 -> 466.4156 | H16: =0.2*H10 -> 559.69872 | I16: =0.2*I10 -> 652.98184 | J16: =0.2*J10 -> 746.26496 | ... L16: =0.2*L10 -> 932.8312 | M16: 20% of US DAC
A17: Qserv nodes | B17: nodes | C17: =C12 -> 95 | D17: =D12 -> 216 | E17: =E12 -> 309 | F17: =F12 -> 348 | G17: =G12 -> 364 | H17: =H12 -> 451 | I17: =I12 -> 436 | J17: =J12 -> 408 | ... L17: =L12 -> 418 | M17: need 3rd DR for loading
A19: Staff LSP | B19: units | C19: LOY1 | D19: LOY2 | E19: LOY3 | F19: LOY4 | G19: LOY5 | H19: LOY6 | I19: LOY7 | J19: LOY8 | K19: LOY9 | L19: LOY10 | M19: Notes
A20: LSP cores | B20: cores | C20: =0.1*C10 -> 51.672014 | D20: =0.1*D10 -> 93.28312 | E20: =0.1*E10 -> 139.92468 | F20: =0.1*F10 -> 186.56624 | G20: =0.1*G10 -> 233.2078 | H20: =0.1*H10 -> 279.84936 | I20: =0.1*I10 -> 326.49092 | J20: =0.1*J10 -> 373.13248 | ... L20: =0.1*L10 -> 466.4156 | M20: 10% of US DAC

Sheet OPS proposal 
